Workbook
Name ExternalData_1: 'Deaths_1x1(AUS)'!$A$1:$L$11214
Name ExternalData_1: 'Deaths_1x1(UK)'!$A$1:$M$11214
Name ExternalData_1: 'Exposures_1x1(AUS)'!$A$1:$N$11214
Name ExternalData_1: 'Exposures_1x1(UK)'!$A$1:$O$11214

Sheet ReadMe
A1: Whittaker-Henderson Graduation Workbook
A3: Inputs sheet: edit K in B2 and data in A6:C125 if needed. Edit the age, deaths and exposure data as needed.
A4: Example 2.1 data (ages 35-70) is preloaded.
A5: WH_Numeical sheet: Use Solver to find the graduated rates that minimises the total objective Q.
A6: WH_Numerical sheet: Trial graduated rates are in column G; initially set equal to crude rates. Adherence term, smoothness term, and total objective Q are computed
A7: WH_Analytical sheet: for the preloaded data only, solves (W + K D'D) qdot = W qhat.
A8: This analytical sheet can accommodate up to 120 ages.

Sheet Inputs
A1: WH Graduation Template
A2: Smoothing parameter K | B2: =10^7 -> 10000000 | D2: Active ages n | E2: =COUNT(A6:A125) -> 40
A4: Paste ages, exposures and deaths below (up to 120 ages)
A5: Age | B5: Exposure E_x | C5: Deaths D_x | D5: mhat_x = D/E | E5: p_x = 1-qhat | F5: w_x = E
A6: 20 | B6: 283502.35 | C6: 164.01 | D6: =IF(OR(B6="",C6="",B6=0),"",C6/B6) -> 0.00057851372 | E6: =IF(D6="","",1-D6) -> 0.99942149 | F6: =B6 -> 283502.35
A7: 21 | B7: 283375.14 | C7: 179.02 | D7: =IF(OR(B7="",C7="",B7=0),"",C7/B7) -> 0.00063174208 | E7: =IF(D7="","",1-D7) -> 0.99936826 | F7: =B7 -> 283375.14
A8: 22 | B8: 285838.65 | C8: 127 | D8: =IF(OR(B8="",C8="",B8=0),"",C8/B8) -> 0.0004443066 | E8: =IF(D8="","",1-D8) -> 0.99955569 | F8: =B8 -> 285838.65
A9: 23 | B9: 283132.8 | C9: 167.02 | D9: =IF(OR(B9="",C9="",B9=0),"",C9/B9) -> 0.00058989986 | E9: =IF(D9="","",1-D9) -> 0.9994101 | F9: =B9 -> 283132.8
A10: 24 | B10: 279196.5 | C10: 164.02 | D10: =IF(OR(B10="",C10="",B10=0),"",C10/B10) -> 0.00058747155 | E10: =IF(D10="","",1-D10) -> 0.99941253 | F10: =B10 -> 279196.5
A11: 25 | B11: 272371.83 | C11: 159.02 | D11: =IF(OR(B11="",C11="",B11=0),"",C11/B11) -> 0.00058383424 | E11: =IF(D11="","",1-D11) -> 0.99941617 | F11: =B11 -> 272371.83
A12: 26 | B12: 270495.83 | C12: 162.02 | D12: =IF(OR(B12="",C12="",B12=0),"",C12/B12) -> 0.00059897411 | E12: =IF(D12="","",1-D12) -> 0.99940103 | F12: =B12 -> 270495.83
A13: 27 | B13: 269320.85 | C13: 163.02 | D13: =IF(OR(B13="",C13="",B13=0),"",C13/B13) -> 0.00060530033 | E13: =IF(D13="","",1-D13) -> 0.9993947 | F13: =B13 -> 269320.85
A14: 28 | B14: 270279.97 | C14: 175.02 | D14: =IF(OR(B14="",C14="",B14=0),"",C14/B14) -> 0.00064755076 | E14: =IF(D14="","",1-D14) -> 0.99935245 | F14: =B14 -> 270279.97
A15: 29 | B15: 274642.93 | C15: 200.02 | D15: =IF(OR(B15="",C15="",B15=0),"",C15/B15) -> 0.00072829109 | E15: =IF(D15="","",1-D15) -> 0.99927171 | F15: =B15 -> 274642.93
A16: 30 | B16: 281389.11 | C16: 193.02 | D16: =IF(OR(B16="",C16="",B16=0),"",C16/B16) -> 0.00068595405 | E16: =IF(D16="","",1-D16) -> 0.99931405 | F16: =B16 -> 281389.11
A17: 31 | B17: 289432.24 | C17: 203.02 | D17: =IF(OR(B17="",C17="",B17=0),"",C17/B17) -> 0.00070144224 | E17: =IF(D17="","",1-D17) -> 0.99929856 | F17: =B17 -> 289432.24
... A45: 59 | B45: 225403.6 | C45: 1184.14 | D45: =IF(OR(B45="",C45="",B45=0),"",C45/B45) -> 0.005253421 | E45: =IF(D45="","",1-D45) -> 0.99474658 | F45: =B45 -> 225403.6

Sheet WH_Numerical
A1: WH Numerical / Objective Illustration
A2: K | B2: =Inputs!B2 -> 10000000 | D2: n | E2: =Inputs!E2 -> 40
F4: Set qdot initial value to qhat_x
A5: Age | B5: Exposure | C5: Deaths | D5: mhat_x | E5: w_x | F5: Trial mdot_x | G5: w_x(mdot-mhat)^2 | H5: Δm | I5: Δ²m | J5: Δ³m | K5: K(Δ³m)^2 | M5: Adherence part | N5: =SUM(G6:G125) -> 0.056716342
A6: =IF(ROW()-5<=$E$2,Inputs!A6,"") -> 20 | B6: =IF(A6="","",Inputs!B6) -> 283502.35 | C6: =IF(A6="","",Inputs!C6) -> 164.01 | D6: =IF(A6="","",Inputs!D6) -> 0.00057851372 | E6: =IF(A6="","",Inputs!F6) -> 283502.35 | F6: 0.00058293682 | G6: =IF(A6="","",E6*(F6-D6)^2) -> 5.5463753e-06 | H6: =IF(OR(A6="",ROW()-5>$E$2-1,F6="",F7=""),"",F7-F6) -> -1.8695858e-05 | I6: =IF(OR(A6="",ROW()-5>$E$2-2,H6="",H7=""),"",H7-H6) -> 9.8286083e-06 | J6: =IF(OR(A6="",ROW()-5>$E$2-3,I6="",I7=""),"",I7-I6) -> 9.6939587e-08 | K6: =IF(OR(J6="",ROW()-5>$E$2-3),"",$B$2*J6^2) -> 9.3972835e-08 | M6: Smoothness part | N6: =SUM(K6:K125) -> 0.0021125446
A7: =IF(ROW()-5<=$E$2,Inputs!A7,"") -> 21 | B7: =IF(A7="","",Inputs!B7) -> 283375.14 | C7: =IF(A7="","",Inputs!C7) -> 179.02 | D7: =IF(A7="","",Inputs!D7) -> 0.00063174208 | E7: =IF(A7="","",Inputs!F7) -> 283375.14 | F7: 0.00056424096 | G7: =IF(A7="","",E7*(F7-D7)^2) -> 0.0012911707 | H7: =IF(OR(A7="",ROW()-5>$E$2-1,F7="",F8=""),"",F8-F7) -> -8.8672493e-06 | I7: =IF(OR(A7="",ROW()-5>$E$2-2,H7="",H8=""),"",H8-H7) -> 9.9255478e-06 | J7: =IF(OR(A7="",ROW()-5>$E$2-3,I7="",I8=""),"",I8-I7) -> -1.5995691e-06 | K7: =IF(OR(J7="",ROW()-5>$E$2-3),"",$B$2*J7^2) -> 2.5586213e-05 | M7: Total Q | N7: =N5+N6 -> 0.058828887
A8: =IF(ROW()-5<=$E$2,Inputs!A8,"") -> 22 | B8: =IF(A8="","",Inputs!B8) -> 285838.65 | C8: =IF(A8="","",Inputs!C8) -> 127 | D8: =IF(A8="","",Inputs!D8) -> 0.0004443066 | E8: =IF(A8="","",Inputs!F8) -> 285838.65 | F8: 0.00055537371 | G8: =IF(A8="","",E8*(F8-D8)^2) -> 0.0035260777 | H8: =IF(OR(A8="",ROW()-5>$E$2-1,F8="",F9=""),"",F9-F8) -> 1.0582986e-06 | I8: =IF(OR(A8="",ROW()-5>$E$2-2,H8="",H9=""),"",H9-H8) -> 8.3259788e-06 | J8: =IF(OR(A8="",ROW()-5>$E$2-3,I8="",I9=""),"",I9-I8) -> -1.8734484e-06 | K8: =IF(OR(J8="",ROW()-5>$E$2-3),"",$B$2*J8^2) -> 3.5098088e-05
A9: =IF(ROW()-5<=$E$2,Inputs!A9,"") -> 23 | B9: =IF(A9="","",Inputs!B9) -> 283132.8 | C9: =IF(A9="","",Inputs!C9) -> 167.02 | D9: =IF(A9="","",Inputs!D9) -> 0.00058989986 | E9: =IF(A9="","",Inputs!F9) -> 283132.8 | F9: 0.00055643201 | G9: =IF(A9="","",E9*(F9-D9)^2) -> 0.00031713625 | H9: =IF(OR(A9="",ROW()-5>$E$2-1,F9="",F10=""),"",F10-F9) -> 9.3842773e-06 | I9: =IF(OR(A9="",ROW()-5>$E$2-2,H9="",H10=""),"",H10-H9) -> 6.4525304e-06 | J9: =IF(OR(A9="",ROW()-5>$E$2-3,I9="",I10=""),"",I10-I9) -> -1.6466123e-06 | K9: =IF(OR(J9="",ROW()-5>$E$2-3),"",$B$2*J9^2) -> 2.7113321e-05
A10: =IF(ROW()-5<=$E$2,Inputs!A10,"") -> 24 | B10: =IF(A10="","",Inputs!B10) -> 279196.5 | C10: =IF(A10="","",Inputs!C10) -> 164.02 | D10: =IF(A10="","",Inputs!D10) -> 0.00058747155 | E10: =IF(A10="","",Inputs!F10) -> 279196.5 | F10: 0.00056581629 | G10: =IF(A10="","",E10*(F10-D10)^2) -> 0.00013092928 | H10: =IF(OR(A10="",ROW()-5>$E$2-1,F10="",F11=""),"",F11-F10) -> 1.5836808e-05 | I10: =IF(OR(A10="",ROW()-5>$E$2-2,H10="",H11=""),"",H11-H10) -> 4.8059181e-06 | J10: =IF(OR(A10="",ROW()-5>$E$2-3,I10="",I11=""),"",I11-I10) -> -1.5183884e-06 | K10: =IF(OR(J10="",ROW()-5>$E$2-3),"",$B$2*J10^2) -> 2.3055033e-05
A11: =IF(ROW()-5<=$E$2,Inputs!A11,"") -> 25 | B11: =IF(A11="","",Inputs!B11) -> 272371.83 | C11: =IF(A11="","",Inputs!C11) -> 159.02 | D11: =IF(A11="","",Inputs!D11) -> 0.00058383424 | E11: =IF(A11="","",Inputs!F11) -> 272371.83 | F11: 0.0005816531 | G11: =IF(A11="","",E11*(F11-D11)^2) -> 1.2957781e-06 | H11: =IF(OR(A11="",ROW()-5>$E$2-1,F11="",F12=""),"",F12-F11) -> 2.0642726e-05 | I11: =IF(OR(A11="",ROW()-5>$E$2-2,H11="",H12=""),"",H12-H11) -> 3.2875297e-06 | J11: =IF(OR(A11="",ROW()-5>$E$2-3,I11="",I12=""),"",I12-I11) -> -1.5444964e-06 | K11: =IF(OR(J11="",ROW()-5>$E$2-3),"",$B$2*J11^2) -> 2.3854692e-05
A12: =IF(ROW()-5<=$E$2,Inputs!A12,"") -> 26 | B12: =IF(A12="","",Inputs!B12) -> 270495.83 | C12: =IF(A12="","",Inputs!C12) -> 162.02 | D12: =IF(A12="","",Inputs!D12) -> 0.00059897411 | E12: =IF(A12="","",Inputs!F12) -> 270495.83 | F12: 0.00060229582 | G12: =IF(A12="","",E12*(F12-D12)^2) -> 2.9845807e-06 | H12: =IF(OR(A12="",ROW()-5>$E$2-1,F12="",F13=""),"",F13-F12) -> 2.3930255e-05 | I12: =IF(OR(A12="",ROW()-5>$E$2-2,H12="",H13=""),"",H13-H12) -> 1.7430333e-06 | J12: =IF(OR(A12="",ROW()-5>$E$2-3,I12="",I13=""),"",I13-I12) -> -1.615822e-06 | K12: =IF(OR(J12="",ROW()-5>$E$2-3),"",$B$2*J12^2) -> 2.6108808e-05
A13: =IF(ROW()-5<=$E$2,Inputs!A13,"") -> 27 | B13: =IF(A13="","",Inputs!B13) -> 269320.85 | C13: =IF(A13="","",Inputs!C13) -> 163.02 | D13: =IF(A13="","",Inputs!D13) -> 0.00060530033 | E13: =IF(A13="","",Inputs!F13) -> 269320.85 | F13: 0.00062622608 | G13: =IF(A13="","",E13*(F13-D13)^2) -> 0.00011793204 | H13: =IF(OR(A13="",ROW()-5>$E$2-1,F13="",F14=""),"",F14-F13) -> 2.5673289e-05 | I13: =IF(OR(A13="",ROW()-5>$E$2-2,H13="",H14=""),"",H14-H13) -> 1.2721125e-07 | J13: =IF(OR(A13="",ROW()-5>$E$2-3,I13="",I14=""),"",I14-I13) -> -1.1362169e-06 | K13: =IF(OR(J13="",ROW()-5>$E$2-3),"",$B$2*J13^2) -> 1.2909887e-05
A14: =IF(ROW()-5<=$E$2,Inputs!A14,"") -> 28 | B14: =IF(A14="","",Inputs!B14) -> 270279.97 | C14: =IF(A14="","",Inputs!C14) -> 175.02 | D14: =IF(A14="","",Inputs!D14) -> 0.00064755076 | E14: =IF(A14="","",Inputs!F14) -> 270279.97 | F14: 0.00065189937 | G14: =IF(A14="","",E14*(F14-D14)^2) -> 5.1110935e-06 | H14: =IF(OR(A14="",ROW()-5>$E$2-1,F14="",F15=""),"",F15-F14) -> 2.58005e-05 | I14: =IF(OR(A14="",ROW()-5>$E$2-2,H14="",H15=""),"",H15-H14) -> -1.0090056e-06 | J14: =IF(OR(A14="",ROW()-5>$E$2-3,I14="",I15=""),"",I15-I14) -> 4.1869872e-08 | K14: =IF(OR(J14="",ROW()-5>$E$2-3),"",$B$2*J14^2) -> 1.7530861e-08
A15: =IF(ROW()-5<=$E$2,Inputs!A15,"") -> 29 | B15: =IF(A15="","",Inputs!B15) -> 274642.93 | C15: =IF(A15="","",Inputs!C15) -> 200.02 | D15: =IF(A15="","",Inputs!D15) -> 0.00072829109 | E15: =IF(A15="","",Inputs!F15) -> 274642.93 | F15: 0.00067769987 | G15: =IF(A15="","",E15*(F15-D15)^2) -> 0.00070294101 | H15: =IF(OR(A15="",ROW()-5>$E$2-1,F15="",F16=""),"",F16-F15) -> 2.4791494e-05 | I15: =IF(OR(A15="",ROW()-5>$E$2-2,H15="",H16=""),"",H16-H15) -> -9.6713574e-07 | J15: =IF(OR(A15="",ROW()-5>$E$2-3,I15="",I16=""),"",I16-I15) -> 5.4781591e-07 | K15: =IF(OR(J15="",ROW()-5>$E$2-3),"",$B$2*J15^2) -> 3.0010227e-06
A16: =IF(ROW()-5<=$E$2,Inputs!A16,"") -> 30 | B16: =IF(A16="","",Inputs!B16) -> 281389.11 | C16: =IF(A16="","",Inputs!C16) -> 193.02 | D16: =IF(A16="","",Inputs!D16) -> 0.00068595405 | E16: =IF(A16="","",Inputs!F16) -> 281389.11 | F16: 0.00070249136 | G16: =IF(A16="","",E16*(F16-D16)^2) -> 7.6955016e-05 | H16: =IF(OR(A16="",ROW()-5>$E$2-1,F16="",F17=""),"",F17-F16) -> 2.3824359e-05 | I16: =IF(OR(A16="",ROW()-5>$E$2-2,H16="",H17=""),"",H17-H16) -> -4.1931983e-07 | J16: =IF(OR(A16="",ROW()-5>$E$2-3,I16="",I17=""),"",I17-I16) -> 8.6022922e-07 | K16: =IF(OR(J16="",ROW()-5>$E$2-3),"",$B$2*J16^2) -> 7.3999432e-06
A17: =IF(ROW()-5<=$E$2,Inputs!A17,"") -> 31 | B17: =IF(A17="","",Inputs!B17) -> 289432.24 | C17: =IF(A17="","",Inputs!C17) -> 203.02 | D17: =IF(A17="","",Inputs!D17) -> 0.00070144224 | E17: =IF(A17="","",Inputs!F17) -> 289432.24 | F17: 0.00072631572 | G17: =IF(A17="","",E17*(F17-D17)^2) -> 0.00017906875 | H17: =IF(OR(A17="",ROW()-5>$E$2-1,F17="",F18=""),"",F18-F17) -> 2.3405039e-05 | I17: =IF(OR(A17="",ROW()-5>$E$2-2,H17="",H18=""),"",H18-H17) -> 4.409094e-07 | J17: =IF(OR(A17="",ROW()-5>$E$2-3,I17="",I18=""),"",I18-I17) -> 1.7152405e-06 | K17: =IF(OR(J17="",ROW()-5>$E$2-3),"",$B$2*J17^2) -> 2.9420499e-05
A18: =IF(ROW()-5<=$E$2,Inputs!A18,"") -> 32 | B18: =IF(A18="","",Inputs!B18) -> 300471.11 | C18: =IF(A18="","",Inputs!C18) -> 234.02 | D18: =IF(A18="","",Inputs!D18) -> 0.0007788436 | E18: =IF(A18="","",Inputs!F18) -> 300471.11 | F18: 0.00074972076 | G18: =IF(A18="","",E18*(F18-D18)^2) -> 0.0002548415 | H18: =IF(OR(A18="",ROW()-5>$E$2-1,F18="",F19=""),"",F19-F18) -> 2.3845948e-05 | I18: =IF(OR(A18="",ROW()-5>$E$2-2,H18="",H19=""),"",H19-H18) -> 2.1561499e-06 | J18: =IF(OR(A18="",ROW()-5>$E$2-3,I18="",I19=""),"",I19-I18) -> 2.2582472e-06 | K18: =IF(OR(J18="",ROW()-5>$E$2-3),"",$B$2*J18^2) -> 5.0996805e-05
A19: =IF(ROW()-5<=$E$2,Inputs!A19,"") -> 33 | B19: =IF(A19="","",Inputs!B19) -> 311000.42 | C19: =IF(A19="","",Inputs!C19) -> 239.03 | D19: =IF(A19="","",Inputs!D19) -> 0.00076858417 | E19: =IF(A19="","",Inputs!F19) -> 311000.42 | F19: 0.00077356671 | G19: =IF(A19="","",E19*(F19-D19)^2) -> 7.7207868e-06 | H19: =IF(OR(A19="",ROW()-5>$E$2-1,F19="",F20=""),"",F20-F19) -> 2.6002098e-05 | I19: =IF(OR(A19="",ROW()-5>$E$2-2,H19="",H20=""),"",H20-H19) -> 4.4143971e-06 | J19: =IF(OR(A19="",ROW()-5>$E$2-3,I19="",I20=""),"",I20-I19) -> 2.6599722e-06 | K19: =IF(OR(J19="",ROW()-5>$E$2-3),"",$B$2*J19^2) -> 7.075452e-05
... A45: =IF(ROW()-5<=$E$2,Inputs!A45,"") -> 59 | B45: =IF(A45="","",Inputs!B45) -> 225403.6 | C45: =IF(A45="","",Inputs!C45) -> 1184.14 | D45: =IF(A45="","",Inputs!D45) -> 0.005253421 | E45: =IF(A45="","",Inputs!F45) -> 225403.6 | F45: 0.0052262204 | G45: =IF(A45="","",E45*(F45-D45)^2) -> 0.0001667699 | H45: =IF(OR(A45="",ROW()-5>$E$2-1,F45="",F46=""),"",F46-F45) | I45: =IF(OR(A45="",ROW()-5>$E$2-2,H45="",H46=""),"",H46-H45) | J45: =IF(OR(A45="",ROW()-5>$E$2-3,I45="",I46=""),"",I46-I45) | K45: =IF(OR(J45="",ROW()-5>$E$2-3),"",$B$2*J45^2)
A46: =IF(ROW()-5<=$E$2,Inputs!A46,"") | B46: =IF(A46="","",Inputs!B46) | C46: =IF(A46="","",Inputs!C46) | D46: =IF(A46="","",Inputs!D46) | E46: =IF(A46="","",Inputs!F46) | G46: =IF(A46="","",E46*(F46-D46)^2) | H46: =IF(OR(A46="",ROW()-5>$E$2-1,F46="",F47=""),"",F47-F46) | I46: =IF(OR(A46="",ROW()-5>$E$2-2,H46="",H47=""),"",H47-H46) | J46: =IF(OR(A46="",ROW()-5>$E$2-3,I46="",I47=""),"",I47-I46) | K46: =IF(OR(J46="",ROW()-5>$E$2-3),"",$B$2*J46^2)
A47: =IF(ROW()-5<=$E$2,Inputs!A47,"") | B47: =IF(A47="","",Inputs!B47) | C47: =IF(A47="","",Inputs!C47) | D47: =IF(A47="","",Inputs!D47) | E47: =IF(A47="","",Inputs!F47) | G47: =IF(A47="","",E47*(F47-D47)^2) | H47: =IF(OR(A47="",ROW()-5>$E$2-1,F47="",F48=""),"",F48-F47) | I47: =IF(OR(A47="",ROW()-5>$E$2-2,H47="",H48=""),"",H48-H47) | J47: =IF(OR(A47="",ROW()-5>$E$2-3,I47="",I48=""),"",I48-I47) | K47: =IF(OR(J47="",ROW()-5>$E$2-3),"",$B$2*J47^2)
A48: =IF(ROW()-5<=$E$2,Inputs!A48,"") | B48: =IF(A48="","",Inputs!B48) | C48: =IF(A48="","",Inputs!C48) | D48: =IF(A48="","",Inputs!D48) | E48: =IF(A48="","",Inputs!F48) | G48: =IF(A48="","",E48*(F48-D48)^2) | H48: =IF(OR(A48="",ROW()-5>$E$2-1,F48="",F49=""),"",F49-F48) | I48: =IF(OR(A48="",ROW()-5>$E$2-2,H48="",H49=""),"",H49-H48) | J48: =IF(OR(A48="",ROW()-5>$E$2-3,I48="",I49=""),"",I49-I48) | K48: =IF(OR(J48="",ROW()-5>$E$2-3),"",$B$2*J48^2)
A49: =IF(ROW()-5<=$E$2,Inputs!A49,"") | B49: =IF(A49="","",Inputs!B49) | C49: =IF(A49="","",Inputs!C49) | D49: =IF(A49="","",Inputs!D49) | E49: =IF(A49="","",Inputs!F49) | G49: =IF(A49="","",E49*(F49-D49)^2) | H49: =IF(OR(A49="",ROW()-5>$E$2-1,F49="",F50=""),"",F50-F49) | I49: =IF(OR(A49="",ROW()-5>$E$2-2,H49="",H50=""),"",H50-H49) | J49: =IF(OR(A49="",ROW()-5>$E$2-3,I49="",I50=""),"",I50-I49) | K49: =IF(OR(J49="",ROW()-5>$E$2-3),"",$B$2*J49^2)
A50: =IF(ROW()-5<=$E$2,Inputs!A50,"") | B50: =IF(A50="","",Inputs!B50) | C50: =IF(A50="","",Inputs!C50) | D50: =IF(A50="","",Inputs!D50) | E50: =IF(A50="","",Inputs!F50) | G50: =IF(A50="","",E50*(F50-D50)^2) | H50: =IF(OR(A50="",ROW()-5>$E$2-1,F50="",F51=""),"",F51-F50) | I50: =IF(OR(A50="",ROW()-5>$E$2-2,H50="",H51=""),"",H51-H50) | J50: =IF(OR(A50="",ROW()-5>$E$2-3,I50="",I51=""),"",I51-I50) | K50: =IF(OR(J50="",ROW()-5>$E$2-3),"",$B$2*J50^2)
A51: =IF(ROW()-5<=$E$2,Inputs!A51,"") | B51: =IF(A51="","",Inputs!B51) | C51: =IF(A51="","",Inputs!C51) | D51: =IF(A51="","",Inputs!D51) | E51: =IF(A51="","",Inputs!F51) | G51: =IF(A51="","",E51*(F51-D51)^2) | H51: =IF(OR(A51="",ROW()-5>$E$2-1,F51="",F52=""),"",F52-F51) | I51: =IF(OR(A51="",ROW()-5>$E$2-2,H51="",H52=""),"",H52-H51) | J51: =IF(OR(A51="",ROW()-5>$E$2-3,I51="",I52=""),"",I52-I51) | K51: =IF(OR(J51="",ROW()-5>$E$2-3),"",$B$2*J51^2)
A52: =IF(ROW()-5<=$E$2,Inputs!A52,"") | B52: =IF(A52="","",Inputs!B52) | C52: =IF(A52="","",Inputs!C52) | D52: =IF(A52="","",Inputs!D52) | E52: =IF(A52="","",Inputs!F52) | G52: =IF(A52="","",E52*(F52-D52)^2) | H52: =IF(OR(A52="",ROW()-5>$E$2-1,F52="",F53=""),"",F53-F52) | I52: =IF(OR(A52="",ROW()-5>$E$2-2,H52="",H53=""),"",H53-H52) | J52: =IF(OR(A52="",ROW()-5>$E$2-3,I52="",I53=""),"",I53-I52) | K52: =IF(OR(J52="",ROW()-5>$E$2-3),"",$B$2*J52^2)
A53: =IF(ROW()-5<=$E$2,Inputs!A53,"") | B53: =IF(A53="","",Inputs!B53) | C53: =IF(A53="","",Inputs!C53) | D53: =IF(A53="","",Inputs!D53) | E53: =IF(A53="","",Inputs!F53) | G53: =IF(A53="","",E53*(F53-D53)^2) | H53: =IF(OR(A53="",ROW()-5>$E$2-1,F53="",F54=""),"",F54-F53) | I53: =IF(OR(A53="",ROW()-5>$E$2-2,H53="",H54=""),"",H54-H53) | J53: =IF(OR(A53="",ROW()-5>$E$2-3,I53="",I54=""),"",I54-I53) | K53: =IF(OR(J53="",ROW()-5>$E$2-3),"",$B$2*J53^2)
A54: =IF(ROW()-5<=$E$2,Inputs!A54,"") | B54: =IF(A54="","",Inputs!B54) | C54: =IF(A54="","",Inputs!C54) | D54: =IF(A54="","",Inputs!D54) | E54: =IF(A54="","",Inputs!F54) | G54: =IF(A54="","",E54*(F54-D54)^2) | H54: =IF(OR(A54="",ROW()-5>$E$2-1,F54="",F55=""),"",F55-F54) | I54: =IF(OR(A54="",ROW()-5>$E$2-2,H54="",H55=""),"",H55-H54) | J54: =IF(OR(A54="",ROW()-5>$E$2-3,I54="",I55=""),"",I55-I54) | K54: =IF(OR(J54="",ROW()-5>$E$2-3),"",$B$2*J54^2)
A55: =IF(ROW()-5<=$E$2,Inputs!A55,"") | B55: =IF(A55="","",Inputs!B55) | C55: =IF(A55="","",Inputs!C55) | D55: =IF(A55="","",Inputs!D55) | E55: =IF(A55="","",Inputs!F55) | G55: =IF(A55="","",E55*(F55-D55)^2) | H55: =IF(OR(A55="",ROW()-5>$E$2-1,F55="",F56=""),"",F56-F55) | I55: =IF(OR(A55="",ROW()-5>$E$2-2,H55="",H56=""),"",H56-H55) | J55: =IF(OR(A55="",ROW()-5>$E$2-3,I55="",I56=""),"",I56-I55) | K55: =IF(OR(J55="",ROW()-5>$E$2-3),"",$B$2*J55^2)
A56: =IF(ROW()-5<=$E$2,Inputs!A56,"") | B56: =IF(A56="","",Inputs!B56) | C56: =IF(A56="","",Inputs!C56) | D56: =IF(A56="","",Inputs!D56) | E56: =IF(A56="","",Inputs!F56) | G56: =IF(A56="","",E56*(F56-D56)^2) | H56: =IF(OR(A56="",ROW()-5>$E$2-1,F56="",F57=""),"",F57-F56) | I56: =IF(OR(A56="",ROW()-5>$E$2-2,H56="",H57=""),"",H57-H56) | J56: =IF(OR(A56="",ROW()-5>$E$2-3,I56="",I57=""),"",I57-I56) | K56: =IF(OR(J56="",ROW()-5>$E$2-3),"",$B$2*J56^2)
A57: =IF(ROW()-5<=$E$2,Inputs!A57,"") | B57: =IF(A57="","",Inputs!B57) | C57: =IF(A57="","",Inputs!C57) | D57: =IF(A57="","",Inputs!D57) | E57: =IF(A57="","",Inputs!F57) | G57: =IF(A57="","",E57*(F57-D57)^2) | H57: =IF(OR(A57="",ROW()-5>$E$2-1,F57="",F58=""),"",F58-F57) | I57: =IF(OR(A57="",ROW()-5>$E$2-2,H57="",H58=""),"",H58-H57) | J57: =IF(OR(A57="",ROW()-5>$E$2-3,I57="",I58=""),"",I58-I57) | K57: =IF(OR(J57="",ROW()-5>$E$2-3),"",$B$2*J57^2)
... A85: =IF(ROW()-5<=$E$2,Inputs!A85,"") | B85: =IF(A85="","",Inputs!B85) | C85: =IF(A85="","",Inputs!C85) | D85: =IF(A85="","",Inputs!D85) | E85: =IF(A85="","",Inputs!F85) | G85: =IF(A85="","",E85*(F85-D85)^2) | H85: =IF(OR(A85="",ROW()-5>$E$2-1,F85="",F86=""),"",F86-F85) | I85: =IF(OR(A85="",ROW()-5>$E$2-2,H85="",H86=""),"",H86-H85) | J85: =IF(OR(A85="",ROW()-5>$E$2-3,I85="",I86=""),"",I86-I85) | K85: =IF(OR(J85="",ROW()-5>$E$2-3),"",$B$2*J85^2)
A86: =IF(ROW()-5<=$E$2,Inputs!A86,"") | B86: =IF(A86="","",Inputs!B86) | C86: =IF(A86="","",Inputs!C86) | D86: =IF(A86="","",Inputs!D86) | E86: =IF(A86="","",Inputs!F86) | F86: =IF(A86="","",D86) | G86: =IF(A86="","",E86*(F86-D86)^2) | H86: =IF(OR(A86="",ROW()-5>$E$2-1,F86="",F87=""),"",F87-F86) | I86: =IF(OR(A86="",ROW()-5>$E$2-2,H86="",H87=""),"",H87-H86) | J86: =IF(OR(A86="",ROW()-5>$E$2-3,I86="",I87=""),"",I87-I86) | K86: =IF(OR(J86="",ROW()-5>$E$2-3),"",$B$2*J86^2)
A87: =IF(ROW()-5<=$E$2,Inputs!A87,"") | B87: =IF(A87="","",Inputs!B87) | C87: =IF(A87="","",Inputs!C87) | D87: =IF(A87="","",Inputs!D87) | E87: =IF(A87="","",Inputs!F87) | F87: =IF(A87="","",D87) | G87: =IF(A87="","",E87*(F87-D87)^2) | H87: =IF(OR(A87="",ROW()-5>$E$2-1,F87="",F88=""),"",F88-F87) | I87: =IF(OR(A87="",ROW()-5>$E$2-2,H87="",H88=""),"",H88-H87) | J87: =IF(OR(A87="",ROW()-5>$E$2-3,I87="",I88=""),"",I88-I87) | K87: =IF(OR(J87="",ROW()-5>$E$2-3),"",$B$2*J87^2)
A88: =IF(ROW()-5<=$E$2,Inputs!A88,"") | B88: =IF(A88="","",Inputs!B88) | C88: =IF(A88="","",Inputs!C88) | D88: =IF(A88="","",Inputs!D88) | E88: =IF(A88="","",Inputs!F88) | F88: =IF(A88="","",D88) | G88: =IF(A88="","",E88*(F88-D88)^2) | H88: =IF(OR(A88="",ROW()-5>$E$2-1,F88="",F89=""),"",F89-F88) | I88: =IF(OR(A88="",ROW()-5>$E$2-2,H88="",H89=""),"",H89-H88) | J88: =IF(OR(A88="",ROW()-5>$E$2-3,I88="",I89=""),"",I89-I88) | K88: =IF(OR(J88="",ROW()-5>$E$2-3),"",$B$2*J88^2)
A89: =IF(ROW()-5<=$E$2,Inputs!A89,"") | B89: =IF(A89="","",Inputs!B89) | C89: =IF(A89="","",Inputs!C89) | D89: =IF(A89="","",Inputs!D89) | E89: =IF(A89="","",Inputs!F89) | F89: =IF(A89="","",D89) | G89: =IF(A89="","",E89*(F89-D89)^2) | H89: =IF(OR(A89="",ROW()-5>$E$2-1,F89="",F90=""),"",F90-F89) | I89: =IF(OR(A89="",ROW()-5>$E$2-2,H89="",H90=""),"",H90-H89) | J89: =IF(OR(A89="",ROW()-5>$E$2-3,I89="",I90=""),"",I90-I89) | K89: =IF(OR(J89="",ROW()-5>$E$2-3),"",$B$2*J89^2)
A90: =IF(ROW()-5<=$E$2,Inputs!A90,"") | B90: =IF(A90="","",Inputs!B90) | C90: =IF(A90="","",Inputs!C90) | D90: =IF(A90="","",Inputs!D90) | E90: =IF(A90="","",Inputs!F90) | F90: =IF(A90="","",D90) | G90: =IF(A90="","",E90*(F90-D90)^2) | H90: =IF(OR(A90="",ROW()-5>$E$2-1,F90="",F91=""),"",F91-F90) | I90: =IF(OR(A90="",ROW()-5>$E$2-2,H90="",H91=""),"",H91-H90) | J90: =IF(OR(A90="",ROW()-5>$E$2-3,I90="",I91=""),"",I91-I90) | K90: =IF(OR(J90="",ROW()-5>$E$2-3),"",$B$2*J90^2)
A91: =IF(ROW()-5<=$E$2,Inputs!A91,"") | B91: =IF(A91="","",Inputs!B91) | C91: =IF(A91="","",Inputs!C91) | D91: =IF(A91="","",Inputs!D91) | E91: =IF(A91="","",Inputs!F91) | F91: =IF(A91="","",D91) | G91: =IF(A91="","",E91*(F91-D91)^2) | H91: =IF(OR(A91="",ROW()-5>$E$2-1,F91="",F92=""),"",F92-F91) | I91: =IF(OR(A91="",ROW()-5>$E$2-2,H91="",H92=""),"",H92-H91) | J91: =IF(OR(A91="",ROW()-5>$E$2-3,I91="",I92=""),"",I92-I91) | K91: =IF(OR(J91="",ROW()-5>$E$2-3),"",$B$2*J91^2)
A92: =IF(ROW()-5<=$E$2,Inputs!A92,"") | B92: =IF(A92="","",Inputs!B92) | C92: =IF(A92="","",Inputs!C92) | D92: =IF(A92="","",Inputs!D92) | E92: =IF(A92="","",Inputs!F92) | F92: =IF(A92="","",D92) | G92: =IF(A92="","",E92*(F92-D92)^2) | H92: =IF(OR(A92="",ROW()-5>$E$2-1,F92="",F93=""),"",F93-F92) | I92: =IF(OR(A92="",ROW()-5>$E$2-2,H92="",H93=""),"",H93-H92) | J92: =IF(OR(A92="",ROW()-5>$E$2-3,I92="",I93=""),"",I93-I92) | K92: =IF(OR(J92="",ROW()-5>$E$2-3),"",$B$2*J92^2)
A93: =IF(ROW()-5<=$E$2,Inputs!A93,"") | B93: =IF(A93="","",Inputs!B93) | C93: =IF(A93="","",Inputs!C93) | D93: =IF(A93="","",Inputs!D93) | E93: =IF(A93="","",Inputs!F93) | F93: =IF(A93="","",D93) | G93: =IF(A93="","",E93*(F93-D93)^2) | H93: =IF(OR(A93="",ROW()-5>$E$2-1,F93="",F94=""),"",F94-F93) | I93: =IF(OR(A93="",ROW()-5>$E$2-2,H93="",H94=""),"",H94-H93) | J93: =IF(OR(A93="",ROW()-5>$E$2-3,I93="",I94=""),"",I94-I93) | K93: =IF(OR(J93="",ROW()-5>$E$2-3),"",$B$2*J93^2)
...

Sheet WH_Analytical
A1: WH Analytical Solution | L1: WH Analytical Solution
A2: K | B2: =Inputs!B2 -> 10000000 | D2: n | E2: =Inputs!E2 -> 40 | I2: Note | J2: Analytical qdot_x solves (W + K D'D) q = W qhat exactly. WH_Numerical currently shows the trial qdot_x column, not a Solver-optimized result. | L2: K | M2: =Inputs!B2 -> 10000000 | O2: n | P2: =Inputs!E2 -> 40
L4: Active A block (top-left n x n only)
A5: b_i | B5: mdot_i | C5: Residual_i = (A mdot - b)_i | E5: Age | F5: mhat_x | G5: mdot_x (analytical) | J5: mdot_x (numerical) | L5: i\j | M5: 1 | N5: 2 | O5: 3 | P5: 4 | Q5: 5 | R5: 6 | S5: 7 | T5: 8 | U5: 9 | V5: 10 | W5: 11 | X5: 12 | Y5: 13 | Z5: 14 | AA5: 15 | AB5: 16 | AC5: 17 | AD5: 18 | AE5: 19 | AF5: 20 | AG5: 21 | AH5: 22 | AI5: 23 | AJ5: 24 | AK5: 25 | AL5: 26 | AM5: 27 | AN5: 28 | AO5: 29 | AP5: 30 | AQ5: 31 | AR5: 32 | AS5: 33 | AT5: 34 | AU5: 35 | AV5: 36 | AW5: 37 | AX5: 38 | AY5: 39 | AZ5: 40 | BA5: 41 | BB5: 42 | BC5: 43 | BD5: 44 | BE5: 45 | BF5: 46 | BG5: 47 | BH5: 48 | BI5: 49 | BJ5: 50 | BK5: 51 | BL5: 52 | BM5: 53 | BN5: 54 | BO5: 55 | BP5: 56 | BQ5: 57 | BR5: 58 | BS5: 59 | BT5: 60 | BU5: 61 | BV5: 62 | BW5: 63 | BX5: 64 | BY5: 65 | BZ5: 66 | CA5: 67 | CB5: 68 | CC5: 69 | CD5: 70 | CE5: 71 | CF5: 72 | CG5: 73 | CH5: 74 | CI5: 75 | CJ5: 76 | CK5: 77 | CL5: 78 | CM5: 79 | CN5: 80 | CO5: 81 | CP5: 82 | CQ5: 83 | CR5: 84 | CS5: 85 | CT5: 86 | CU5: 87 | CV5: 88 | CW5: 89 | CX5: 90 | CY5: 91 | CZ5: 92 | DA5: 93 | DB5: 94 | DC5: 95 | DD5: 96 | DE5: 97 | DF5: 98 | DG5: 99 | DH5: 100 | DI5: 101 | DJ5: 102 | DK5: 103 | DL5: 104 | DM5: 105 | DN5: 106 | DO5: 107 | DP5: 108 | DQ5: 109 | DR5: 110 | DS5: 111 | DT5: 112 | DU5: 113 | DV5: 114 | DW5: 115 | DX5: 116 | DY5: 117 | DZ5: 118 | EA5: 119 | EB5: 120
A6: =IF(L6<=$P$2,INDEX(WH_Backend!$E$6:$E$125,L6),0) -> 164.01 | B6: {=IF(L6<=$P$2,MMULT(M131:INDEX(M131:EF131,$P$2),$A$6:INDEX($A$6:$A$125,$P$2)),0)} -> 0.00058266542 | C6: =IF(L6<=$P$2,MMULT(M6:INDEX(M6:EF6,$P$2),$B$6:INDEX($B$6:$B$125,$P$2))-A6,0) -> 2.2737368e-13 | E6: =IF(L6<=$P$2,Inputs!A6,"") -> 20 | F6: =IF(L6<=$P$2,Inputs!D6,"") -> 0.00057851372 | G6: =IF(L6<=$P$2,B6,"") -> 0.00058266542 | J6: =IF($L6<=$E$2,WH_Numerical!$F6,"") -> 0.00058293682 | L6: 1 | M6: =IF(AND($L6<=$P$2,1<=$P$2),INDEX(WH_Backend!$DZ$6:$IO$125,$L6,1),0) -> 10283502 | N6: =IF(AND($L6<=$P$2,2<=$P$2),INDEX(WH_Backend!$DZ$6:$IO$125,$L6,2),0) -> -30000000 | O6: =IF(AND($L6<=$P$2,3<=$P$2),INDEX(WH_Backend!$DZ$6:$IO$125,$L6,3),0) -> 30000000 | P6: =IF(AND($L6<=$P$2,4<=$P$2),INDEX(WH_Backend!$DZ$6:$IO$125,$L6,4),0) -> -10000000 | Q6: =IF(AND($L6<=$P$2,5<=$P$2),INDEX(WH_Backend!$DZ$6:$IO$125,$L6,5),0) -> 0 | R6: =IF(AND($L6<=$P$2,6<=$P$2),INDEX(WH_Backend!$DZ$6:$IO$125,$L6,6),0) -> 0 | S6: =IF(AND($L6<=$P$2,7<=$P$2),INDEX(WH_Backend!$DZ$6:$IO$125,$L6,7),0) -> 0 | T6: =IF(AND($L6<=$P$2,8<=$P$2),INDEX(WH_Backend!$DZ$6:$IO$125,$L6,8),0) -> 0 | U6: =IF(AND($L6<=$P$2,9<=$P$2),INDEX(WH_Backend!$DZ$6:$IO$125,$L6,9),0) -> 0 | V6: =IF(AND($L6<=$P$2,10<=$P$2),INDEX(WH_Backend!$DZ$6:$IO$125,$L6,10),0) -> 0 | W6: =IF(AND($L6<=$P$2,11<=$P$2),INDEX(WH_Backend!$DZ$6:$IO$125,$L6,11),0) -> 0 | X6: =IF(AND($L6<=$P$2,12<=$P$2),INDEX(WH_Backend!$DZ$6:$IO$125,$L6,12),0) -> 0 | Y6: =IF(AND($L6<=$P$2,13<=$P$2),INDEX(WH_Backend!$DZ$6:$IO$125,$L6,13),0) -> 0 | Z6: =IF(AND($L6<=$P$2,14<=$P$2),INDEX(WH_Backend!$DZ$6:$IO$125,$L6,14),0) -> 0 | AA6: =IF(AND($L6<=$P$2,15<=$P$2),INDEX(WH_Backend!$DZ$6:$IO$125,$L6,15),0) -> 0 | AB6: =IF(AND($L6<=$P$2,16<=$P$2),INDEX(WH_Backend!$DZ$6:$IO$125,$L6,16),0) -> 0 | AC6: =IF(AND($L6<=$P$2,17<=$P$2),INDEX(WH_Backend!$DZ$6:$IO$125,$L6,17),0) -> 0 | AD6: =IF(AND($L6<=$P$2,18<=$P$2),INDEX(WH_Backend!$DZ$6:$IO$125,$L6,18),0) -> 0 | AE6: =IF(AND($L6<=$P$2,19<=$P$2),INDEX(WH_Backend!$DZ$6:$IO$125,$L6,19),0) -> 0 | AF6: =IF(AND($L6<=$P$2,20<=$P$2),INDEX(WH_Backend!$DZ$6:$IO$125,$L6,20),0) -> 0 | AG6: =IF(AND($L6<=$P$2,21<=$P$2),INDEX(WH_Backend!$DZ$6:$IO$125,$L6,21),0) -> 0 | AH6: =IF(AND($L6<=$P$2,22<=$P$2),INDEX(WH_Backend!$DZ$6:$IO$125,$L6,22),0) -> 0 | AI6: =IF(AND($L6<=$P$2,23<=$P$2),INDEX(WH_Backend!$DZ$6:$IO$125,$L6,23),0) -> 0 | AJ6: =IF(AND($L6<=$P$2,24<=$P$2),INDEX(WH_Backend!$DZ$6:$IO$125,$L6,24),0) -> 0 | AK6: =IF(AND($L6<=$P$2,25<=$P$2),INDEX(WH_Backend!$DZ$6:$IO$125,$L6,25),0) -> 0 | AL6: =IF(AND($L6<=$P$2,26<=$P$2),INDEX(WH_Backend!$DZ$6:$IO$125,$L6,26),0) -> 0 | AM6: =IF(AND($L6<=$P$2,27<=$P$2),INDEX(WH_Backend!$DZ$6:$IO$125,$L6,27),0) -> 0 | AN6: =IF(AND($L6<=$P$2,28<=$P$2),INDEX(WH_Backend!$DZ$6:$IO$125,$L6,28),0) -> 0 | AO6: =IF(AND($L6<=$P$2,29<=$P$2),INDEX(WH_Backend!$DZ$6:$IO$125,$L6,29),0) -> 0 | AP6: =IF(AND($L6<=$P$2,30<=$P$2),INDEX(WH_Backend!$DZ$6:$IO$125,$L6,30),0) -> 0 | AQ6: =IF(AND($L6<=$P$2,31<=$P$2),INDEX(WH_Backend!$DZ$6:$IO$125,$L6,31),0) -> 0 | AR6: =IF(AND($L6<=$P$2,32<=$P$2),INDEX(WH_Backend!$DZ$6:$IO$125,$L6,32),0) -> 0 | AS6: =IF(AND($L6<=$P$2,33<=$P$2),INDEX(WH_Backend!$DZ$6:$IO$125,$L6,33),0) -> 0 | AT6: =IF(AND($L6<=$P$2,34<=$P$2),INDEX(WH_Backend!$DZ$6:$IO$125,$L6,34),0) -> 0 | AU6: =IF(AND($L6<=$P$2,35<=$P$2),INDEX(WH_Backend!$DZ$6:$IO$125,$L6,35),0) -> 0 | AV6: =IF(AND($L6<=$P$2,36<=$P$2),INDEX(WH_Backend!$DZ$6:$IO$125,$L6,36),0) -> 0 | AW6: =IF(AND($L6<=$P$2,37<=$P$2),INDEX(WH_Backend!$DZ$6:$IO$125,$L6,37),0) -> 0 | AX6: =IF(AND($L6<=$P$2,38<=$P$2),INDEX(WH_Backend!$DZ$6:$IO$125,$L6,38),0) -> 0 | AY6: =IF(AND($L6<=$P$2,39<=$P$2),INDEX(WH_Backend!$DZ$6:$IO$125,$L6,39),0) -> 0 | AZ6: =IF(AND($L6<=$P$2,40<=$P$2),INDEX(WH_Backend!$DZ$6:$IO$125,$L6,40),0) -> 0 | BA6: =IF(AND($L6<=$P$2,41<=$P$2),INDEX(WH_Backend!$DZ$6:$IO$125,$L6,41),0) -> 0 | BB6: =IF(AND($L6<=$P$2,42<=$P$2),INDEX(WH_Backend!$DZ$6:$IO$125,$L6,42),0) -> 0 | BC6: =IF(AND($L6<=$P$2,43<=$P$2),INDEX(WH_Backend!$DZ$6:$IO$125,$L6,43),0) -> 0 | BD6: =IF(AND($L6<=$P$2,44<=$P$2),INDEX(WH_Backend!$DZ$6:$IO$125,$L6,44),0) -> 0 | BE6: =IF(AND($L6<=$P$2,45<=$P$2),INDEX(WH_Backend!$DZ$6:$IO$125,$L6,45),0) -> 0 | BF6: =IF(AND($L6<=$P$2,46<=$P$2),INDEX(WH_Backend!$DZ$6:$IO$125,$L6,46),0) -> 0 | BG6: =IF(AND($L6<=$P$2,47<=$P$2),INDEX(WH_Backend!$DZ$6:$IO$125,$L6,47),0) -> 0 | BH6: =IF(AND($L6<=$P$2,48<=$P$2),INDEX(WH_Backend!$DZ$6:$IO$125,$L6,48),0) -> 0 | BI6: =IF(AND($L6<=$P$2,49<=$P$2),INDEX(WH_Backend!$DZ$6:$IO$125,$L6,49),0) -> 0 | BJ6: =IF(AND($L6<=$P$2,50<=$P$2),INDEX(WH_Backend!$DZ$6:$IO$125,$L6,50),0) -> 0 | BK6: =IF(AND($L6<=$P$2,51<=$P$2),INDEX(WH_Backend!$DZ$6:$IO$125,$L6,51),0) -> 0 | BL6: =IF(AND($L6<=$P$2,52<=$P$2),INDEX(WH_Backend!$DZ$6:$IO$125,$L6,52),0) -> 0 | BM6: =IF(AND($L6<=$P$2,53<=$P$2),INDEX(WH_Backend!$DZ$6:$IO$125,$L6,53),0) -> 0 | BN6: =IF(AND($L6<=$P$2,54<=$P$2),INDEX(WH_Backend!$DZ$6:$IO$125,$L6,54),0) -> 0 | BO6: =IF(AND($L6<=$P$2,55<=$P$2),INDEX(WH_Backend!$DZ$6:$IO$125,$L6,55),0) -> 0 | BP6: =IF(AND($L6<=$P$2,56<=$P$2),INDEX(WH_Backend!$DZ$6:$IO$125,$L6,56),0) -> 0 | BQ6: =IF(AND($L6<=$P$2,57<=$P$2),INDEX(WH_Backend!$DZ$6:$IO$125,$L6,57),0) -> 0 | BR6: =IF(AND($L6<=$P$2,58<=$P$2),INDEX(WH_Backend!$DZ$6:$IO$125,$L6,58),0) -> 0 | BS6: =IF(AND($L6<=$P$2,59<=$P$2),INDEX(WH_Backend!$DZ$6:$IO$125,$L6,59),0) -> 0 | BT6: =IF(AND($L6<=$P$2,60<=$P$2),INDEX(WH_Backend!$DZ$6:$IO$125,$L6,60),0) -> 0 | BU6: =IF(AND($L6<=$P$2,61<=$P$2),INDEX(WH_Backend!$DZ$6:$IO$125,$L6,61),0) -> 0 | BV6: =IF(AND($L6<=$P$2,62<=$P$2),INDEX(WH_Backend!$DZ$6:$IO$125,$L6,62),0) -> 0 | BW6: =IF(AND($L6<=$P$2,63<=$P$2),INDEX(WH_Backend!$DZ$6:$IO$125,$L6,63),0) -> 0 | BX6: =IF(AND($L6<=$P$2,64<=$P$2),INDEX(WH_Backend!$DZ$6:$IO$125,$L6,64),0) -> 0 | BY6: =IF(AND($L6<=$P$2,65<=$P$2),INDEX(WH_Backend!$DZ$6:$IO$125,$L6,65),0) -> 0 | BZ6: =IF(AND($L6<=$P$2,66<=$P$2),INDEX(WH_Backend!$DZ$6:$IO$125,$L6,66),0) -> 0 | CA6: =IF(AND($L6<=$P$2,67<=$P$2),INDEX(WH_Backend!$DZ$6:$IO$125,$L6,67),0) -> 0 | CB6: =IF(AND($L6<=$P$2,68<=$P$2),INDEX(WH_Backend!$DZ$6:$IO$125,$L6,68),0) -> 0 | CC6: =IF(AND($L6<=$P$2,69<=$P$2),INDEX(WH_Backend!$DZ$6:$IO$125,$L6,69),0) -> 0 | CD6: =IF(AND($L6<=$P$2,70<=$P$2),INDEX(WH_Backend!$DZ$6:$IO$125,$L6,70),0) -> 0 | CE6: =IF(AND($L6<=$P$2,71<=$P$2),INDEX(WH_Backend!$DZ$6:$IO$125,$L6,71),0) -> 0 | CF6: =IF(AND($L6<=$P$2,72<=$P$2),INDEX(WH_Backend!$DZ$6:$IO$125,$L6,72),0) -> 0 | CG6: =IF(AND($L6<=$P$2,73<=$P$2),INDEX(WH_Backend!$DZ$6:$IO$125,$L6,73),0) -> 0 | CH6: =IF(AND($L6<=$P$2,74<=$P$2),INDEX(WH_Backend!$DZ$6:$IO$125,$L6,74),0) -> 0 | CI6: =IF(AND($L6<=$P$2,75<=$P$2),INDEX(WH_Backend!$DZ$6:$IO$125,$L6,75),0) -> 0 | CJ6: =IF(AND($L6<=$P$2,76<=$P$2),INDEX(WH_Backend!$DZ$6:$IO$125,$L6,76),0) -> 0 | CK6: =IF(AND($L6<=$P$2,77<=$P$2),INDEX(WH_Backend!$DZ$6:$IO$125,$L6,77),0) -> 0 | CL6: =IF(AND($L6<=$P$2,78<=$P$2),INDEX(WH_Backend!$DZ$6:$IO$125,$L6,78),0) -> 0 | CM6: =IF(AND($L6<=$P$2,79<=$P$2),INDEX(WH_Backend!$DZ$6:$IO$125,$L6,79),0) -> 0 | CN6: =IF(AND($L6<=$P$2,80<=$P$2),INDEX(WH_Backend!$DZ$6:$IO$125,$L6,80),0) -> 0 | CO6: =IF(AND($L6<=$P$2,81<=$P$2),INDEX(WH_Backend!$DZ$6:$IO$125,$L6,81),0) -> 0 | CP6: =IF(AND($L6<=$P$2,82<=$P$2),INDEX(WH_Backend!$DZ$6:$IO$125,$L6,82),0) -> 0 | CQ6: =IF(AND($L6<=$P$2,83<=$P$2),INDEX(WH_Backend!$DZ$6:$IO$125,$L6,83),0) -> 0 | CR6: =IF(AND($L6<=$P$2,84<=$P$2),INDEX(WH_Backend!$DZ$6:$IO$125,$L6,84),0) -> 0 | CS6: =IF(AND($L6<=$P$2,85<=$P$2),INDEX(WH_Backend!$DZ$6:$IO$125,$L6,85),0) -> 0 | CT6: =IF(AND($L6<=$P$2,86<=$P$2),INDEX(WH_Backend!$DZ$6:$IO$125,$L6,86),0) -> 0 | CU6: =IF(AND($L6<=$P$2,87<=$P$2),INDEX(WH_Backend!$DZ$6:$IO$125,$L6,87),0) -> 0 | CV6: =IF(AND($L6<=$P$2,88<=$P$2),INDEX(WH_Backend!$DZ$6:$IO$125,$L6,88),0) -> 0 | CW6: =IF(AND($L6<=$P$2,89<=$P$2),INDEX(WH_Backend!$DZ$6:$IO$125,$L6,89),0) -> 0 | CX6: =IF(AND($L6<=$P$2,90<=$P$2),INDEX(WH_Backend!$DZ$6:$IO$125,$L6,90),0) -> 0 | CY6: =IF(AND($L6<=$P$2,91<=$P$2),INDEX(WH_Backend!$DZ$6:$IO$125,$L6,91),0) -> 0 | CZ6: =IF(AND($L6<=$P$2,92<=$P$2),INDEX(WH_Backend!$DZ$6:$IO$125,$L6,92),0) -> 0 | DA6: =IF(AND($L6<=$P$2,93<=$P$2),INDEX(WH_Backend!$DZ$6:$IO$125,$L6,93),0) -> 0 | DB6: =IF(AND($L6<=$P$2,94<=$P$2),INDEX(WH_Backend!$DZ$6:$IO$125,$L6,94),0) -> 0 | DC6: =IF(AND($L6<=$P$2,95<=$P$2),INDEX(WH_Backend!$DZ$6:$IO$125,$L6,95),0) -> 0 | DD6: =IF(AND($L6<=$P$2,96<=$P$2),INDEX(WH_Backend!$DZ$6:$IO$125,$L6,96),0) -> 0 | DE6: =IF(AND($L6<=$P$2,97<=$P$2),INDEX(WH_Backend!$DZ$6:$IO$125,$L6,97),0) -> 0 | DF6: =IF(AND($L6<=$P$2,98<=$P$2),INDEX(WH_Backend!$DZ$6:$IO$125,$L6,98),0) -> 0 | DG6: =IF(AND($L6<=$P$2,99<=$P$2),INDEX(WH_Backend!$DZ$6:$IO$125,$L6,99),0) -> 0 | DH6: =IF(AND($L6<=$P$2,100<=$P$2),INDEX(WH_Backend!$DZ$6:$IO$125,$L6,100),0) -> 0 | DI6: =IF(AND($L6<=$P$2,101<=$P$2),INDEX(WH_Backend!$DZ$6:$IO$125,$L6,101),0) -> 0 | DJ6: =IF(AND($L6<=$P$2,102<=$P$2),INDEX(WH_Backend!$DZ$6:$IO$125,$L6,102),0) -> 0 | DK6: =IF(AND($L6<=$P$2,103<=$P$2),INDEX(WH_Backend!$DZ$6:$IO$125,$L6,103),0) -> 0 | DL6: =IF(AND($L6<=$P$2,104<=$P$2),INDEX(WH_Backend!$DZ$6:$IO$125,$L6,104),0) -> 0 | DM6: =IF(AND($L6<=$P$2,105<=$P$2),INDEX(WH_Backend!$DZ$6:$IO$125,$L6,105),0) -> 0 | DN6: =IF(AND($L6<=$P$2,106<=$P$2),INDEX(WH_Backend!$DZ$6:$IO$125,$L6,106),0) -> 0 | DO6: =IF(AND($L6<=$P$2,107<=$P$2),INDEX(WH_Backend!$DZ$6:$IO$125,$L6,107),0) -> 0 | DP6: =IF(AND($L6<=$P$2,108<=$P$2),INDEX(WH_Backend!$DZ$6:$IO$125,$L6,108),0) -> 0 | DQ6: =IF(AND($L6<=$P$2,109<=$P$2),INDEX(WH_Backend!$DZ$6:$IO$125,$L6,109),0) -> 0 | DR6: =IF(AND($L6<=$P$2,110<=$P$2),INDEX(WH_Backend!$DZ$6:$IO$125,$L6,110),0) -> 0 | DS6: =IF(AND($L6<=$P$2,111<=$P$2),INDEX(WH_Backend!$DZ$6:$IO$125,$L6,111),0) -> 0 | DT6: =IF(AND($L6<=$P$2,112<=$P$2),INDEX(WH_Backend!$DZ$6:$IO$125,$L6,112),0) -> 0 | DU6: =IF(AND($L6<=$P$2,113<=$P$2),INDEX(WH_Backend!$DZ$6:$IO$125,$L6,113),0) -> 0 | DV6: =IF(AND($L6<=$P$2,114<=$P$2),INDEX(WH_Backend!$DZ$6:$IO$125,$L6,114),0) -> 0 | DW6: =IF(AND($L6<=$P$2,115<=$P$2),INDEX(WH_Backend!$DZ$6:$IO$125,$L6,115),0) -> 0 | DX6: =IF(AND($L6<=$P$2,116<=$P$2),INDEX(WH_Backend!$DZ$6:$IO$125,$L6,116),0) -> 0 | DY6: =IF(AND($L6<=$P$2,117<=$P$2),INDEX(WH_Backend!$DZ$6:$IO$125,$L6,117),0) -> 0 | DZ6: =IF(AND($L6<=$P$2,118<=$P$2),INDEX(WH_Backend!$DZ$6:$IO$125,$L6,118),0) -> 0 | EA6: =IF(AND($L6<=$P$2,119<=$P$2),INDEX(WH_Backend!$DZ$6:$IO$125,$L6,119),0) -> 0 | EB6: =IF(AND($L6<=$P$2,120<=$P$2),INDEX(WH_Backend!$DZ$6:$IO$125,$L6,120),0) -> 0
A7: =IF(L7<=$P$2,INDEX(WH_Backend!$E$6:$E$125,L7),0) -> 179.02 | B7: {=IF(L7<=$P$2,MMULT(M132:INDEX(M132:EF132,$P$2),$A$6:INDEX($A$6:$A$125,$P$2)),0)} -> 0.0005644707 | C7: =IF(L7<=$P$2,MMULT(M7:INDEX(M7:EF7,$P$2),$B$6:INDEX($B$6:$B$125,$P$2))-A7,0) -> -4.8316906e-13 | E7: =IF(L7<=$P$2,Inputs!A7,"") -> 21 | F7: =IF(L7<=$P$2,Inputs!D7,"") -> 0.00063174208 | G7: =IF(L7<=$P$2,B7,"") -> 0.0005644707 | J7: =IF($L7<=$E$2,WH_Numerical!$F7,"") -> 0.00056424096 | L7: 2 | M7: =IF(AND($L7<=$P$2,1<=$P$2),INDEX(WH_Backend!$DZ$6:$IO$125,$L7,1),0) -> -30000000 | N7: =IF(AND($L7<=$P$2,2<=$P$2),INDEX(WH_Backend!$DZ$6:$IO$125,$L7,2),0) -> 1.0028338e+08 | O7: =IF(AND($L7<=$P$2,3<=$P$2),INDEX(WH_Backend!$DZ$6:$IO$125,$L7,3),0) -> -120000000 | P7: =IF(AND($L7<=$P$2,4<=$P$2),INDEX(WH_Backend!$DZ$6:$IO$125,$L7,4),0) -> 60000000 | Q7: =IF(AND($L7<=$P$2,5<=$P$2),INDEX(WH_Backend!$DZ$6:$IO$125,$L7,5),0) -> -10000000 | R7: =IF(AND($L7<=$P$2,6<=$P$2),INDEX(WH_Backend!$DZ$6:$IO$125,$L7,6),0) -> 0 | S7: =IF(AND($L7<=$P$2,7<=$P$2),INDEX(WH_Backend!$DZ$6:$IO$125,$L7,7),0) -> 0 | T7: =IF(AND($L7<=$P$2,8<=$P$2),INDEX(WH_Backend!$DZ$6:$IO$125,$L7,8),0) -> 0 | U7: =IF(AND($L7<=$P$2,9<=$P$2),INDEX(WH_Backend!$DZ$6:$IO$125,$L7,9),0) -> 0 | V7: =IF(AND($L7<=$P$2,10<=$P$2),INDEX(WH_Backend!$DZ$6:$IO$125,$L7,10),0) -> 0 | W7: =IF(AND($L7<=$P$2,11<=$P$2),INDEX(WH_Backend!$DZ$6:$IO$125,$L7,11),0) -> 0 | X7: =IF(AND($L7<=$P$2,12<=$P$2),INDEX(WH_Backend!$DZ$6:$IO$125,$L7,12),0) -> 0 | Y7: =IF(AND($L7<=$P$2,13<=$P$2),INDEX(WH_Backend!$DZ$6:$IO$125,$L7,13),0) -> 0 | Z7: =IF(AND($L7<=$P$2,14<=$P$2),INDEX(WH_Backend!$DZ$6:$IO$125,$L7,14),0) -> 0 | AA7: =IF(AND($L7<=$P$2,15<=$P$2),INDEX(WH_Backend!$DZ$6:$IO$125,$L7,15),0) -> 0 | AB7: =IF(AND($L7<=$P$2,16<=$P$2),INDEX(WH_Backend!$DZ$6:$IO$125,$L7,16),0) -> 0 | AC7: =IF(AND($L7<=$P$2,17<=$P$2),INDEX(WH_Backend!$DZ$6:$IO$125,$L7,17),0) -> 0 | AD7: =IF(AND($L7<=$P$2,18<=$P$2),INDEX(WH_Backend!$DZ$6:$IO$125,$L7,18),0) -> 0 | AE7: =IF(AND($L7<=$P$2,19<=$P$2),INDEX(WH_Backend!$DZ$6:$IO$125,$L7,19),0) -> 0 | AF7: =IF(AND($L7<=$P$2,20<=$P$2),INDEX(WH_Backend!$DZ$6:$IO$125,$L7,20),0) -> 0 | AG7: =IF(AND($L7<=$P$2,21<=$P$2),INDEX(WH_Backend!$DZ$6:$IO$125,$L7,21),0) -> 0 | AH7: =IF(AND($L7<=$P$2,22<=$P$2),INDEX(WH_Backend!$DZ$6:$IO$125,$L7,22),0) -> 0 | AI7: =IF(AND($L7<=$P$2,23<=$P$2),INDEX(WH_Backend!$DZ$6:$IO$125,$L7,23),0) -> 0 | AJ7: =IF(AND($L7<=$P$2,24<=$P$2),INDEX(WH_Backend!$DZ$6:$IO$125,$L7,24),0) -> 0 | AK7: =IF(AND($L7<=$P$2,25<=$P$2),INDEX(WH_Backend!$DZ$6:$IO$125,$L7,25),0) -> 0 | AL7: =IF(AND($L7<=$P$2,26<=$P$2),INDEX(WH_Backend!$DZ$6:$IO$125,$L7,26),0) -> 0 | AM7: =IF(AND($L7<=$P$2,27<=$P$2),INDEX(WH_Backend!$DZ$6:$IO$125,$L7,27),0) -> 0 | AN7: =IF(AND($L7<=$P$2,28<=$P$2),INDEX(WH_Backend!$DZ$6:$IO$125,$L7,28),0) -> 0 | AO7: =IF(AND($L7<=$P$2,29<=$P$2),INDEX(WH_Backend!$DZ$6:$IO$125,$L7,29),0) -> 0 | AP7: =IF(AND($L7<=$P$2,30<=$P$2),INDEX(WH_Backend!$DZ$6:$IO$125,$L7,30),0) -> 0 | AQ7: =IF(AND($L7<=$P$2,31<=$P$2),INDEX(WH_Backend!$DZ$6:$IO$125,$L7,31),0) -> 0 | AR7: =IF(AND($L7<=$P$2,32<=$P$2),INDEX(WH_Backend!$DZ$6:$IO$125,$L7,32),0) -> 0 | AS7: =IF(AND($L7<=$P$2,33<=$P$2),INDEX(WH_Backend!$DZ$6:$IO$125,$L7,33),0) -> 0 | AT7: =IF(AND($L7<=$P$2,34<=$P$2),INDEX(WH_Backend!$DZ$6:$IO$125,$L7,34),0) -> 0 | AU7: =IF(AND($L7<=$P$2,35<=$P$2),INDEX(WH_Backend!$DZ$6:$IO$125,$L7,35),0) -> 0 | AV7: =IF(AND($L7<=$P$2,36<=$P$2),INDEX(WH_Backend!$DZ$6:$IO$125,$L7,36),0) -> 0 | AW7: =IF(AND($L7<=$P$2,37<=$P$2),INDEX(WH_Backend!$DZ$6:$IO$125,$L7,37),0) -> 0 | AX7: =IF(AND($L7<=$P$2,38<=$P$2),INDEX(WH_Backend!$DZ$6:$IO$125,$L7,38),0) -> 0 | AY7: =IF(AND($L7<=$P$2,39<=$P$2),INDEX(WH_Backend!$DZ$6:$IO$125,$L7,39),0) -> 0 | AZ7: =IF(AND($L7<=$P$2,40<=$P$2),INDEX(WH_Backend!$DZ$6:$IO$125,$L7,40),0) -> 0 | BA7: =IF(AND($L7<=$P$2,41<=$P$2),INDEX(WH_Backend!$DZ$6:$IO$125,$L7,41),0) -> 0 | BB7: =IF(AND($L7<=$P$2,42<=$P$2),INDEX(WH_Backend!$DZ$6:$IO$125,$L7,42),0) -> 0 | BC7: =IF(AND($L7<=$P$2,43<=$P$2),INDEX(WH_Backend!$DZ$6:$IO$125,$L7,43),0) -> 0 | BD7: =IF(AND($L7<=$P$2,44<=$P$2),INDEX(WH_Backend!$DZ$6:$IO$125,$L7,44),0) -> 0 | BE7: =IF(AND($L7<=$P$2,45<=$P$2),INDEX(WH_Backend!$DZ$6:$IO$125,$L7,45),0) -> 0 | BF7: =IF(AND($L7<=$P$2,46<=$P$2),INDEX(WH_Backend!$DZ$6:$IO$125,$L7,46),0) -> 0 | BG7: =IF(AND($L7<=$P$2,47<=$P$2),INDEX(WH_Backend!$DZ$6:$IO$125,$L7,47),0) -> 0 | BH7: =IF(AND($L7<=$P$2,48<=$P$2),INDEX(WH_Backend!$DZ$6:$IO$125,$L7,48),0) -> 0 | BI7: =IF(AND($L7<=$P$2,49<=$P$2),INDEX(WH_Backend!$DZ$6:$IO$125,$L7,49),0) -> 0 | BJ7: =IF(AND($L7<=$P$2,50<=$P$2),INDEX(WH_Backend!$DZ$6:$IO$125,$L7,50),0) -> 0 | BK7: =IF(AND($L7<=$P$2,51<=$P$2),INDEX(WH_Backend!$DZ$6:$IO$125,$L7,51),0) -> 0 | BL7: =IF(AND($L7<=$P$2,52<=$P$2),INDEX(WH_Backend!$DZ$6:$IO$125,$L7,52),0) -> 0 | BM7: =IF(AND($L7<=$P$2,53<=$P$2),INDEX(WH_Backend!$DZ$6:$IO$125,$L7,53),0) -> 0 | BN7: =IF(AND($L7<=$P$2,54<=$P$2),INDEX(WH_Backend!$DZ$6:$IO$125,$L7,54),0) -> 0 | BO7: =IF(AND($L7<=$P$2,55<=$P$2),INDEX(WH_Backend!$DZ$6:$IO$125,$L7,55),0) -> 0 | BP7: =IF(AND($L7<=$P$2,56<=$P$2),INDEX(WH_Backend!$DZ$6:$IO$125,$L7,56),0) -> 0 | BQ7: =IF(AND($L7<=$P$2,57<=$P$2),INDEX(WH_Backend!$DZ$6:$IO$125,$L7,57),0) -> 0 | BR7: =IF(AND($L7<=$P$2,58<=$P$2),INDEX(WH_Backend!$DZ$6:$IO$125,$L7,58),0) -> 0 | BS7: =IF(AND($L7<=$P$2,59<=$P$2),INDEX(WH_Backend!$DZ$6:$IO$125,$L7,59),0) -> 0 | BT7: =IF(AND($L7<=$P$2,60<=$P$2),INDEX(WH_Backend!$DZ$6:$IO$125,$L7,60),0) -> 0 | BU7: =IF(AND($L7<=$P$2,61<=$P$2),INDEX(WH_Backend!$DZ$6:$IO$125,$L7,61),0) -> 0 | BV7: =IF(AND($L7<=$P$2,62<=$P$2),INDEX(WH_Backend!$DZ$6:$IO$125,$L7,62),0) -> 0 | BW7: =IF(AND($L7<=$P$2,63<=$P$2),INDEX(WH_Backend!$DZ$6:$IO$125,$L7,63),0) -> 0 | BX7: =IF(AND($L7<=$P$2,64<=$P$2),INDEX(WH_Backend!$DZ$6:$IO$125,$L7,64),0) -> 0 | BY7: =IF(AND($L7<=$P$2,65<=$P$2),INDEX(WH_Backend!$DZ$6:$IO$125,$L7,65),0) -> 0 | BZ7: =IF(AND($L7<=$P$2,66<=$P$2),INDEX(WH_Backend!$DZ$6:$IO$125,$L7,66),0) -> 0 | CA7: =IF(AND($L7<=$P$2,67<=$P$2),INDEX(WH_Backend!$DZ$6:$IO$125,$L7,67),0) -> 0 | CB7: =IF(AND($L7<=$P$2,68<=$P$2),INDEX(WH_Backend!$DZ$6:$IO$125,$L7,68),0) -> 0 | CC7: =IF(AND($L7<=$P$2,69<=$P$2),INDEX(WH_Backend!$DZ$6:$IO$125,$L7,69),0) -> 0 | CD7: =IF(AND($L7<=$P$2,70<=$P$2),INDEX(WH_Backend!$DZ$6:$IO$125,$L7,70),0) -> 0 | CE7: =IF(AND($L7<=$P$2,71<=$P$2),INDEX(WH_Backend!$DZ$6:$IO$125,$L7,71),0) -> 0 | CF7: =IF(AND($L7<=$P$2,72<=$P$2),INDEX(WH_Backend!$DZ$6:$IO$125,$L7,72),0) -> 0 | CG7: =IF(AND($L7<=$P$2,73<=$P$2),INDEX(WH_Backend!$DZ$6:$IO$125,$L7,73),0) -> 0 | CH7: =IF(AND($L7<=$P$2,74<=$P$2),INDEX(WH_Backend!$DZ$6:$IO$125,$L7,74),0) -> 0 | CI7: =IF(AND($L7<=$P$2,75<=$P$2),INDEX(WH_Backend!$DZ$6:$IO$125,$L7,75),0) -> 0 | CJ7: =IF(AND($L7<=$P$2,76<=$P$2),INDEX(WH_Backend!$DZ$6:$IO$125,$L7,76),0) -> 0 | CK7: =IF(AND($L7<=$P$2,77<=$P$2),INDEX(WH_Backend!$DZ$6:$IO$125,$L7,77),0) -> 0 | CL7: =IF(AND($L7<=$P$2,78<=$P$2),INDEX(WH_Backend!$DZ$6:$IO$125,$L7,78),0) -> 0 | CM7: =IF(AND($L7<=$P$2,79<=$P$2),INDEX(WH_Backend!$DZ$6:$IO$125,$L7,79),0) -> 0 | CN7: =IF(AND($L7<=$P$2,80<=$P$2),INDEX(WH_Backend!$DZ$6:$IO$125,$L7,80),0) -> 0 | CO7: =IF(AND($L7<=$P$2,81<=$P$2),INDEX(WH_Backend!$DZ$6:$IO$125,$L7,81),0) -> 0 | CP7: =IF(AND($L7<=$P$2,82<=$P$2),INDEX(WH_Backend!$DZ$6:$IO$125,$L7,82),0) -> 0 | CQ7: =IF(AND($L7<=$P$2,83<=$P$2),INDEX(WH_Backend!$DZ$6:$IO$125,$L7,83),0) -> 0 | CR7: =IF(AND($L7<=$P$2,84<=$P$2),INDEX(WH_Backend!$DZ$6:$IO$125,$L7,84),0) -> 0 | CS7: =IF(AND($L7<=$P$2,85<=$P$2),INDEX(WH_Backend!$DZ$6:$IO$125,$L7,85),0) -> 0 | CT7: =IF(AND($L7<=$P$2,86<=$P$2),INDEX(WH_Backend!$DZ$6:$IO$125,$L7,86),0) -> 0 | CU7: =IF(AND($L7<=$P$2,87<=$P$2),INDEX(WH_Backend!$DZ$6:$IO$125,$L7,87),0) -> 0 | CV7: =IF(AND($L7<=$P$2,88<=$P$2),INDEX(WH_Backend!$DZ$6:$IO$125,$L7,88),0) -> 0 | CW7: =IF(AND($L7<=$P$2,89<=$P$2),INDEX(WH_Backend!$DZ$6:$IO$125,$L7,89),0) -> 0 | CX7: =IF(AND($L7<=$P$2,90<=$P$2),INDEX(WH_Backend!$DZ$6:$IO$125,$L7,90),0) -> 0 | CY7: =IF(AND($L7<=$P$2,91<=$P$2),INDEX(WH_Backend!$DZ$6:$IO$125,$L7,91),0) -> 0 | CZ7: =IF(AND($L7<=$P$2,92<=$P$2),INDEX(WH_Backend!$DZ$6:$IO$125,$L7,92),0) -> 0 | DA7: =IF(AND($L7<=$P$2,93<=$P$2),INDEX(WH_Backend!$DZ$6:$IO$125,$L7,93),0) -> 0 | DB7: =IF(AND($L7<=$P$2,94<=$P$2),INDEX(WH_Backend!$DZ$6:$IO$125,$L7,94),0) -> 0 | DC7: =IF(AND($L7<=$P$2,95<=$P$2),INDEX(WH_Backend!$DZ$6:$IO$125,$L7,95),0) -> 0 | DD7: =IF(AND($L7<=$P$2,96<=$P$2),INDEX(WH_Backend!$DZ$6:$IO$125,$L7,96),0) -> 0 | DE7: =IF(AND($L7<=$P$2,97<=$P$2),INDEX(WH_Backend!$DZ$6:$IO$125,$L7,97),0) -> 0 | DF7: =IF(AND($L7<=$P$2,98<=$P$2),INDEX(WH_Backend!$DZ$6:$IO$125,$L7,98),0) -> 0 | DG7: =IF(AND($L7<=$P$2,99<=$P$2),INDEX(WH_Backend!$DZ$6:$IO$125,$L7,99),0) -> 0 | DH7: =IF(AND($L7<=$P$2,100<=$P$2),INDEX(WH_Backend!$DZ$6:$IO$125,$L7,100),0) -> 0 | DI7: =IF(AND($L7<=$P$2,101<=$P$2),INDEX(WH_Backend!$DZ$6:$IO$125,$L7,101),0) -> 0 | DJ7: =IF(AND($L7<=$P$2,102<=$P$2),INDEX(WH_Backend!$DZ$6:$IO$125,$L7,102),0) -> 0 | DK7: =IF(AND($L7<=$P$2,103<=$P$2),INDEX(WH_Backend!$DZ$6:$IO$125,$L7,103),0) -> 0 | DL7: =IF(AND($L7<=$P$2,104<=$P$2),INDEX(WH_Backend!$DZ$6:$IO$125,$L7,104),0) -> 0 | DM7: =IF(AND($L7<=$P$2,105<=$P$2),INDEX(WH_Backend!$DZ$6:$IO$125,$L7,105),0) -> 0 | DN7: =IF(AND($L7<=$P$2,106<=$P$2),INDEX(WH_Backend!$DZ$6:$IO$125,$L7,106),0) -> 0 | DO7: =IF(AND($L7<=$P$2,107<=$P$2),INDEX(WH_Backend!$DZ$6:$IO$125,$L7,107),0) -> 0 | DP7: =IF(AND($L7<=$P$2,108<=$P$2),INDEX(WH_Backend!$DZ$6:$IO$125,$L7,108),0) -> 0 | DQ7: =IF(AND($L7<=$P$2,109<=$P$2),INDEX(WH_Backend!$DZ$6:$IO$125,$L7,109),0) -> 0 | DR7: =IF(AND($L7<=$P$2,110<=$P$2),INDEX(WH_Backend!$DZ$6:$IO$125,$L7,110),0) -> 0 | DS7: =IF(AND($L7<=$P$2,111<=$P$2),INDEX(WH_Backend!$DZ$6:$IO$125,$L7,111),0) -> 0 | DT7: =IF(AND($L7<=$P$2,112<=$P$2),INDEX(WH_Backend!$DZ$6:$IO$125,$L7,112),0) -> 0 | DU7: =IF(AND($L7<=$P$2,113<=$P$2),INDEX(WH_Backend!$DZ$6:$IO$125,$L7,113),0) -> 0 | DV7: =IF(AND($L7<=$P$2,114<=$P$2),INDEX(WH_Backend!$DZ$6:$IO$125,$L7,114),0) -> 0 | DW7: =IF(AND($L7<=$P$2,115<=$P$2),INDEX(WH_Backend!$DZ$6:$IO$125,$L7,115),0) -> 0 | DX7: =IF(AND($L7<=$P$2,116<=$P$2),INDEX(WH_Backend!$DZ$6:$IO$125,$L7,116),0) -> 0 | DY7: =IF(AND($L7<=$P$2,117<=$P$2),INDEX(WH_Backend!$DZ$6:$IO$125,$L7,117),0) -> 0 | DZ7: =IF(AND($L7<=$P$2,118<=$P$2),INDEX(WH_Backend!$DZ$6:$IO$125,$L7,118),0) -> 0 | EA7: =IF(AND($L7<=$P$2,119<=$P$2),INDEX(WH_Backend!$DZ$6:$IO$125,$L7,119),0) -> 0 | EB7: =IF(AND($L7<=$P$2,120<=$P$2),INDEX(WH_Backend!$DZ$6:$IO$125,$L7,120),0) -> 0
A8: =IF(L8<=$P$2,INDEX(WH_Backend!$E$6:$E$125,L8),0) -> 127 | B8: {=IF(L8<=$P$2,MMULT(M133:INDEX(M133:EF133,$P$2),$A$6:INDEX($A$6:$A$125,$P$2)),0)} -> 0.00055593475 | C8: =IF(L8<=$P$2,MMULT(M8:INDEX(M8:EF8,$P$2),$B$6:INDEX($B$6:$B$125,$P$2))-A8,0) -> 1.6370905e-11 | E8: =IF(L8<=$P$2,Inputs!A8,"") -> 22 | F8: =IF(L8<=$P$2,Inputs!D8,"") -> 0.0004443066 | G8: =IF(L8<=$P$2,B8,"") -> 0.00055593475 | J8: =IF($L8<=$E$2,WH_Numerical!$F8,"") -> 0.00055537371 | L8: 3 | M8: =IF(AND($L8<=$P$2,1<=$P$2),INDEX(WH_Backend!$DZ$6:$IO$125,$L8,1),0) -> 30000000 | N8: =IF(AND($L8<=$P$2,2<=$P$2),INDEX(WH_Backend!$DZ$6:$IO$125,$L8,2),0) -> -120000000 | O8: =IF(AND($L8<=$P$2,3<=$P$2),INDEX(WH_Backend!$DZ$6:$IO$125,$L8,3),0) -> 1.9028584e+08 | P8: =IF(AND($L8<=$P$2,4<=$P$2),INDEX(WH_Backend!$DZ$6:$IO$125,$L8,4),0) -> -150000000 | Q8: =IF(AND($L8<=$P$2,5<=$P$2),INDEX(WH_Backend!$DZ$6:$IO$125,$L8,5),0) -> 60000000 | R8: =IF(AND($L8<=$P$2,6<=$P$2),INDEX(WH_Backend!$DZ$6:$IO$125,$L8,6),0) -> -10000000 | S8: =IF(AND($L8<=$P$2,7<=$P$2),INDEX(WH_Backend!$DZ$6:$IO$125,$L8,7),0) -> 0 | T8: =IF(AND($L8<=$P$2,8<=$P$2),INDEX(WH_Backend!$DZ$6:$IO$125,$L8,8),0) -> 0 | U8: =IF(AND($L8<=$P$2,9<=$P$2),INDEX(WH_Backend!$DZ$6:$IO$125,$L8,9),0) -> 0 | V8: =IF(AND($L8<=$P$2,10<=$P$2),INDEX(WH_Backend!$DZ$6:$IO$125,$L8,10),0) -> 0 | W8: =IF(AND($L8<=$P$2,11<=$P$2),INDEX(WH_Backend!$DZ$6:$IO$125,$L8,11),0) -> 0 | X8: =IF(AND($L8<=$P$2,12<=$P$2),INDEX(WH_Backend!$DZ$6:$IO$125,$L8,12),0) -> 0 | Y8: =IF(AND($L8<=$P$2,13<=$P$2),INDEX(WH_Backend!$DZ$6:$IO$125,$L8,13),0) -> 0 | Z8: =IF(AND($L8<=$P$2,14<=$P$2),INDEX(WH_Backend!$DZ$6:$IO$125,$L8,14),0) -> 0 | AA8: =IF(AND($L8<=$P$2,15<=$P$2),INDEX(WH_Backend!$DZ$6:$IO$125,$L8,15),0) -> 0 | AB8: =IF(AND($L8<=$P$2,16<=$P$2),INDEX(WH_Backend!$DZ$6:$IO$125,$L8,16),0) -> 0 | AC8: =IF(AND($L8<=$P$2,17<=$P$2),INDEX(WH_Backend!$DZ$6:$IO$125,$L8,17),0) -> 0 | AD8: =IF(AND($L8<=$P$2,18<=$P$2),INDEX(WH_Backend!$DZ$6:$IO$125,$L8,18),0) -> 0 | AE8: =IF(AND($L8<=$P$2,19<=$P$2),INDEX(WH_Backend!$DZ$6:$IO$125,$L8,19),0) -> 0 | AF8: =IF(AND($L8<=$P$2,20<=$P$2),INDEX(WH_Backend!$DZ$6:$IO$125,$L8,20),0) -> 0 | AG8: =IF(AND($L8<=$P$2,21<=$P$2),INDEX(WH_Backend!$DZ$6:$IO$125,$L8,21),0) -> 0 | AH8: =IF(AND($L8<=$P$2,22<=$P$2),INDEX(WH_Backend!$DZ$6:$IO$125,$L8,22),0) -> 0 | AI8: =IF(AND($L8<=$P$2,23<=$P$2),INDEX(WH_Backend!$DZ$6:$IO$125,$L8,23),0) -> 0 | AJ8: =IF(AND($L8<=$P$2,24<=$P$2),INDEX(WH_Backend!$DZ$6:$IO$125,$L8,24),0) -> 0 | AK8: =IF(AND($L8<=$P$2,25<=$P$2),INDEX(WH_Backend!$DZ$6:$IO$125,$L8,25),0) -> 0 | AL8: =IF(AND($L8<=$P$2,26<=$P$2),INDEX(WH_Backend!$DZ$6:$IO$125,$L8,26),0) -> 0 | AM8: =IF(AND($L8<=$P$2,27<=$P$2),INDEX(WH_Backend!$DZ$6:$IO$125,$L8,27),0) -> 0 | AN8: =IF(AND($L8<=$P$2,28<=$P$2),INDEX(WH_Backend!$DZ$6:$IO$125,$L8,28),0) -> 0 | AO8: =IF(AND($L8<=$P$2,29<=$P$2),INDEX(WH_Backend!$DZ$6:$IO$125,$L8,29),0) -> 0 | AP8: =IF(AND($L8<=$P$2,30<=$P$2),INDEX(WH_Backend!$DZ$6:$IO$125,$L8,30),0) -> 0 | AQ8: =IF(AND($L8<=$P$2,31<=$P$2),INDEX(WH_Backend!$DZ$6:$IO$125,$L8,31),0) -> 0 | AR8: =IF(AND($L8<=$P$2,32<=$P$2),INDEX(WH_Backend!$DZ$6:$IO$125,$L8,32),0) -> 0 | AS8: =IF(AND($L8<=$P$2,33<=$P$2),INDEX(WH_Backend!$DZ$6:$IO$125,$L8,33),0) -> 0 | AT8: =IF(AND($L8<=$P$2,34<=$P$2),INDEX(WH_Backend!$DZ$6:$IO$125,$L8,34),0) -> 0 | AU8: =IF(AND($L8<=$P$2,35<=$P$2),INDEX(WH_Backend!$DZ$6:$IO$125,$L8,35),0) -> 0 | AV8: =IF(AND($L8<=$P$2,36<=$P$2),INDEX(WH_Backend!$DZ$6:$IO$125,$L8,36),0) -> 0 | AW8: =IF(AND($L8<=$P$2,37<=$P$2),INDEX(WH_Backend!$DZ$6:$IO$125,$L8,37),0) -> 0 | AX8: =IF(AND($L8<=$P$2,38<=$P$2),INDEX(WH_Backend!$DZ$6:$IO$125,$L8,38),0) -> 0 | AY8: =IF(AND($L8<=$P$2,39<=$P$2),INDEX(WH_Backend!$DZ$6:$IO$125,$L8,39),0) -> 0 | AZ8: =IF(AND($L8<=$P$2,40<=$P$2),INDEX(WH_Backend!$DZ$6:$IO$125,$L8,40),0) -> 0 | BA8: =IF(AND($L8<=$P$2,41<=$P$2),INDEX(WH_Backend!$DZ$6:$IO$125,$L8,41),0) -> 0 | BB8: =IF(AND($L8<=$P$2,42<=$P$2),INDEX(WH_Backend!$DZ$6:$IO$125,$L8,42),0) -> 0 | BC8: =IF(AND($L8<=$P$2,43<=$P$2),INDEX(WH_Backend!$DZ$6:$IO$125,$L8,43),0) -> 0 | BD8: =IF(AND($L8<=$P$2,44<=$P$2),INDEX(WH_Backend!$DZ$6:$IO$125,$L8,44),0) -> 0 | BE8: =IF(AND($L8<=$P$2,45<=$P$2),INDEX(WH_Backend!$DZ$6:$IO$125,$L8,45),0) -> 0 | BF8: =IF(AND($L8<=$P$2,46<=$P$2),INDEX(WH_Backend!$DZ$6:$IO$125,$L8,46),0) -> 0 | BG8: =IF(AND($L8<=$P$2,47<=$P$2),INDEX(WH_Backend!$DZ$6:$IO$125,$L8,47),0) -> 0 | BH8: =IF(AND($L8<=$P$2,48<=$P$2),INDEX(WH_Backend!$DZ$6:$IO$125,$L8,48),0) -> 0 | BI8: =IF(AND($L8<=$P$2,49<=$P$2),INDEX(WH_Backend!$DZ$6:$IO$125,$L8,49),0) -> 0 | BJ8: =IF(AND($L8<=$P$2,50<=$P$2),INDEX(WH_Backend!$DZ$6:$IO$125,$L8,50),0) -> 0 | BK8: =IF(AND($L8<=$P$2,51<=$P$2),INDEX(WH_Backend!$DZ$6:$IO$125,$L8,51),0) -> 0 | BL8: =IF(AND($L8<=$P$2,52<=$P$2),INDEX(WH_Backend!$DZ$6:$IO$125,$L8,52),0) -> 0 | BM8: =IF(AND($L8<=$P$2,53<=$P$2),INDEX(WH_Backend!$DZ$6:$IO$125,$L8,53),0) -> 0 | BN8: =IF(AND($L8<=$P$2,54<=$P$2),INDEX(WH_Backend!$DZ$6:$IO$125,$L8,54),0) -> 0 | BO8: =IF(AND($L8<=$P$2,55<=$P$2),INDEX(WH_Backend!$DZ$6:$IO$125,$L8,55),0) -> 0 | BP8: =IF(AND($L8<=$P$2,56<=$P$2),INDEX(WH_Backend!$DZ$6:$IO$125,$L8,56),0) -> 0 | BQ8: =IF(AND($L8<=$P$2,57<=$P$2),INDEX(WH_Backend!$DZ$6:$IO$125,$L8,57),0) -> 0 | BR8: =IF(AND($L8<=$P$2,58<=$P$2),INDEX(WH_Backend!$DZ$6:$IO$125,$L8,58),0) -> 0 | BS8: =IF(AND($L8<=$P$2,59<=$P$2),INDEX(WH_Backend!$DZ$6:$IO$125,$L8,59),0) -> 0 | BT8: =IF(AND($L8<=$P$2,60<=$P$2),INDEX(WH_Backend!$DZ$6:$IO$125,$L8,60),0) -> 0 | BU8: =IF(AND($L8<=$P$2,61<=$P$2),INDEX(WH_Backend!$DZ$6:$IO$125,$L8,61),0) -> 0 | BV8: =IF(AND($L8<=$P$2,62<=$P$2),INDEX(WH_Backend!$DZ$6:$IO$125,$L8,62),0) -> 0 | BW8: =IF(AND($L8<=$P$2,63<=$P$2),INDEX(WH_Backend!$DZ$6:$IO$125,$L8,63),0) -> 0 | BX8: =IF(AND($L8<=$P$2,64<=$P$2),INDEX(WH_Backend!$DZ$6:$IO$125,$L8,64),0) -> 0 | BY8: =IF(AND($L8<=$P$2,65<=$P$2),INDEX(WH_Backend!$DZ$6:$IO$125,$L8,65),0) -> 0 | BZ8: =IF(AND($L8<=$P$2,66<=$P$2),INDEX(WH_Backend!$DZ$6:$IO$125,$L8,66),0) -> 0 | CA8: =IF(AND($L8<=$P$2,67<=$P$2),INDEX(WH_Backend!$DZ$6:$IO$125,$L8,67),0) -> 0 | CB8: =IF(AND($L8<=$P$2,68<=$P$2),INDEX(WH_Backend!$DZ$6:$IO$125,$L8,68),0) -> 0 | CC8: =IF(AND($L8<=$P$2,69<=$P$2),INDEX(WH_Backend!$DZ$6:$IO$125,$L8,69),0) -> 0 | CD8: =IF(AND($L8<=$P$2,70<=$P$2),INDEX(WH_Backend!$DZ$6:$IO$125,$L8,70),0) -> 0 | CE8: =IF(AND($L8<=$P$2,71<=$P$2),INDEX(WH_Backend!$DZ$6:$IO$125,$L8,71),0) -> 0 | CF8: =IF(AND($L8<=$P$2,72<=$P$2),INDEX(WH_Backend!$DZ$6:$IO$125,$L8,72),0) -> 0 | CG8: =IF(AND($L8<=$P$2,73<=$P$2),INDEX(WH_Backend!$DZ$6:$IO$125,$L8,73),0) -> 0 | CH8: =IF(AND($L8<=$P$2,74<=$P$2),INDEX(WH_Backend!$DZ$6:$IO$125,$L8,74),0) -> 0 | CI8: =IF(AND($L8<=$P$2,75<=$P$2),INDEX(WH_Backend!$DZ$6:$IO$125,$L8,75),0) -> 0 | CJ8: =IF(AND($L8<=$P$2,76<=$P$2),INDEX(WH_Backend!$DZ$6:$IO$125,$L8,76),0) -> 0 | CK8: =IF(AND($L8<=$P$2,77<=$P$2),INDEX(WH_Backend!$DZ$6:$IO$125,$L8,77),0) -> 0 | CL8: =IF(AND($L8<=$P$2,78<=$P$2),INDEX(WH_Backend!$DZ$6:$IO$125,$L8,78),0) -> 0 | CM8: =IF(AND($L8<=$P$2,79<=$P$2),INDEX(WH_Backend!$DZ$6:$IO$125,$L8,79),0) -> 0 | CN8: =IF(AND($L8<=$P$2,80<=$P$2),INDEX(WH_Backend!$DZ$6:$IO$125,$L8,80),0) -> 0 | CO8: =IF(AND($L8<=$P$2,81<=$P$2),INDEX(WH_Backend!$DZ$6:$IO$125,$L8,81),0) -> 0 | CP8: =IF(AND($L8<=$P$2,82<=$P$2),INDEX(WH_Backend!$DZ$6:$IO$125,$L8,82),0) -> 0 | CQ8: =IF(AND($L8<=$P$2,83<=$P$2),INDEX(WH_Backend!$DZ$6:$IO$125,$L8,83),0) -> 0 | CR8: =IF(AND($L8<=$P$2,84<=$P$2),INDEX(WH_Backend!$DZ$6:$IO$125,$L8,84),0) -> 0 | CS8: =IF(AND($L8<=$P$2,85<=$P$2),INDEX(WH_Backend!$DZ$6:$IO$125,$L8,85),0) -> 0 | CT8: =IF(AND($L8<=$P$2,86<=$P$2),INDEX(WH_Backend!$DZ$6:$IO$125,$L8,86),0) -> 0 | CU8: =IF(AND($L8<=$P$2,87<=$P$2),INDEX(WH_Backend!$DZ$6:$IO$125,$L8,87),0) -> 0 | CV8: =IF(AND($L8<=$P$2,88<=$P$2),INDEX(WH_Backend!$DZ$6:$IO$125,$L8,88),0) -> 0 | CW8: =IF(AND($L8<=$P$2,89<=$P$2),INDEX(WH_Backend!$DZ$6:$IO$125,$L8,89),0) -> 0 | CX8: =IF(AND($L8<=$P$2,90<=$P$2),INDEX(WH_Backend!$DZ$6:$IO$125,$L8,90),0) -> 0 | CY8: =IF(AND($L8<=$P$2,91<=$P$2),INDEX(WH_Backend!$DZ$6:$IO$125,$L8,91),0) -> 0 | CZ8: =IF(AND($L8<=$P$2,92<=$P$2),INDEX(WH_Backend!$DZ$6:$IO$125,$L8,92),0) -> 0 | DA8: =IF(AND($L8<=$P$2,93<=$P$2),INDEX(WH_Backend!$DZ$6:$IO$125,$L8,93),0) -> 0 | DB8: =IF(AND($L8<=$P$2,94<=$P$2),INDEX(WH_Backend!$DZ$6:$IO$125,$L8,94),0) -> 0 | DC8: =IF(AND($L8<=$P$2,95<=$P$2),INDEX(WH_Backend!$DZ$6:$IO$125,$L8,95),0) -> 0 | DD8: =IF(AND($L8<=$P$2,96<=$P$2),INDEX(WH_Backend!$DZ$6:$IO$125,$L8,96),0) -> 0 | DE8: =IF(AND($L8<=$P$2,97<=$P$2),INDEX(WH_Backend!$DZ$6:$IO$125,$L8,97),0) -> 0 | DF8: =IF(AND($L8<=$P$2,98<=$P$2),INDEX(WH_Backend!$DZ$6:$IO$125,$L8,98),0) -> 0 | DG8: =IF(AND($L8<=$P$2,99<=$P$2),INDEX(WH_Backend!$DZ$6:$IO$125,$L8,99),0) -> 0 | DH8: =IF(AND($L8<=$P$2,100<=$P$2),INDEX(WH_Backend!$DZ$6:$IO$125,$L8,100),0) -> 0 | DI8: =IF(AND($L8<=$P$2,101<=$P$2),INDEX(WH_Backend!$DZ$6:$IO$125,$L8,101),0) -> 0 | DJ8: =IF(AND($L8<=$P$2,102<=$P$2),INDEX(WH_Backend!$DZ$6:$IO$125,$L8,102),0) -> 0 | DK8: =IF(AND($L8<=$P$2,103<=$P$2),INDEX(WH_Backend!$DZ$6:$IO$125,$L8,103),0) -> 0 | DL8: =IF(AND($L8<=$P$2,104<=$P$2),INDEX(WH_Backend!$DZ$6:$IO$125,$L8,104),0) -> 0 | DM8: =IF(AND($L8<=$P$2,105<=$P$2),INDEX(WH_Backend!$DZ$6:$IO$125,$L8,105),0) -> 0 | DN8: =IF(AND($L8<=$P$2,106<=$P$2),INDEX(WH_Backend!$DZ$6:$IO$125,$L8,106),0) -> 0 | DO8: =IF(AND($L8<=$P$2,107<=$P$2),INDEX(WH_Backend!$DZ$6:$IO$125,$L8,107),0) -> 0 | DP8: =IF(AND($L8<=$P$2,108<=$P$2),INDEX(WH_Backend!$DZ$6:$IO$125,$L8,108),0) -> 0 | DQ8: =IF(AND($L8<=$P$2,109<=$P$2),INDEX(WH_Backend!$DZ$6:$IO$125,$L8,109),0) -> 0 | DR8: =IF(AND($L8<=$P$2,110<=$P$2),INDEX(WH_Backend!$DZ$6:$IO$125,$L8,110),0) -> 0 | DS8: =IF(AND($L8<=$P$2,111<=$P$2),INDEX(WH_Backend!$DZ$6:$IO$125,$L8,111),0) -> 0 | DT8: =IF(AND($L8<=$P$2,112<=$P$2),INDEX(WH_Backend!$DZ$6:$IO$125,$L8,112),0) -> 0 | DU8: =IF(AND($L8<=$P$2,113<=$P$2),INDEX(WH_Backend!$DZ$6:$IO$125,$L8,113),0) -> 0 | DV8: =IF(AND($L8<=$P$2,114<=$P$2),INDEX(WH_Backend!$DZ$6:$IO$125,$L8,114),0) -> 0 | DW8: =IF(AND($L8<=$P$2,115<=$P$2),INDEX(WH_Backend!$DZ$6:$IO$125,$L8,115),0) -> 0 | DX8: =IF(AND($L8<=$P$2,116<=$P$2),INDEX(WH_Backend!$DZ$6:$IO$125,$L8,116),0) -> 0 | DY8: =IF(AND($L8<=$P$2,117<=$P$2),INDEX(WH_Backend!$DZ$6:$IO$125,$L8,117),0) -> 0 | DZ8: =IF(AND($L8<=$P$2,118<=$P$2),INDEX(WH_Backend!$DZ$6:$IO$125,$L8,118),0) -> 0 | EA8: =IF(AND($L8<=$P$2,119<=$P$2),INDEX(WH_Backend!$DZ$6:$IO$125,$L8,119),0) -> 0 | EB8: =IF(AND($L8<=$P$2,120<=$P$2),INDEX(WH_Backend!$DZ$6:$IO$125,$L8,120),0) -> 0
