Workbook

Sheet M_70_t
A1: Year | B1: Mortality rate
A2: 1995 | B2: 0.00085662921
A3: 1996 | B3: 0.00082999933
A4: 1997 | B4: 0.00080999953
A5: 1998 | B5: 0.00097750974
A6: 1999 | B6: 0.00078849179
A7: 2000 | B7: 0.00099667191
A8: 2001 | B8: 0.00075112818
A9: 2002 | B9: 0.0007042875
A10: 2003 | B10: 0.00062560882
A11: 2004 | B11: 0.00063014139
A12: 2005 | B12: 0.00058383424
A13: 2006 | B13: 0.00049907285
... A26: 2019 | B26: 0.00044343997

Sheet Sheet1

Sheet Q2(a)_Derivation
A1: Q2(a): Cox–de Boor recursion and support
A3: Convention: B_(t_j,k)(t) denotes order k (degree k−1), with support [t_j, t_(j+k)). For M1, h=3 years and t_(j+r)=t_j+3r; extend the uniform knot sequence as required.
A5: Order 1: B_(t_j,1)(t)=1 if t_j≤t<t_j+h, and 0 otherwise. All subsequent basis functions are obtained from this indicator using the recursion below.
A7: For k=2,3,4: B_(t_j,k)(t)=[(t−t_j)/((k−1)h)] B_(t_j,k−1)(t)+[(t_j+kh−t)/((k−1)h)] B_(t_(j+1),k−1)(t).
A9: Order 2: B_(t_j,2)=[(t−t_j)/h]B_(t_j,1)+[(t_j+2h−t)/h]B_(t_(j+1),1).
A11: Order 3: B_(t_j,3)=[(t−t_j)/(2h)]B_(t_j,2)+[(t_j+3h−t)/(2h)]B_(t_(j+1),2).
A13: Order 4: B_(t_j,4)=[(t−t_j)/(3h)]B_(t_j,3)+[(t_j+4h−t)/(3h)]B_(t_(j+1),3).
A15: To display the piecewise forms compactly, let u=(t−t_j)/h and v_+=MAX(v,0). Then B_(t_j,k)(t)=Σ_(r=0)^k (−1)^r COMBIN(k,r)(u−r)_+^(k−1)/(k−1)! for k≥2.
A17: Order 2: u_+−2(u−1)_++(u−2)_+. Order 3: [u_+²−3(u−1)_+²+3(u−2)_+²−(u−3)_+²]/2.
A19: Order 4: [u_+³−4(u−1)_+³+6(u−2)_+³−4(u−3)_+³+(u−4)_+³]/6. The recurrence tables in this sheet and the model sheets calculate the same functions directly.
A21: The first-order support is one knot interval. Each recursion combines adjacent lower-order supports, adding one interval. The support length is therefore kh: 3, 6, 9 and 12 years for orders 1–4. For k≥2 the curve is also zero at the left endpoint; support here means the usual enclosing knot interval.
A25: Basis | B25: Order | C25: Degree | D25: Start year | E25: End year (excluded) | F25: Support length (years)
A26: B_1998,1 | B26: 1 | C26: 0 | D26: 1998 | E26: =D26+3*B26 -> 2001 | F26: =E26-D26 -> 3
A27: B_1998,2 | B27: 2 | C27: 1 | D27: 1998 | E27: =D27+3*B27 -> 2004 | F27: =E27-D27 -> 6
A28: B_1998,3 | B28: 3 | C28: 2 | D28: 1998 | E28: =D28+3*B28 -> 2007 | F28: =E28-D28 -> 9
A29: B_1998,4 | B29: 4 | C29: 3 | D29: 1998 | E29: =D29+3*B29 -> 2010 | F29: =E29-D29 -> 12
A31: Excel worked example below: B_1998,k for t=1995,…,2013. Intermediate adjacent first-, second- and third-order bases are retained so that every recursion step is visible.
A34: Year | B34: B1998,order1 | C34: B2001,order1 | D34: B2004,order1 | E34: B2007,order1 | F34: B1998,order2 | G34: B2001,order2 | H34: B2004,order2 | I34: B1998,order3 | J34: B2001,order3 | K34: B1998,order4
A35: 1995 | B35: =IF(AND($A35>=1998,$A35<2001),1,0) -> 0 | C35: =IF(AND($A35>=2001,$A35<2004),1,0) -> 0 | D35: =IF(AND($A35>=2004,$A35<2007),1,0) -> 0 | E35: =IF(AND($A35>=2007,$A35<2010),1,0) -> 0 | F35: =($A35-1998)/3*B35+(2004-$A35)/3*C35 -> 0 | G35: =($A35-2001)/3*C35+(2007-$A35)/3*D35 -> 0 | H35: =($A35-2004)/3*D35+(2010-$A35)/3*E35 -> 0 | I35: =($A35-1998)/6*F35+(2007-$A35)/6*G35 -> 0 | J35: =($A35-2001)/6*G35+(2010-$A35)/6*H35 -> 0 | K35: =($A35-1998)/9*I35+(2010-$A35)/9*J35 -> 0
A36: 1996 | B36: =IF(AND($A36>=1998,$A36<2001),1,0) -> 0 | C36: =IF(AND($A36>=2001,$A36<2004),1,0) -> 0 | D36: =IF(AND($A36>=2004,$A36<2007),1,0) -> 0 | E36: =IF(AND($A36>=2007,$A36<2010),1,0) -> 0 | F36: =($A36-1998)/3*B36+(2004-$A36)/3*C36 -> 0 | G36: =($A36-2001)/3*C36+(2007-$A36)/3*D36 -> 0 | H36: =($A36-2004)/3*D36+(2010-$A36)/3*E36 -> 0 | I36: =($A36-1998)/6*F36+(2007-$A36)/6*G36 -> 0 | J36: =($A36-2001)/6*G36+(2010-$A36)/6*H36 -> 0 | K36: =($A36-1998)/9*I36+(2010-$A36)/9*J36 -> 0
A37: 1997 | B37: =IF(AND($A37>=1998,$A37<2001),1,0) -> 0 | C37: =IF(AND($A37>=2001,$A37<2004),1,0) -> 0 | D37: =IF(AND($A37>=2004,$A37<2007),1,0) -> 0 | E37: =IF(AND($A37>=2007,$A37<2010),1,0) -> 0 | F37: =($A37-1998)/3*B37+(2004-$A37)/3*C37 -> 0 | G37: =($A37-2001)/3*C37+(2007-$A37)/3*D37 -> 0 | H37: =($A37-2004)/3*D37+(2010-$A37)/3*E37 -> 0 | I37: =($A37-1998)/6*F37+(2007-$A37)/6*G37 -> 0 | J37: =($A37-2001)/6*G37+(2010-$A37)/6*H37 -> 0 | K37: =($A37-1998)/9*I37+(2010-$A37)/9*J37 -> 0
A38: 1998 | B38: =IF(AND($A38>=1998,$A38<2001),1,0) -> 1 | C38: =IF(AND($A38>=2001,$A38<2004),1,0) -> 0 | D38: =IF(AND($A38>=2004,$A38<2007),1,0) -> 0 | E38: =IF(AND($A38>=2007,$A38<2010),1,0) -> 0 | F38: =($A38-1998)/3*B38+(2004-$A38)/3*C38 -> 0 | G38: =($A38-2001)/3*C38+(2007-$A38)/3*D38 -> 0 | H38: =($A38-2004)/3*D38+(2010-$A38)/3*E38 -> 0 | I38: =($A38-1998)/6*F38+(2007-$A38)/6*G38 -> 0 | J38: =($A38-2001)/6*G38+(2010-$A38)/6*H38 -> 0 | K38: =($A38-1998)/9*I38+(2010-$A38)/9*J38 -> 0
A39: 1999 | B39: =IF(AND($A39>=1998,$A39<2001),1,0) -> 1 | C39: =IF(AND($A39>=2001,$A39<2004),1,0) -> 0 | D39: =IF(AND($A39>=2004,$A39<2007),1,0) -> 0 | E39: =IF(AND($A39>=2007,$A39<2010),1,0) -> 0 | F39: =($A39-1998)/3*B39+(2004-$A39)/3*C39 -> 0.33333333 | G39: =($A39-2001)/3*C39+(2007-$A39)/3*D39 -> 0 | H39: =($A39-2004)/3*D39+(2010-$A39)/3*E39 -> 0 | I39: =($A39-1998)/6*F39+(2007-$A39)/6*G39 -> 0.055555556 | J39: =($A39-2001)/6*G39+(2010-$A39)/6*H39 -> 0 | K39: =($A39-1998)/9*I39+(2010-$A39)/9*J39 -> 0.0061728395
A40: 2000 | B40: =IF(AND($A40>=1998,$A40<2001),1,0) -> 1 | C40: =IF(AND($A40>=2001,$A40<2004),1,0) -> 0 | D40: =IF(AND($A40>=2004,$A40<2007),1,0) -> 0 | E40: =IF(AND($A40>=2007,$A40<2010),1,0) -> 0 | F40: =($A40-1998)/3*B40+(2004-$A40)/3*C40 -> 0.66666667 | G40: =($A40-2001)/3*C40+(2007-$A40)/3*D40 -> 0 | H40: =($A40-2004)/3*D40+(2010-$A40)/3*E40 -> 0 | I40: =($A40-1998)/6*F40+(2007-$A40)/6*G40 -> 0.22222222 | J40: =($A40-2001)/6*G40+(2010-$A40)/6*H40 -> 0 | K40: =($A40-1998)/9*I40+(2010-$A40)/9*J40 -> 0.049382716
A41: 2001 | B41: =IF(AND($A41>=1998,$A41<2001),1,0) -> 0 | C41: =IF(AND($A41>=2001,$A41<2004),1,0) -> 1 | D41: =IF(AND($A41>=2004,$A41<2007),1,0) -> 0 | E41: =IF(AND($A41>=2007,$A41<2010),1,0) -> 0 | F41: =($A41-1998)/3*B41+(2004-$A41)/3*C41 -> 1 | G41: =($A41-2001)/3*C41+(2007-$A41)/3*D41 -> 0 | H41: =($A41-2004)/3*D41+(2010-$A41)/3*E41 -> 0 | I41: =($A41-1998)/6*F41+(2007-$A41)/6*G41 -> 0.5 | J41: =($A41-2001)/6*G41+(2010-$A41)/6*H41 -> 0 | K41: =($A41-1998)/9*I41+(2010-$A41)/9*J41 -> 0.16666667
A42: 2002 | B42: =IF(AND($A42>=1998,$A42<2001),1,0) -> 0 | C42: =IF(AND($A42>=2001,$A42<2004),1,0) -> 1 | D42: =IF(AND($A42>=2004,$A42<2007),1,0) -> 0 | E42: =IF(AND($A42>=2007,$A42<2010),1,0) -> 0 | F42: =($A42-1998)/3*B42+(2004-$A42)/3*C42 -> 0.66666667 | G42: =($A42-2001)/3*C42+(2007-$A42)/3*D42 -> 0.33333333 | H42: =($A42-2004)/3*D42+(2010-$A42)/3*E42 -> 0 | I42: =($A42-1998)/6*F42+(2007-$A42)/6*G42 -> 0.72222222 | J42: =($A42-2001)/6*G42+(2010-$A42)/6*H42 -> 0.055555556 | K42: =($A42-1998)/9*I42+(2010-$A42)/9*J42 -> 0.37037037
A43: 2003 | B43: =IF(AND($A43>=1998,$A43<2001),1,0) -> 0 | C43: =IF(AND($A43>=2001,$A43<2004),1,0) -> 1 | D43: =IF(AND($A43>=2004,$A43<2007),1,0) -> 0 | E43: =IF(AND($A43>=2007,$A43<2010),1,0) -> 0 | F43: =($A43-1998)/3*B43+(2004-$A43)/3*C43 -> 0.33333333 | G43: =($A43-2001)/3*C43+(2007-$A43)/3*D43 -> 0.66666667 | H43: =($A43-2004)/3*D43+(2010-$A43)/3*E43 -> 0 | I43: =($A43-1998)/6*F43+(2007-$A43)/6*G43 -> 0.72222222 | J43: =($A43-2001)/6*G43+(2010-$A43)/6*H43 -> 0.22222222 | K43: =($A43-1998)/9*I43+(2010-$A43)/9*J43 -> 0.57407407
A44: 2004 | B44: =IF(AND($A44>=1998,$A44<2001),1,0) -> 0 | C44: =IF(AND($A44>=2001,$A44<2004),1,0) -> 0 | D44: =IF(AND($A44>=2004,$A44<2007),1,0) -> 1 | E44: =IF(AND($A44>=2007,$A44<2010),1,0) -> 0 | F44: =($A44-1998)/3*B44+(2004-$A44)/3*C44 -> 0 | G44: =($A44-2001)/3*C44+(2007-$A44)/3*D44 -> 1 | H44: =($A44-2004)/3*D44+(2010-$A44)/3*E44 -> 0 | I44: =($A44-1998)/6*F44+(2007-$A44)/6*G44 -> 0.5 | J44: =($A44-2001)/6*G44+(2010-$A44)/6*H44 -> 0.5 | K44: =($A44-1998)/9*I44+(2010-$A44)/9*J44 -> 0.66666667
A45: 2005 | B45: =IF(AND($A45>=1998,$A45<2001),1,0) -> 0 | C45: =IF(AND($A45>=2001,$A45<2004),1,0) -> 0 | D45: =IF(AND($A45>=2004,$A45<2007),1,0) -> 1 | E45: =IF(AND($A45>=2007,$A45<2010),1,0) -> 0 | F45: =($A45-1998)/3*B45+(2004-$A45)/3*C45 -> 0 | G45: =($A45-2001)/3*C45+(2007-$A45)/3*D45 -> 0.66666667 | H45: =($A45-2004)/3*D45+(2010-$A45)/3*E45 -> 0.33333333 | I45: =($A45-1998)/6*F45+(2007-$A45)/6*G45 -> 0.22222222 | J45: =($A45-2001)/6*G45+(2010-$A45)/6*H45 -> 0.72222222 | K45: =($A45-1998)/9*I45+(2010-$A45)/9*J45 -> 0.57407407
A46: 2006 | B46: =IF(AND($A46>=1998,$A46<2001),1,0) -> 0 | C46: =IF(AND($A46>=2001,$A46<2004),1,0) -> 0 | D46: =IF(AND($A46>=2004,$A46<2007),1,0) -> 1 | E46: =IF(AND($A46>=2007,$A46<2010),1,0) -> 0 | F46: =($A46-1998)/3*B46+(2004-$A46)/3*C46 -> 0 | G46: =($A46-2001)/3*C46+(2007-$A46)/3*D46 -> 0.33333333 | H46: =($A46-2004)/3*D46+(2010-$A46)/3*E46 -> 0.66666667 | I46: =($A46-1998)/6*F46+(2007-$A46)/6*G46 -> 0.055555556 | J46: =($A46-2001)/6*G46+(2010-$A46)/6*H46 -> 0.72222222 | K46: =($A46-1998)/9*I46+(2010-$A46)/9*J46 -> 0.37037037
... A53: 2013 | B53: =IF(AND($A53>=1998,$A53<2001),1,0) -> 0 | C53: =IF(AND($A53>=2001,$A53<2004),1,0) -> 0 | D53: =IF(AND($A53>=2004,$A53<2007),1,0) -> 0 | E53: =IF(AND($A53>=2007,$A53<2010),1,0) -> 0 | F53: =($A53-1998)/3*B53+(2004-$A53)/3*C53 -> 0 | G53: =($A53-2001)/3*C53+(2007-$A53)/3*D53 -> 0 | H53: =($A53-2004)/3*D53+(2010-$A53)/3*E53 -> 0 | I53: =($A53-1998)/6*F53+(2007-$A53)/6*G53 -> 0 | J53: =($A53-2001)/6*G53+(2010-$A53)/6*H53 -> 0 | K53: =($A53-1998)/9*I53+(2010-$A53)/9*J53 -> 0

Sheet Q2_ReadMe
A1: Question 2 — workbook guide and instructor correction
A2: Original sheets M_70_t and Sheet1 are preserved. Source: uploaded M_70_t.xlsx. Added sheets contain all Q2 calculations. Input rates have units of deaths per person-year; coefficients describe natural-log mortality; the B-spline basis is dimensionless.
A4: Instructor correction supplied by the user: treat (b) and (c) independently. For (c), refit both M1 and M2 using M_70_t data and refer to age 70 in the discussion, although the instructor states the spreadsheet rates actually belong to age 25.
A6: Part (b) inputs from assignment PDF (independent of spreadsheet observations)
A7: Year | B7: Central death rate
A8: 1995 | B8: 0.0235
A9: 1998 | B9: 0.0207
A10: 2001 | B10: 0.0183
A11: 2004 | B11: 0.0166
A13: Part (b) uses exactly the four rates above: no interpolation of missing annual observations and no use of M_70_t data in estimation. Annual fitted values are model evaluations, not invented observations.
A15: Part (c) uses M_70_t!A2:B11 (1995–2004) to estimate both models. Rows A12:B26 (2005–2019) are retained as out-of-sample observations for plotting only; they do not enter SSE or the normal equations.
A17: Q2(a)_Derivation: recursion and support; Q2(b)_M1: independent four-point M1; Q2(c)_M1: refitted M1; Q2(c)_M2: annual-knot M2; Q2(c)_Comparison: three curves and responses to Kevin.
A19: No extra objective, nonnegativity constraint, automatic smoothing selection is used. As confirmed by the user, LN(m) is the response, following Unit 4 pp.79–80 and Week11_Q1sol.xlsx; EXP converts fitted log rates back to mortality. lambda=1 and the second-order coefficient penalty are applied exactly as L=SSE+(lambda/2)*Penalty.
A21: Method reference: assignment Q2 Cox–de Boor construction and coefficient second-difference projection. The zero-second-difference forecast continues the final coefficient slope. Cross-checked against Unit 4 pp.63–64,79–81 and Week11_Q1sol.xlsx. Unit 4 p.88 uses a third-order example; this assignment specifies second order, so the Week 11 second-order extension is used.
A25: Year | B25: Part (b) M1 projection
A26: 2007 | B26: ='Q2(b)_M1'!C20 -> 0.014826547
A27: 2010 | B27: ='Q2(b)_M1'!C23 -> 0.013316994
A28: 2013 | B28: ='Q2(b)_M1'!C26 -> 0.011961134
A29: 2016 | B29: ='Q2(b)_M1'!C29 -> 0.01074332
A30: 2019 | B30: ='Q2(b)_M1'!C32 -> 0.0096494969

Sheet Q2(b)_M1
A1: Q2(b): M1, four assignment observations
A2: Fit only the stated training observations. Cubic B-splines have order 4 and support [t_j,t_j+4h). Observed/output rates are annual central death rates (per person-year). The response and fitted coefficients are on the natural-log mortality scale; knot locations are calendar years.
A4: lambda | B4: 1 | C4: Knot step h | D4: 3
A5: Log-scale objective: L=SSE+(lambda/2)*SUM((theta_j−2*theta_(j−1)+theta_(j−2))^2). Normal equations: [BᵀB+(lambda/2)D₂ᵀD₂]theta=BᵀLN(m). SSE=SUM((LN(m)−B*theta)^2). No nonnegativity constraint, tuning, or extra penalty is used.
A7: Year | B7: Observed rate | C7: Fitted / projected | D7: Period | E7: Training residual | F7: Log residual² | G7: Fitted / projected LN(m)
A8: 1995 | B8: ='Q2_ReadMe'!B8 -> 0.0235 | C8: =EXP(G8) -> 0.023424538 | D8: Fitted | E8: =LN(B8)-G8 -> 0.0032162971 | F8: =E8^2 -> 1.0344567e-05 | G8: {=MMULT(AO150:AY150,$I$15:$I$25)} -> -3.7539712 | H8: SSE | I8: =SUM(F8:F17) -> 9.4615696e-05
A9: 1996 | C9: =EXP(G9) -> 0.022478879 | D9: Fitted | G9: {=MMULT(AO151:AY151,$I$15:$I$25)} -> -3.7951791 | H9: Penalty (estimated theta only) | I9: =SUM(K17:K20) -> 0.00010744318
A10: 1997 | C10: =EXP(G10) -> 0.021577951 | D10: Fitted | G10: {=MMULT(AO152:AY152,$I$15:$I$25)} -> -3.8360833 | H10: L = SSE + lambda/2*Penalty | I10: =I8+$B$4/2*I9 -> 0.00014833728
A11: 1998 | B11: ='Q2_ReadMe'!B9 -> 0.0207 | C11: =EXP(G11) -> 0.020723251 | D11: Fitted | E11: =LN(B11)-G11 -> -0.0011225944 | F11: =E11^2 -> 1.2602182e-06 | G11: {=MMULT(AO153:AY153,$I$15:$I$25)} -> -3.876499
A12: 1999 | C12: =EXP(G12) -> 0.019915452 | D12: Fitted | G12: {=MMULT(AO154:AY154,$I$15:$I$25)} -> -3.9162594
A13: 2000 | C13: =EXP(G13) -> 0.019153514 | D13: Fitted | G13: {=MMULT(AO155:AY155,$I$15:$I$25)} -> -3.9552691
A14: 2001 | B14: ='Q2_ReadMe'!B10 -> 0.0183 | C14: =EXP(G14) -> 0.018435991 | D14: Fitted | E14: =LN(B14)-G14 -> -0.0074037026 | F14: =E14^2 -> 5.4814812e-05 | G14: {=MMULT(AO156:AY156,$I$15:$I$25)} -> -3.9934505 | H14: Coefficient knot | I14: theta | J14: Second difference | K14: Squared difference | L14: Status
A15: 2002 | C15: =EXP(G15) -> 0.017760498 | D15: Fitted | G15: {=MMULT(AO157:AY157,$I$15:$I$25)} -> -4.0307785 | H15: 1986 | I15: {=INDEX(MMULT(MINVERSE($C$91:$H$96),$J$91:$J$96),1,1)} -> -3.6297189 | L15: Estimated
A16: 2003 | C16: =EXP(G16) -> 0.017121213 | D16: Fitted | G16: {=MMULT(AO158:AY158,$I$15:$I$25)} -> -4.0674371 | H16: 1989 | I16: {=INDEX(MMULT(MINVERSE($C$91:$H$96),$J$91:$J$96),2,1)} -> -3.7541498 | L16: Estimated
A17: 2004 | B17: ='Q2_ReadMe'!B11 -> 0.0166 | C17: =EXP(G17) -> 0.016512088 | D17: Fitted | E17: =LN(B17)-G17 -> 0.0053099999 | F17: =E17^2 -> 2.8196099e-05 | G17: {=MMULT(AO159:AY159,$I$15:$I$25)} -> -4.1036626 | H17: 1992 | I17: {=INDEX(MMULT(MINVERSE($C$91:$H$96),$J$91:$J$96),3,1)} -> -3.8775087 | J17: =I17-2*I16+I15 -> 0.001072099 | K17: =J17^2 -> 1.1493964e-06 | L17: Estimated
A18: 2005 | C18: =EXP(G18) -> 0.015928219 | D18: Projected | G18: {=MMULT(AO160:AY160,$I$15:$I$25)} -> -4.139663 | H18: 1995 | I18: {=INDEX(MMULT(MINVERSE($C$91:$H$96),$J$91:$J$96),4,1)} -> -3.9948092 | J18: =I18-2*I17+I16 -> 0.0060583961 | K18: =J18^2 -> 3.6704164e-05 | L18: Estimated
A19: 2006 | C19: =EXP(G19) -> 0.01536701 | D19: Projected | G19: {=MMULT(AO161:AY161,$I$15:$I$25)} -> -4.1755322 | H19: 1998 | I19: {=INDEX(MMULT(MINVERSE($C$91:$H$96),$J$91:$J$96),5,1)} -> -4.1039576 | J19: =I19-2*I18+I17 -> 0.0081520989 | K19: =J19^2 -> 6.6456716e-05 | L19: Estimated
A20: 2007 | C20: =EXP(G20) -> 0.014826547 | D20: Projected | G20: {=MMULT(AO162:AY162,$I$15:$I$25)} -> -4.211336 | H20: 2001 | I20: {=INDEX(MMULT(MINVERSE($C$91:$H$96),$J$91:$J$96),6,1)} -> -4.211336 | J20: =I20-2*I19+I18 -> 0.00177 | K20: =J20^2 -> 3.1328999e-06 | L20: Estimated
A21: 2008 | C21: =EXP(G21) -> 0.014305249 | D21: Projected | G21: {=MMULT(AO163:AY163,$I$15:$I$25)} -> -4.2471288 | H21: 2004 | I21: =2*I20-I19 -> -4.3187144 | J21: =I21-2*I20+I19 -> 0 | K21: =J21^2 -> 0 | L21: Projected: Δ²theta=0
A22: 2009 | C22: =EXP(G22) -> 0.013802279 | D22: Projected | G22: {=MMULT(AO164:AY164,$I$15:$I$25)} -> -4.2829216 | H22: 2007 | I22: =2*I21-I20 -> -4.4260927 | J22: =I22-2*I21+I20 -> 0 | K22: =J22^2 -> 0 | L22: Projected: Δ²theta=0
A23: 2010 | C23: =EXP(G23) -> 0.013316994 | D23: Projected | G23: {=MMULT(AO165:AY165,$I$15:$I$25)} -> -4.3187144 | H23: 2010 | I23: =2*I22-I21 -> -4.5334711 | J23: =I23-2*I22+I21 -> 0 | K23: =J23^2 -> 0 | L23: Projected: Δ²theta=0
A24: 2011 | C24: =EXP(G24) -> 0.012848771 | D24: Projected | G24: {=MMULT(AO166:AY166,$I$15:$I$25)} -> -4.3545071 | H24: 2013 | I24: =2*I23-I22 -> -4.6408495 | J24: =I24-2*I23+I22 -> 0 | K24: =J24^2 -> 0 | L24: Projected: Δ²theta=0
A25: 2012 | C25: =EXP(G25) -> 0.01239701 | D25: Projected | G25: {=MMULT(AO167:AY167,$I$15:$I$25)} -> -4.3902999 | H25: 2016 | I25: =2*I24-I23 -> -4.7482279 | J25: =I25-2*I24+I23 -> 0 | K25: =J25^2 -> 0 | L25: Projected: Δ²theta=0
A26: 2013 | C26: =EXP(G26) -> 0.011961134 | D26: Projected | G26: {=MMULT(AO168:AY168,$I$15:$I$25)} -> -4.4260927
A27: 2014 | C27: =EXP(G27) -> 0.011540583 | D27: Projected | G27: {=MMULT(AO169:AY169,$I$15:$I$25)} -> -4.4618855
A28: 2015 | C28: =EXP(G28) -> 0.011134818 | D28: Projected | G28: {=MMULT(AO170:AY170,$I$15:$I$25)} -> -4.4976783
A29: 2016 | C29: =EXP(G29) -> 0.01074332 | D29: Projected | G29: {=MMULT(AO171:AY171,$I$15:$I$25)} -> -4.5334711
A30: 2017 | C30: =EXP(G30) -> 0.010365587 | D30: Projected | G30: {=MMULT(AO172:AY172,$I$15:$I$25)} -> -4.5692639
A31: 2018 | C31: =EXP(G31) -> 0.010001135 | D31: Projected | G31: {=MMULT(AO173:AY173,$I$15:$I$25)} -> -4.6050567
A32: 2019 | C32: =EXP(G32) -> 0.0096494969 | D32: Projected | G32: {=MMULT(AO174:AY174,$I$15:$I$25)} -> -4.6408495
A68: Training design matrix B and response y=LN(m) (training years only)
A70: Training year | B70: y = LN(m) | C70: B1986,4 | D70: B1989,4 | E70: B1992,4 | F70: B1995,4 | G70: B1998,4 | H70: B2001,4
A71: 1995 | B71: =LN('Q2_ReadMe'!B8) -> -3.7507549 | C71: =AO150 -> 0.16666667 | D71: =AP150 -> 0.66666667 | E71: =AQ150 -> 0.16666667 | F71: =AR150 -> 0 | G71: =AS150 -> 0 | H71: =AT150 -> 0
A72: 1998 | B72: =LN('Q2_ReadMe'!B9) -> -3.8776216 | C72: =AO153 -> 0 | D72: =AP153 -> 0.16666667 | E72: =AQ153 -> 0.66666667 | F72: =AR153 -> 0.16666667 | G72: =AS153 -> 0 | H72: =AT153 -> 0
A73: 2001 | B73: =LN('Q2_ReadMe'!B10) -> -4.0008542 | C73: =AO156 -> 0 | D73: =AP156 -> 0 | E73: =AQ156 -> 0.16666667 | F73: =AR156 -> 0.66666667 | G73: =AS156 -> 0.16666667 | H73: =AT156 -> 0
A74: 2004 | B74: =LN('Q2_ReadMe'!B11) -> -4.0983526 | C74: =AO159 -> 0 | D74: =AP159 -> 0 | E74: =AQ159 -> 0 | F74: =AR159 -> 0.16666667 | G74: =AS159 -> 0.66666667 | H74: =AT159 -> 0.16666667
A88: Penalised normal matrix G = BᵀB + (lambda/2)D₂ᵀD₂, and RHS = Bᵀy
C90: 1986 | D90: 1989 | E90: 1992 | F90: 1995 | G90: 1998 | H90: 2001 | J90: Bᵀy
A91: 1986 | C91: =SUMPRODUCT(C$71:C$74,C$71:C$74)+$B$4/2*SUMPRODUCT(C$111:C$114,C$111:C$114) -> 0.52777778 | D91: =SUMPRODUCT(C$71:C$74,D$71:D$74)+$B$4/2*SUMPRODUCT(C$111:C$114,D$111:D$114) -> -0.88888889 | E91: =SUMPRODUCT(C$71:C$74,E$71:E$74)+$B$4/2*SUMPRODUCT(C$111:C$114,E$111:E$114) -> 0.52777778 | F91: =SUMPRODUCT(C$71:C$74,F$71:F$74)+$B$4/2*SUMPRODUCT(C$111:C$114,F$111:F$114) -> 0 | G91: =SUMPRODUCT(C$71:C$74,G$71:G$74)+$B$4/2*SUMPRODUCT(C$111:C$114,G$111:G$114) -> 0 | H91: =SUMPRODUCT(C$71:C$74,H$71:H$74)+$B$4/2*SUMPRODUCT(C$111:C$114,H$111:H$114) -> 0 | J91: =SUMPRODUCT(C$71:C$74,$B$71:$B$74) -> -0.62512581
A92: 1989 | C92: =SUMPRODUCT(D$71:D$74,C$71:C$74)+$B$4/2*SUMPRODUCT(D$111:D$114,C$111:C$114) -> -0.88888889 | D92: =SUMPRODUCT(D$71:D$74,D$71:D$74)+$B$4/2*SUMPRODUCT(D$111:D$114,D$111:D$114) -> 2.9722222 | E92: =SUMPRODUCT(D$71:D$74,E$71:E$74)+$B$4/2*SUMPRODUCT(D$111:D$114,E$111:E$114) -> -1.7777778 | F92: =SUMPRODUCT(D$71:D$74,F$71:F$74)+$B$4/2*SUMPRODUCT(D$111:D$114,F$111:F$114) -> 0.52777778 | G92: =SUMPRODUCT(D$71:D$74,G$71:G$74)+$B$4/2*SUMPRODUCT(D$111:D$114,G$111:G$114) -> 0 | H92: =SUMPRODUCT(D$71:D$74,H$71:H$74)+$B$4/2*SUMPRODUCT(D$111:D$114,H$111:H$114) -> 0 | J92: =SUMPRODUCT(D$71:D$74,$B$71:$B$74) -> -3.1467735
...

Sheet Q2(c)_M1
A1: Q2(c): M1 refitted to supplied annual data
A2: Fit only the stated training observations. Cubic B-splines have order 4 and support [t_j,t_j+4h). Observed/output rates are annual central death rates (per person-year). The response and fitted coefficients are on the natural-log mortality scale; knot locations are calendar years.
A4: lambda | B4: 1 | C4: Knot step h | D4: 3
A5: Log-scale objective: L=SSE+(lambda/2)*SUM((theta_j−2*theta_(j−1)+theta_(j−2))^2). Normal equations: [BᵀB+(lambda/2)D₂ᵀD₂]theta=BᵀLN(m). SSE=SUM((LN(m)−B*theta)^2). No nonnegativity constraint, tuning, or extra penalty is used.
A7: Year | B7: Observed rate | C7: Fitted / projected | D7: Period | E7: Training residual | F7: Log residual² | G7: Fitted / projected LN(m)
A8: 1995 | B8: ='M_70_t'!B2 -> 0.00085662921 | C8: =EXP(G8) -> 0.0008706219 | D8: Fitted | E8: =LN(B8)-G8 -> -0.016202608 | F8: =E8^2 -> 0.0002625245 | G8: {=MMULT(AO150:AY150,$I$15:$I$25)} -> -7.0463028 | H8: SSE | I8: =SUM(F8:F17) -> 0.078972717
A9: 1996 | B9: ='M_70_t'!B3 -> 0.00082999933 | C9: =EXP(G9) -> 0.0008729578 | D9: Fitted | E9: =LN(B9)-G9 -> -0.050462327 | F9: =E9^2 -> 0.0025464465 | G9: {=MMULT(AO151:AY151,$I$15:$I$25)} -> -7.0436233 | H9: Penalty (estimated theta only) | I9: =SUM(K17:K20) -> 0.026319106
A10: 1997 | B10: ='M_70_t'!B4 -> 0.00080999953 | C10: =EXP(G10) -> 0.00087078595 | D10: Fitted | E10: =LN(B10)-G10 -> -0.072362526 | F10: =E10^2 -> 0.0052363351 | G10: {=MMULT(AO152:AY152,$I$15:$I$25)} -> -7.0461144 | H10: L = SSE + lambda/2*Penalty | I10: =I8+$B$4/2*I9 -> 0.09213227
A11: 1998 | B11: ='M_70_t'!B5 -> 0.00097750974 | C11: =EXP(G11) -> 0.00086076144 | D11: Fitted | E11: =LN(B11)-G11 -> 0.12719087 | F11: =E11^2 -> 0.016177517 | G11: {=MMULT(AO153:AY153,$I$15:$I$25)} -> -7.0576932
A12: 1999 | B12: ='M_70_t'!B6 -> 0.00078849179 | C12: =EXP(G12) -> 0.00084043562 | D12: Fitted | E12: =LN(B12)-G12 -> -0.063798354 | F12: =E12^2 -> 0.00407023 | G12: {=MMULT(AO154:AY154,$I$15:$I$25)} -> -7.0815902
A13: 2000 | B13: ='M_70_t'!B7 -> 0.00099667191 | C13: =EXP(G13) -> 0.00081015218 | D13: Fitted | E13: =LN(B13)-G13 -> 0.20719954 | F13: =E13^2 -> 0.042931648 | G13: {=MMULT(AO155:AY155,$I$15:$I$25)} -> -7.1182885
A14: 2001 | B14: ='M_70_t'!B8 -> 0.00075112818 | C14: =EXP(G14) -> 0.00077118367 | D14: Fitted | E14: =LN(B14)-G14 -> -0.026350255 | F14: =E14^2 -> 0.00069433592 | G14: {=MMULT(AO156:AY156,$I$15:$I$25)} -> -7.167584 | H14: Coefficient knot | I14: theta | J14: Second difference | K14: Squared difference | L14: Status
A15: 2002 | B15: ='M_70_t'!B9 -> 0.0007042875 | C15: =EXP(G15) -> 0.00072549063 | D15: Fitted | E15: =LN(B15)-G15 -> -0.029661505 | F15: =E15^2 -> 0.00087980489 | G15: {=MMULT(AO157:AY157,$I$15:$I$25)} -> -7.2286624 | H15: 1986 | I15: {=INDEX(MMULT(MINVERSE($C$91:$H$96),$J$91:$J$96),1,1)} -> -7.0619388 | L15: Estimated
A16: 2003 | B16: ='M_70_t'!B10 -> 0.00062560882 | C16: =EXP(G16) -> 0.00067671034 | D16: Fitted | E16: =LN(B16)-G16 -> -0.078518041 | F16: =E16^2 -> 0.0061650828 | G16: {=MMULT(AO158:AY158,$I$15:$I$25)} -> -7.2982672 | H16: 1989 | I16: {=INDEX(MMULT(MINVERSE($C$91:$H$96),$J$91:$J$96),2,1)} -> -7.0444231 | L16: Estimated
A17: 2004 | B17: ='M_70_t'!B11 -> 0.00063014139 | C17: =EXP(G17) -> 0.00062827566 | D17: Fitted | E17: =LN(B17)-G17 -> 0.0029652113 | F17: =E17^2 -> 8.7924778e-06 | G17: {=MMULT(AO159:AY159,$I$15:$I$25)} -> -7.3725315 | H17: 1992 | I17: {=INDEX(MMULT(MINVERSE($C$91:$H$96),$J$91:$J$96),3,1)} -> -7.0381855 | J17: =I17-2*I16+I15 -> -0.011278167 | K17: =J17^2 -> 0.00012719706 | L17: Estimated
A18: 2005 | B18: ='M_70_t'!B12 -> 0.00058383424 | C18: =EXP(G18) -> 0.00058249566 | D18: Projected | G18: {=MMULT(AO160:AY160,$I$15:$I$25)} -> -7.4481888 | H18: 1995 | I18: {=INDEX(MMULT(MINVERSE($C$91:$H$96),$J$91:$J$96),4,1)} -> -7.1489939 | J18: =I18-2*I17+I16 -> -0.11704601 | K18: =J18^2 -> 0.013699768 | L18: Estimated
A19: 2006 | B19: ='M_70_t'!B13 -> 0.00049907285 | C19: =EXP(G19) -> 0.00053976621 | D19: Projected | G19: {=MMULT(AO161:AY161,$I$15:$I$25)} -> -7.5243745 | H19: 1998 | I19: {=INDEX(MMULT(MINVERSE($C$91:$H$96),$J$91:$J$96),5,1)} -> -7.3713428 | J19: =I19-2*I18+I17 -> -0.11154043 | K19: =J19^2 -> 0.012441267 | L19: Estimated
A20: 2007 | B20: ='M_70_t'!B14 -> 0.0005624154 | C20: =EXP(G20) -> 0.0005000391 | D20: Projected | G20: {=MMULT(AO162:AY162,$I$15:$I$25)} -> -7.6008243 | H20: 2001 | I20: {=INDEX(MMULT(MINVERSE($C$91:$H$96),$J$91:$J$96),6,1)} -> -7.6008243 | J20: =I20-2*I19+I18 -> -0.0071326559 | K20: =J20^2 -> 5.087478e-05 | L20: Estimated
A21: 2008 | B21: ='M_70_t'!B15 -> 0.00056619808 | C21: =EXP(G21) -> 0.00046321553 | D21: Projected | G21: {=MMULT(AO163:AY163,$I$15:$I$25)} -> -7.6773181 | H21: 2004 | I21: =2*I20-I19 -> -7.8303058 | J21: =I21-2*I20+I19 -> 0 | K21: =J21^2 -> 0 | L21: Projected: Δ²theta=0
A22: 2009 | B22: ='M_70_t'!B16 -> 0.00054060672 | C22: =EXP(G22) -> 0.0004291037 | D22: Projected | G22: {=MMULT(AO164:AY164,$I$15:$I$25)} -> -7.7538119 | H22: 2007 | I22: =2*I21-I20 -> -8.0597873 | J22: =I22-2*I21+I20 -> 0 | K22: =J22^2 -> 0 | L22: Projected: Δ²theta=0
A23: 2010 | B23: ='M_70_t'!B17 -> 0.00048500736 | C23: =EXP(G23) -> 0.00039750392 | D23: Projected | G23: {=MMULT(AO165:AY165,$I$15:$I$25)} -> -7.8303058 | H23: 2010 | I23: =2*I22-I21 -> -8.2892688 | J23: =I23-2*I22+I21 -> -8.8817842e-16 | K23: =J23^2 -> 7.8886091e-31 | L23: Projected: Δ²theta=0
A24: 2011 | B24: ='M_70_t'!B18 -> 0.00052495861 | C24: =EXP(G24) -> 0.00036823118 | D24: Projected | G24: {=MMULT(AO166:AY166,$I$15:$I$25)} -> -7.9067996 | H24: 2013 | I24: =2*I23-I22 -> -8.5187503 | J24: =I24-2*I23+I22 -> 0 | K24: =J24^2 -> 0 | L24: Projected: Δ²theta=0
A25: 2012 | B25: ='M_70_t'!B19 -> 0.00044495933 | C25: =EXP(G25) -> 0.00034111413 | D25: Projected | G25: {=MMULT(AO167:AY167,$I$15:$I$25)} -> -7.9832934 | H25: 2016 | I25: =2*I24-I23 -> -8.7482318 | J25: =I25-2*I24+I23 -> 0 | K25: =J25^2 -> 0 | L25: Projected: Δ²theta=0
A26: 2013 | B26: ='M_70_t'!B20 -> 0.00041112307 | C26: =EXP(G26) -> 0.00031599402 | D26: Projected | G26: {=MMULT(AO168:AY168,$I$15:$I$25)} -> -8.0597873
A27: 2014 | B27: ='M_70_t'!B21 -> 0.00044881582 | C27: =EXP(G27) -> 0.00029272379 | D27: Projected | G27: {=MMULT(AO169:AY169,$I$15:$I$25)} -> -8.1362811
A28: 2015 | B28: ='M_70_t'!B22 -> 0.00040681103 | C28: =EXP(G28) -> 0.0002711672 | D28: Projected | G28: {=MMULT(AO170:AY170,$I$15:$I$25)} -> -8.2127749
A29: 2016 | B29: ='M_70_t'!B23 -> 0.00049105418 | C29: =EXP(G29) -> 0.00025119808 | D29: Projected | G29: {=MMULT(AO171:AY171,$I$15:$I$25)} -> -8.2892688
A30: 2017 | B30: ='M_70_t'!B24 -> 0.00046002433 | C30: =EXP(G30) -> 0.00023269951 | D30: Projected | G30: {=MMULT(AO172:AY172,$I$15:$I$25)} -> -8.3657626
A31: 2018 | B31: ='M_70_t'!B25 -> 0.0004166418 | C31: =EXP(G31) -> 0.0002155632 | D31: Projected | G31: {=MMULT(AO173:AY173,$I$15:$I$25)} -> -8.4422564
A32: 2019 | B32: ='M_70_t'!B26 -> 0.00044343997 | C32: =EXP(G32) -> 0.00019968883 | D32: Projected | G32: {=MMULT(AO174:AY174,$I$15:$I$25)} -> -8.5187503
A68: Training design matrix B and response y=LN(m) (training years only)
A70: Training year | B70: y = LN(m) | C70: B1986,4 | D70: B1989,4 | E70: B1992,4 | F70: B1995,4 | G70: B1998,4 | H70: B2001,4
A71: 1995 | B71: =LN('M_70_t'!B2) -> -7.0625054 | C71: =AO150 -> 0.16666667 | D71: =AP150 -> 0.66666667 | E71: =AQ150 -> 0.16666667 | F71: =AR150 -> 0 | G71: =AS150 -> 0 | H71: =AT150 -> 0
A72: 1996 | B72: =LN('M_70_t'!B3) -> -7.0940857 | C72: =AO151 -> 0.049382716 | D72: =AP151 -> 0.57407407 | E72: =AQ151 -> 0.37037037 | F72: =AR151 -> 0.0061728395 | G72: =AS151 -> 0 | H72: =AT151 -> 0
A73: 1997 | B73: =LN('M_70_t'!B4) -> -7.1184769 | C73: =AO152 -> 0.0061728395 | D73: =AP152 -> 0.37037037 | E73: =AQ152 -> 0.57407407 | F73: =AR152 -> 0.049382716 | G73: =AS152 -> 0 | H73: =AT152 -> 0
A74: 1998 | B74: =LN('M_70_t'!B5) -> -6.9305023 | C74: =AO153 -> 0 | D74: =AP153 -> 0.16666667 | E74: =AQ153 -> 0.66666667 | F74: =AR153 -> 0.16666667 | G74: =AS153 -> 0 | H74: =AT153 -> 0
A75: 1999 | B75: =LN('M_70_t'!B6) -> -7.1453886 | C75: =AO154 -> 0 | D75: =AP154 -> 0.049382716 | E75: =AQ154 -> 0.57407407 | F75: =AR154 -> 0.37037037 | G75: =AS154 -> 0.0061728395 | H75: =AT154 -> 0
A76: 2000 | B76: =LN('M_70_t'!B7) -> -6.9110889 | C76: =AO155 -> 0 | D76: =AP155 -> 0.0061728395 | E76: =AQ155 -> 0.37037037 | F76: =AR155 -> 0.57407407 | G76: =AS155 -> 0.049382716 | H76: =AT155 -> 0
A77: 2001 | B77: =LN('M_70_t'!B8) -> -7.1939342 | C77: =AO156 -> 0 | D77: =AP156 -> 0 | E77: =AQ156 -> 0.16666667 | F77: =AR156 -> 0.66666667 | G77: =AS156 -> 0.16666667 | H77: =AT156 -> 0
A78: 2002 | B78: =LN('M_70_t'!B9) -> -7.2583239 | C78: =AO157 -> 0 | D78: =AP157 -> 0 | E78: =AQ157 -> 0.049382716 | F78: =AR157 -> 0.57407407 | G78: =AS157 -> 0.37037037 | H78: =AT157 -> 0.0061728395
...

Sheet Q2(c)_M2
A1: Q2(c): M2 with annual knots
A2: Fit only the stated training observations. Cubic B-splines have order 4 and support [t_j,t_j+4h). Observed/output rates are annual central death rates (per person-year). The response and fitted coefficients are on the natural-log mortality scale; knot locations are calendar years.
A4: lambda | B4: 1 | C4: Knot step h | D4: 1
A5: Log-scale objective: L=SSE+(lambda/2)*SUM((theta_j−2*theta_(j−1)+theta_(j−2))^2). Normal equations: [BᵀB+(lambda/2)D₂ᵀD₂]theta=BᵀLN(m). SSE=SUM((LN(m)−B*theta)^2). No nonnegativity constraint, tuning, or extra penalty is used.
A7: Year | B7: Observed rate | C7: Fitted / projected | D7: Period | E7: Training residual | F7: Log residual² | G7: Fitted / projected LN(m)
A8: 1995 | B8: ='M_70_t'!B2 -> 0.00085662921 | C8: =EXP(G8) -> 0.00084301756 | D8: Fitted | E8: =LN(B8)-G8 -> 0.016017381 | F8: =E8^2 -> 0.00025655649 | G8: {=MMULT(CK150:DK150,$I$15:$I$41)} -> -7.0785228 | H8: SSE | I8: =SUM(F8:F17) -> 0.052886243
A9: 1996 | B9: ='M_70_t'!B3 -> 0.00082999933 | C9: =EXP(G9) -> 0.00084087505 | D9: Fitted | E9: =LN(B9)-G9 -> -0.013018184 | F9: =E9^2 -> 0.00016947312 | G9: {=MMULT(CK151:DK151,$I$15:$I$41)} -> -7.0810675 | H9: Penalty (estimated theta only) | I9: =SUM(K17:K26) -> 0.012804924
A10: 1997 | B10: ='M_70_t'!B4 -> 0.00080999953 | C10: =EXP(G10) -> 0.00085782785 | D10: Fitted | E10: =LN(B10)-G10 -> -0.057369768 | F10: =E10^2 -> 0.0032912903 | G10: {=MMULT(CK152:DK152,$I$15:$I$41)} -> -7.0611071 | H10: L = SSE + lambda/2*Penalty | I10: =I8+$B$4/2*I9 -> 0.059288704
A11: 1998 | B11: ='M_70_t'!B5 -> 0.00097750974 | C11: =EXP(G11) -> 0.00088477982 | D11: Fitted | E11: =LN(B11)-G11 -> 0.099669436 | F11: =E11^2 -> 0.0099339965 | G11: {=MMULT(CK153:DK153,$I$15:$I$41)} -> -7.0301717
A12: 1999 | B12: ='M_70_t'!B6 -> 0.00078849179 | C12: =EXP(G12) -> 0.00088983283 | D12: Fitted | E12: =LN(B12)-G12 -> -0.12091161 | F12: =E12^2 -> 0.014619618 | G12: {=MMULT(CK154:DK154,$I$15:$I$41)} -> -7.0244769
A13: 2000 | B13: ='M_70_t'!B7 -> 0.00099667191 | C13: =EXP(G13) -> 0.00086510202 | D13: Fitted | E13: =LN(B13)-G13 -> 0.1415742 | F13: =E13^2 -> 0.020043255 | G13: {=MMULT(CK155:DK155,$I$15:$I$41)} -> -7.0526631
A14: 2001 | B14: ='M_70_t'!B8 -> 0.00075112818 | C14: =EXP(G14) -> 0.00079031773 | D14: Fitted | E14: =LN(B14)-G14 -> -0.050858734 | F14: =E14^2 -> 0.0025866108 | G14: {=MMULT(CK156:DK156,$I$15:$I$41)} -> -7.1430755 | H14: Coefficient knot | I14: theta | J14: Second difference | K14: Squared difference | L14: Status
A15: 2002 | B15: ='M_70_t'!B9 -> 0.0007042875 | C15: =EXP(G15) -> 0.000707654 | D15: Fitted | E15: =LN(B15)-G15 -> -0.004768617 | F15: =E15^2 -> 2.2739708e-05 | G15: {=MMULT(CK157:DK157,$I$15:$I$41)} -> -7.2535553 | H15: 1992 | I15: {=INDEX(MMULT(MINVERSE($C$91:$N$102),$P$91:$P$102),1,1)} -> -7.0678027 | L15: Estimated
A16: 2003 | B16: ='M_70_t'!B10 -> 0.00062560882 | C16: =EXP(G16) -> 0.00064858288 | D16: Fitted | E16: =LN(B16)-G16 -> -0.036064508 | F16: =E16^2 -> 0.0013006488 | G16: {=MMULT(CK158:DK158,$I$15:$I$41)} -> -7.3407208 | H16: 1993 | I16: {=INDEX(MMULT(MINVERSE($C$91:$N$102),$P$91:$P$102),2,1)} -> -7.0794126 | L16: Estimated
A17: 2004 | B17: ='M_70_t'!B11 -> 0.00063014139 | C17: =EXP(G17) -> 0.00061413442 | D17: Fitted | E17: =LN(B17)-G17 -> 0.025730404 | F17: =E17^2 -> 0.00066205367 | G17: {=MMULT(CK159:DK159,$I$15:$I$41)} -> -7.3952967 | H17: 1994 | I17: {=INDEX(MMULT(MINVERSE($C$91:$N$102),$P$91:$P$102),3,1)} -> -7.0856834 | J17: =I17-2*I16+I15 -> 0.0053391269 | K17: =J17^2 -> 2.8506276e-05 | L17: Estimated
A18: 2005 | B18: ='M_70_t'!B12 -> 0.00058383424 | C18: =EXP(G18) -> 0.0005887072 | D18: Projected | G18: {=MMULT(CK160:DK160,$I$15:$I$41)} -> -7.4375816 | H18: 1995 | I18: {=INDEX(MMULT(MINVERSE($C$91:$N$102),$P$91:$P$102),4,1)} -> -7.0642588 | J18: =I18-2*I17+I16 -> 0.027695367 | K18: =J18^2 -> 0.00076703334 | L18: Estimated
A19: 2006 | B19: ='M_70_t'!B13 -> 0.00049907285 | C19: =EXP(G19) -> 0.00056514002 | D19: Projected | G19: {=MMULT(CK161:DK161,$I$15:$I$41)} -> -7.478437 | H19: 1996 | I19: {=INDEX(MMULT(MINVERSE($C$91:$N$102),$P$91:$P$102),5,1)} -> -7.0239243 | J19: =I19-2*I18+I17 -> 0.018909898 | K19: =J19^2 -> 0.00035758426 | L19: Estimated
A20: 2007 | B20: ='M_70_t'!B14 -> 0.0005624154 | C20: =EXP(G20) -> 0.00054251629 | D20: Projected | G20: {=MMULT(CK162:DK162,$I$15:$I$41)} -> -7.5192924 | H20: 1997 | I20: {=INDEX(MMULT(MINVERSE($C$91:$N$102),$P$91:$P$102),6,1)} -> -7.0210746 | J20: =I20-2*I19+I18 -> -0.037484844 | K20: =J20^2 -> 0.0014051135 | L20: Estimated
A21: 2008 | B21: ='M_70_t'!B15 -> 0.00056619808 | C21: =EXP(G21) -> 0.00052079823 | D21: Projected | G21: {=MMULT(CK163:DK163,$I$15:$I$41)} -> -7.5601479 | H21: 1998 | I21: {=INDEX(MMULT(MINVERSE($C$91:$N$102),$P$91:$P$102),7,1)} -> -7.0386391 | J21: =I21-2*I20+I19 -> -0.020414131 | K21: =J21^2 -> 0.00041673676 | L21: Estimated
A22: 2009 | B22: ='M_70_t'!B16 -> 0.00054060672 | C22: =EXP(G22) -> 0.0004999496 | D22: Projected | G22: {=MMULT(CK164:DK164,$I$15:$I$41)} -> -7.6010033 | H22: 1999 | I22: {=INDEX(MMULT(MINVERSE($C$91:$N$102),$P$91:$P$102),8,1)} -> -7.1403479 | J22: =I22-2*I21+I20 -> -0.084144356 | K22: =J22^2 -> 0.0070802726 | L22: Estimated
A23: 2010 | B23: ='M_70_t'!B17 -> 0.00048500736 | C23: =EXP(G23) -> 0.00047993557 | D23: Projected | G23: {=MMULT(CK165:DK165,$I$15:$I$41)} -> -7.6418587 | H23: 2000 | I23: {=INDEX(MMULT(MINVERSE($C$91:$N$102),$P$91:$P$102),9,1)} -> -7.2584225 | J23: =I23-2*I22+I21 -> -0.016365757 | K23: =J23^2 -> 0.000267838 | L23: Estimated
A24: 2011 | B24: ='M_70_t'!B18 -> 0.00052495861 | C24: =EXP(G24) -> 0.00046072275 | D24: Projected | G24: {=MMULT(CK166:DK166,$I$15:$I$41)} -> -7.6827141 | H24: 2001 | I24: {=INDEX(MMULT(MINVERSE($C$91:$N$102),$P$91:$P$102),10,1)} -> -7.347294 | J24: =I24-2*I23+I22 -> 0.029203059 | K24: =J24^2 -> 0.00085281864 | L24: Estimated
A25: 2012 | B25: ='M_70_t'!B19 -> 0.00044495933 | C25: =EXP(G25) -> 0.00044227906 | D25: Projected | G25: {=MMULT(CK167:DK167,$I$15:$I$41)} -> -7.7235695 | H25: 2002 | I25: {=INDEX(MMULT(MINVERSE($C$91:$N$102),$P$91:$P$102),11,1)} -> -7.3967262 | J25: =I25-2*I24+I23 -> 0.039439304 | K25: =J25^2 -> 0.0015554587 | L25: Estimated
A26: 2013 | B26: ='M_70_t'!B20 -> 0.00041112307 | C26: =EXP(G26) -> 0.00042457371 | D26: Projected | G26: {=MMULT(CK168:DK168,$I$15:$I$41)} -> -7.7644249 | H26: 2003 | I26: {=INDEX(MMULT(MINVERSE($C$91:$N$102),$P$91:$P$102),12,1)} -> -7.4375816 | J26: =I26-2*I25+I24 -> 0.0085768012 | K26: =J26^2 -> 7.3561519e-05 | L26: Estimated
A27: 2014 | B27: ='M_70_t'!B21 -> 0.00044881582 | C27: =EXP(G27) -> 0.00040757714 | D27: Projected | G27: {=MMULT(CK169:DK169,$I$15:$I$41)} -> -7.8052803 | H27: 2004 | I27: =2*I26-I25 -> -7.478437 | J27: =I27-2*I26+I25 -> 0 | K27: =J27^2 -> 0 | L27: Projected: Δ²theta=0
A28: 2015 | B28: ='M_70_t'!B22 -> 0.00040681103 | C28: =EXP(G28) -> 0.00039126098 | D28: Projected | G28: {=MMULT(CK170:DK170,$I$15:$I$41)} -> -7.8461358 | H28: 2005 | I28: =2*I27-I26 -> -7.5192924 | J28: =I28-2*I27+I26 -> 0 | K28: =J28^2 -> 0 | L28: Projected: Δ²theta=0
A29: 2016 | B29: ='M_70_t'!B23 -> 0.00049105418 | C29: =EXP(G29) -> 0.00037559798 | D29: Projected | G29: {=MMULT(CK171:DK171,$I$15:$I$41)} -> -7.8869912 | H29: 2006 | I29: =2*I28-I27 -> -7.5601479 | J29: =I29-2*I28+I27 -> 0 | K29: =J29^2 -> 0 | L29: Projected: Δ²theta=0
A30: 2017 | B30: ='M_70_t'!B24 -> 0.00046002433 | C30: =EXP(G30) -> 0.00036056202 | D30: Projected | G30: {=MMULT(CK172:DK172,$I$15:$I$41)} -> -7.9278466 | H30: 2007 | I30: =2*I29-I28 -> -7.6010033 | J30: =I30-2*I29+I28 -> 0 | K30: =J30^2 -> 0 | L30: Projected: Δ²theta=0
A31: 2018 | B31: ='M_70_t'!B25 -> 0.0004166418 | C31: =EXP(G31) -> 0.00034612797 | D31: Projected | G31: {=MMULT(CK173:DK173,$I$15:$I$41)} -> -7.968702 | H31: 2008 | I31: =2*I30-I29 -> -7.6418587 | J31: =I31-2*I30+I29 -> 0 | K31: =J31^2 -> 0 | L31: Projected: Δ²theta=0
A32: 2019 | B32: ='M_70_t'!B26 -> 0.00044343997 | C32: =EXP(G32) -> 0.00033227174 | D32: Projected | G32: {=MMULT(CK174:DK174,$I$15:$I$41)} -> -8.0095574 | H32: 2009 | I32: =2*I31-I30 -> -7.6827141 | J32: =I32-2*I31+I30 -> 0 | K32: =J32^2 -> 0 | L32: Projected: Δ²theta=0
H33: 2010 | I33: =2*I32-I31 -> -7.7235695 | J33: =I33-2*I32+I31 -> 0 | K33: =J33^2 -> 0 | L33: Projected: Δ²theta=0
H34: 2011 | I34: =2*I33-I32 -> -7.7644249 | J34: =I34-2*I33+I32 -> 0 | K34: =J34^2 -> 0 | L34: Projected: Δ²theta=0
H35: 2012 | I35: =2*I34-I33 -> -7.8052803 | J35: =I35-2*I34+I33 -> 0 | K35: =J35^2 -> 0 | L35: Projected: Δ²theta=0
H36: 2013 | I36: =2*I35-I34 -> -7.8461358 | J36: =I36-2*I35+I34 -> 0 | K36: =J36^2 -> 0 | L36: Projected: Δ²theta=0
H37: 2014 | I37: =2*I36-I35 -> -7.8869912 | J37: =I37-2*I36+I35 -> 0 | K37: =J37^2 -> 0 | L37: Projected: Δ²theta=0
H38: 2015 | I38: =2*I37-I36 -> -7.9278466 | J38: =I38-2*I37+I36 -> 0 | K38: =J38^2 -> 0 | L38: Projected: Δ²theta=0
H39: 2016 | I39: =2*I38-I37 -> -7.968702 | J39: =I39-2*I38+I37 -> 0 | K39: =J39^2 -> 0 | L39: Projected: Δ²theta=0
H40: 2017 | I40: =2*I39-I38 -> -8.0095574 | J40: =I40-2*I39+I38 -> 0 | K40: =J40^2 -> 0 | L40: Projected: Δ²theta=0
H41: 2018 | I41: =2*I40-I39 -> -8.0504128 | J41: =I41-2*I40+I39 -> 0 | K41: =J41^2 -> 0 | L41: Projected: Δ²theta=0
A68: Training design matrix B and response y=LN(m) (training years only)
...

Sheet Q2(c)_Comparison
A1: Q2(c): observed age-70 mortality, refitted M1 and M2
A2: Instructor correction: use supplied spreadsheet data and discuss as age 70. Both M1 and M2 are independently fitted to 1995–2004 only. Observations after 2004 are shown for comparison, not used for fitting.
A5: Year | B5: Observed rate | C5: Refitted M1 | D5: M2 | E5: Period | H5: Training diagnostics (1995–2004 only)
A6: 1995 | B6: ='M_70_t'!B2 -> 0.00085662921 | C6: ='Q2(c)_M1'!C8 -> 0.0008706219 | D6: ='Q2(c)_M2'!C8 -> 0.00084301756 | E6: Training
A7: 1996 | B7: ='M_70_t'!B3 -> 0.00082999933 | C7: ='Q2(c)_M1'!C9 -> 0.0008729578 | D7: ='Q2(c)_M2'!C9 -> 0.00084087505 | E7: Training | H7: Model | I7: SSE | J7: Penalty | K7: Objective | L7: Parameters
A8: 1997 | B8: ='M_70_t'!B4 -> 0.00080999953 | C8: ='Q2(c)_M1'!C10 -> 0.00087078595 | D8: ='Q2(c)_M2'!C10 -> 0.00085782785 | E8: Training | H8: M1 | I8: ='Q2(c)_M1'!I8 -> 0.078972717 | J8: ='Q2(c)_M1'!I9 -> 0.026319106 | K8: ='Q2(c)_M1'!I10 -> 0.09213227 | L8: 6
A9: 1998 | B9: ='M_70_t'!B5 -> 0.00097750974 | C9: ='Q2(c)_M1'!C11 -> 0.00086076144 | D9: ='Q2(c)_M2'!C11 -> 0.00088477982 | E9: Training | H9: M2 | I9: ='Q2(c)_M2'!I8 -> 0.052886243 | J9: ='Q2(c)_M2'!I9 -> 0.012804924 | K9: ='Q2(c)_M2'!I10 -> 0.059288704 | L9: 12
A10: 1999 | B10: ='M_70_t'!B6 -> 0.00078849179 | C10: ='Q2(c)_M1'!C12 -> 0.00084043562 | D10: ='Q2(c)_M2'!C12 -> 0.00088983283 | E10: Training
A11: 2000 | B11: ='M_70_t'!B7 -> 0.00099667191 | C11: ='Q2(c)_M1'!C13 -> 0.00081015218 | D11: ='Q2(c)_M2'!C13 -> 0.00086510202 | E11: Training
A12: 2001 | B12: ='M_70_t'!B8 -> 0.00075112818 | C12: ='Q2(c)_M1'!C14 -> 0.00077118367 | D12: ='Q2(c)_M2'!C14 -> 0.00079031773 | E12: Training | H12: Requested projection years
A13: 2002 | B13: ='M_70_t'!B9 -> 0.0007042875 | C13: ='Q2(c)_M1'!C15 -> 0.00072549063 | D13: ='Q2(c)_M2'!C15 -> 0.000707654 | E13: Training
A14: 2003 | B14: ='M_70_t'!B10 -> 0.00062560882 | C14: ='Q2(c)_M1'!C16 -> 0.00067671034 | D14: ='Q2(c)_M2'!C16 -> 0.00064858288 | E14: Training | H14: Year | I14: Refitted M1 | J14: M2
A15: 2004 | B15: ='M_70_t'!B11 -> 0.00063014139 | C15: ='Q2(c)_M1'!C17 -> 0.00062827566 | D15: ='Q2(c)_M2'!C17 -> 0.00061413442 | E15: Training | H15: 2007 | I15: =INDEX(C6:C30,MATCH(H15,A6:A30,0)) -> 0.0005000391 | J15: =INDEX(D6:D30,MATCH(H15,A6:A30,0)) -> 0.00054251629
A16: 2005 | B16: ='M_70_t'!B12 -> 0.00058383424 | C16: ='Q2(c)_M1'!C18 -> 0.00058249566 | D16: ='Q2(c)_M2'!C18 -> 0.0005887072 | E16: Projection / out of sample | H16: 2010 | I16: =INDEX(C6:C30,MATCH(H16,A6:A30,0)) -> 0.00039750392 | J16: =INDEX(D6:D30,MATCH(H16,A6:A30,0)) -> 0.00047993557
A17: 2006 | B17: ='M_70_t'!B13 -> 0.00049907285 | C17: ='Q2(c)_M1'!C19 -> 0.00053976621 | D17: ='Q2(c)_M2'!C19 -> 0.00056514002 | E17: Projection / out of sample | H17: 2013 | I17: =INDEX(C6:C30,MATCH(H17,A6:A30,0)) -> 0.00031599402 | J17: =INDEX(D6:D30,MATCH(H17,A6:A30,0)) -> 0.00042457371
A18: 2007 | B18: ='M_70_t'!B14 -> 0.0005624154 | C18: ='Q2(c)_M1'!C20 -> 0.0005000391 | D18: ='Q2(c)_M2'!C20 -> 0.00054251629 | E18: Projection / out of sample | H18: 2016 | I18: =INDEX(C6:C30,MATCH(H18,A6:A30,0)) -> 0.00025119808 | J18: =INDEX(D6:D30,MATCH(H18,A6:A30,0)) -> 0.00037559798
A19: 2008 | B19: ='M_70_t'!B15 -> 0.00056619808 | C19: ='Q2(c)_M1'!C21 -> 0.00046321553 | D19: ='Q2(c)_M2'!C21 -> 0.00052079823 | E19: Projection / out of sample | H19: 2019 | I19: =INDEX(C6:C30,MATCH(H19,A6:A30,0)) -> 0.00019968883 | J19: =INDEX(D6:D30,MATCH(H19,A6:A30,0)) -> 0.00033227174
A20: 2009 | B20: ='M_70_t'!B16 -> 0.00054060672 | C20: ='Q2(c)_M1'!C22 -> 0.0004291037 | D20: ='Q2(c)_M2'!C22 -> 0.0004999496 | E20: Projection / out of sample
A21: 2010 | B21: ='M_70_t'!B17 -> 0.00048500736 | C21: ='Q2(c)_M1'!C23 -> 0.00039750392 | D21: ='Q2(c)_M2'!C23 -> 0.00047993557 | E21: Projection / out of sample
A22: 2011 | B22: ='M_70_t'!B18 -> 0.00052495861 | C22: ='Q2(c)_M1'!C24 -> 0.00036823118 | D22: ='Q2(c)_M2'!C24 -> 0.00046072275 | E22: Projection / out of sample
A23: 2012 | B23: ='M_70_t'!B19 -> 0.00044495933 | C23: ='Q2(c)_M1'!C25 -> 0.00034111413 | D23: ='Q2(c)_M2'!C25 -> 0.00044227906 | E23: Projection / out of sample
A24: 2013 | B24: ='M_70_t'!B20 -> 0.00041112307 | C24: ='Q2(c)_M1'!C26 -> 0.00031599402 | D24: ='Q2(c)_M2'!C26 -> 0.00042457371 | E24: Projection / out of sample
A25: 2014 | B25: ='M_70_t'!B21 -> 0.00044881582 | C25: ='Q2(c)_M1'!C27 -> 0.00029272379 | D25: ='Q2(c)_M2'!C27 -> 0.00040757714 | E25: Projection / out of sample
A26: 2015 | B26: ='M_70_t'!B22 -> 0.00040681103 | C26: ='Q2(c)_M1'!C28 -> 0.0002711672 | D26: ='Q2(c)_M2'!C28 -> 0.00039126098 | E26: Projection / out of sample
A27: 2016 | B27: ='M_70_t'!B23 -> 0.00049105418 | C27: ='Q2(c)_M1'!C29 -> 0.00025119808 | D27: ='Q2(c)_M2'!C29 -> 0.00037559798 | E27: Projection / out of sample
A28: 2017 | B28: ='M_70_t'!B24 -> 0.00046002433 | C28: ='Q2(c)_M1'!C30 -> 0.00023269951 | D28: ='Q2(c)_M2'!C30 -> 0.00036056202 | E28: Projection / out of sample
A29: 2018 | B29: ='M_70_t'!B25 -> 0.0004166418 | C29: ='Q2(c)_M1'!C31 -> 0.0002155632 | D29: ='Q2(c)_M2'!C31 -> 0.00034612797 | E29: Projection / out of sample
A30: 2019 | B30: ='M_70_t'!B26 -> 0.00044343997 | C30: ='Q2(c)_M1'!C32 -> 0.00019968883 | D30: ='Q2(c)_M2'!C32 -> 0.00033227174 | E30: Projection / out of sample
A58: Overfitting: annual knots increase the fitted coefficients from 6 to 12 and hence increase flexibility. However, lambda=1 and the second-order difference penalty constrain coefficient curvature. More knots alone do not establish overfitting; the in-sample fit and projected behaviour must be considered together.
A61: Evidence: refitted M1 SSE=0.07897271693, penalty=0.0263191063; M2 SSE=0.05288624263, penalty=0.01280492365. These are training diagnostics, not a new optimisation or a tuning criterion. The two different bases also mean identical numerical lambda does not imply identical effective smoothing.
A64: Benefits of annual knots: they distribute local flexibility across each calendar year, reducing dependence on an arbitrary three-year knot placement and allowing annual mortality changes to be represented more locally. The penalty retains control of rapid coefficient variation.
A67: Interpretation of theta_2001: it is a coefficient multiplying B_(2001,4), not the mortality rate or log mortality at year 2001. Under M1 the basis has support [2001,2013), lasting 12 years; under M2 it has support [2001,2005), lasting 4 years. Thus the same year label does not give the coefficient the same meaning or justify direct numerical comparison.
A70: Sudden one-year changes: M2 has finer local resolution because its cubic basis supports span four years instead of twelve, so it can represent such a change more locally. Cubic smoothness and the fixed penalty can still attenuate the change; this does not guarantee better forecasts.
A73: Projection: both models use the same zero-second-difference coefficient extension. The fitted coefficient tails differ, so their mortality projections may differ. Do not use the independent part-(b) M1 curve in this comparison.
