Workbook

Sheet M_70_t
A1: Year | B1: Mortality rate
A2: 1995 | B2: 0.00085662921
A3: 1996 | B3: 0.00082999933
A4: 1997 | B4: 0.00080999953
A5: 1998 | B5: 0.00097750974
A6: 1999 | B6: 0.00078849179
A7: 2000 | B7: 0.00099667191
A8: 2001 | B8: 0.00075112818
A9: 2002 | B9: 0.0007042875
A10: 2003 | B10: 0.00062560882
A11: 2004 | B11: 0.00063014139
A12: 2005 | B12: 0.00058383424
A13: 2006 | B13: 0.00049907285
... A26: 2019 | B26: 0.00044343997

Sheet Sheet1

Sheet Q2(a)_Derivation
A1: Q2(a): Cox–de Boor recursion and support
A3: Convention: B_(t_j,k)(t) denotes order k (degree k−1), with support [t_j, t_(j+k)). For M1, h=3 years and t_(j+r)=t_j+3r; extend the uniform knot sequence as required.
A5: Order 1: B_(t_j,1)(t)=1 if t_j≤t<t_j+h, and 0 otherwise. All subsequent basis functions are obtained from this indicator using the recursion below.
A7: For k=2,3,4: B_(t_j,k)(t)=[(t−t_j)/((k−1)h)] B_(t_j,k−1)(t)+[(t_j+kh−t)/((k−1)h)] B_(t_(j+1),k−1)(t).
A9: Order 2: B_(t_j,2)=[(t−t_j)/h]B_(t_j,1)+[(t_j+2h−t)/h]B_(t_(j+1),1).
A11: Order 3: B_(t_j,3)=[(t−t_j)/(2h)]B_(t_j,2)+[(t_j+3h−t)/(2h)]B_(t_(j+1),2).
A13: Order 4: B_(t_j,4)=[(t−t_j)/(3h)]B_(t_j,3)+[(t_j+4h−t)/(3h)]B_(t_(j+1),3).
A15: To display the piecewise forms compactly, let u=(t−t_j)/h and v_+=MAX(v,0). Then B_(t_j,k)(t)=Σ_(r=0)^k (−1)^r COMBIN(k,r)(u−r)_+^(k−1)/(k−1)! for k≥2.
A17: Order 2: u_+−2(u−1)_++(u−2)_+. Order 3: [u_+²−3(u−1)_+²+3(u−2)_+²−(u−3)_+²]/2.
A19: Order 4: [u_+³−4(u−1)_+³+6(u−2)_+³−4(u−3)_+³+(u−4)_+³]/6. The recurrence tables in this sheet and the model sheets calculate the same functions directly.
A21: The first-order support is one knot interval. Each recursion combines adjacent lower-order supports, adding one interval. The support length is therefore kh: 3, 6, 9 and 12 years for orders 1–4. For k≥2 the curve is also zero at the left endpoint; support here means the usual enclosing knot interval.
A25: Basis | B25: Order | C25: Degree | D25: Start year | E25: End year (excluded) | F25: Support length (years)
A26: B_1998,1 | B26: 1 | C26: 0 | D26: 1998 | E26: =D26+3*B26 -> 2001 | F26: =E26-D26 -> 3
A27: B_1998,2 | B27: 2 | C27: 1 | D27: 1998 | E27: =D27+3*B27 -> 2004 | F27: =E27-D27 -> 6
A28: B_1998,3 | B28: 3 | C28: 2 | D28: 1998 | E28: =D28+3*B28 -> 2007 | F28: =E28-D28 -> 9
A29: B_1998,4 | B29: 4 | C29: 3 | D29: 1998 | E29: =D29+3*B29 -> 2010 | F29: =E29-D29 -> 12
A31: Excel worked example below: B_1998,k for t=1995,…,2013. Intermediate adjacent first-, second- and third-order bases are retained so that every recursion step is visible.
A34: Year | B34: B1998,order1 | C34: B2001,order1 | D34: B2004,order1 | E34: B2007,order1 | F34: B1998,order2 | G34: B2001,order2 | H34: B2004,order2 | I34: B1998,order3 | J34: B2001,order3 | K34: B1998,order4
A35: 1995 | B35: =IF(AND($A35>=1998,$A35<2001),1,0) -> 0 | C35: =IF(AND($A35>=2001,$A35<2004),1,0) -> 0 | D35: =IF(AND($A35>=2004,$A35<2007),1,0) -> 0 | E35: =IF(AND($A35>=2007,$A35<2010),1,0) -> 0 | F35: =($A35-1998)/3*B35+(2004-$A35)/3*C35 -> 0 | G35: =($A35-2001)/3*C35+(2007-$A35)/3*D35 -> 0 | H35: =($A35-2004)/3*D35+(2010-$A35)/3*E35 -> 0 | I35: =($A35-1998)/6*F35+(2007-$A35)/6*G35 -> 0 | J35: =($A35-2001)/6*G35+(2010-$A35)/6*H35 -> 0 | K35: =($A35-1998)/9*I35+(2010-$A35)/9*J35 -> 0
A36: 1996 | B36: =IF(AND($A36>=1998,$A36<2001),1,0) -> 0 | C36: =IF(AND($A36>=2001,$A36<2004),1,0) -> 0 | D36: =IF(AND($A36>=2004,$A36<2007),1,0) -> 0 | E36: =IF(AND($A36>=2007,$A36<2010),1,0) -> 0 | F36: =($A36-1998)/3*B36+(2004-$A36)/3*C36 -> 0 | G36: =($A36-2001)/3*C36+(2007-$A36)/3*D36 -> 0 | H36: =($A36-2004)/3*D36+(2010-$A36)/3*E36 -> 0 | I36: =($A36-1998)/6*F36+(2007-$A36)/6*G36 -> 0 | J36: =($A36-2001)/6*G36+(2010-$A36)/6*H36 -> 0 | K36: =($A36-1998)/9*I36+(2010-$A36)/9*J36 -> 0
A37: 1997 | B37: =IF(AND($A37>=1998,$A37<2001),1,0) -> 0 | C37: =IF(AND($A37>=2001,$A37<2004),1,0) -> 0 | D37: =IF(AND($A37>=2004,$A37<2007),1,0) -> 0 | E37: =IF(AND($A37>=2007,$A37<2010),1,0) -> 0 | F37: =($A37-1998)/3*B37+(2004-$A37)/3*C37 -> 0 | G37: =($A37-2001)/3*C37+(2007-$A37)/3*D37 -> 0 | H37: =($A37-2004)/3*D37+(2010-$A37)/3*E37 -> 0 | I37: =($A37-1998)/6*F37+(2007-$A37)/6*G37 -> 0 | J37: =($A37-2001)/6*G37+(2010-$A37)/6*H37 -> 0 | K37: =($A37-1998)/9*I37+(2010-$A37)/9*J37 -> 0
A38: 1998 | B38: =IF(AND($A38>=1998,$A38<2001),1,0) -> 1 | C38: =IF(AND($A38>=2001,$A38<2004),1,0) -> 0 | D38: =IF(AND($A38>=2004,$A38<2007),1,0) -> 0 | E38: =IF(AND($A38>=2007,$A38<2010),1,0) -> 0 | F38: =($A38-1998)/3*B38+(2004-$A38)/3*C38 -> 0 | G38: =($A38-2001)/3*C38+(2007-$A38)/3*D38 -> 0 | H38: =($A38-2004)/3*D38+(2010-$A38)/3*E38 -> 0 | I38: =($A38-1998)/6*F38+(2007-$A38)/6*G38 -> 0 | J38: =($A38-2001)/6*G38+(2010-$A38)/6*H38 -> 0 | K38: =($A38-1998)/9*I38+(2010-$A38)/9*J38 -> 0
A39: 1999 | B39: =IF(AND($A39>=1998,$A39<2001),1,0) -> 1 | C39: =IF(AND($A39>=2001,$A39<2004),1,0) -> 0 | D39: =IF(AND($A39>=2004,$A39<2007),1,0) -> 0 | E39: =IF(AND($A39>=2007,$A39<2010),1,0) -> 0 | F39: =($A39-1998)/3*B39+(2004-$A39)/3*C39 -> 0.33333333 | G39: =($A39-2001)/3*C39+(2007-$A39)/3*D39 -> 0 | H39: =($A39-2004)/3*D39+(2010-$A39)/3*E39 -> 0 | I39: =($A39-1998)/6*F39+(2007-$A39)/6*G39 -> 0.055555556 | J39: =($A39-2001)/6*G39+(2010-$A39)/6*H39 -> 0 | K39: =($A39-1998)/9*I39+(2010-$A39)/9*J39 -> 0.0061728395
A40: 2000 | B40: =IF(AND($A40>=1998,$A40<2001),1,0) -> 1 | C40: =IF(AND($A40>=2001,$A40<2004),1,0) -> 0 | D40: =IF(AND($A40>=2004,$A40<2007),1,0) -> 0 | E40: =IF(AND($A40>=2007,$A40<2010),1,0) -> 0 | F40: =($A40-1998)/3*B40+(2004-$A40)/3*C40 -> 0.66666667 | G40: =($A40-2001)/3*C40+(2007-$A40)/3*D40 -> 0 | H40: =($A40-2004)/3*D40+(2010-$A40)/3*E40 -> 0 | I40: =($A40-1998)/6*F40+(2007-$A40)/6*G40 -> 0.22222222 | J40: =($A40-2001)/6*G40+(2010-$A40)/6*H40 -> 0 | K40: =($A40-1998)/9*I40+(2010-$A40)/9*J40 -> 0.049382716
A41: 2001 | B41: =IF(AND($A41>=1998,$A41<2001),1,0) -> 0 | C41: =IF(AND($A41>=2001,$A41<2004),1,0) -> 1 | D41: =IF(AND($A41>=2004,$A41<2007),1,0) -> 0 | E41: =IF(AND($A41>=2007,$A41<2010),1,0) -> 0 | F41: =($A41-1998)/3*B41+(2004-$A41)/3*C41 -> 1 | G41: =($A41-2001)/3*C41+(2007-$A41)/3*D41 -> 0 | H41: =($A41-2004)/3*D41+(2010-$A41)/3*E41 -> 0 | I41: =($A41-1998)/6*F41+(2007-$A41)/6*G41 -> 0.5 | J41: =($A41-2001)/6*G41+(2010-$A41)/6*H41 -> 0 | K41: =($A41-1998)/9*I41+(2010-$A41)/9*J41 -> 0.16666667
A42: 2002 | B42: =IF(AND($A42>=1998,$A42<2001),1,0) -> 0 | C42: =IF(AND($A42>=2001,$A42<2004),1,0) -> 1 | D42: =IF(AND($A42>=2004,$A42<2007),1,0) -> 0 | E42: =IF(AND($A42>=2007,$A42<2010),1,0) -> 0 | F42: =($A42-1998)/3*B42+(2004-$A42)/3*C42 -> 0.66666667 | G42: =($A42-2001)/3*C42+(2007-$A42)/3*D42 -> 0.33333333 | H42: =($A42-2004)/3*D42+(2010-$A42)/3*E42 -> 0 | I42: =($A42-1998)/6*F42+(2007-$A42)/6*G42 -> 0.72222222 | J42: =($A42-2001)/6*G42+(2010-$A42)/6*H42 -> 0.055555556 | K42: =($A42-1998)/9*I42+(2010-$A42)/9*J42 -> 0.37037037
A43: 2003 | B43: =IF(AND($A43>=1998,$A43<2001),1,0) -> 0 | C43: =IF(AND($A43>=2001,$A43<2004),1,0) -> 1 | D43: =IF(AND($A43>=2004,$A43<2007),1,0) -> 0 | E43: =IF(AND($A43>=2007,$A43<2010),1,0) -> 0 | F43: =($A43-1998)/3*B43+(2004-$A43)/3*C43 -> 0.33333333 | G43: =($A43-2001)/3*C43+(2007-$A43)/3*D43 -> 0.66666667 | H43: =($A43-2004)/3*D43+(2010-$A43)/3*E43 -> 0 | I43: =($A43-1998)/6*F43+(2007-$A43)/6*G43 -> 0.72222222 | J43: =($A43-2001)/6*G43+(2010-$A43)/6*H43 -> 0.22222222 | K43: =($A43-1998)/9*I43+(2010-$A43)/9*J43 -> 0.57407407
A44: 2004 | B44: =IF(AND($A44>=1998,$A44<2001),1,0) -> 0 | C44: =IF(AND($A44>=2001,$A44<2004),1,0) -> 0 | D44: =IF(AND($A44>=2004,$A44<2007),1,0) -> 1 | E44: =IF(AND($A44>=2007,$A44<2010),1,0) -> 0 | F44: =($A44-1998)/3*B44+(2004-$A44)/3*C44 -> 0 | G44: =($A44-2001)/3*C44+(2007-$A44)/3*D44 -> 1 | H44: =($A44-2004)/3*D44+(2010-$A44)/3*E44 -> 0 | I44: =($A44-1998)/6*F44+(2007-$A44)/6*G44 -> 0.5 | J44: =($A44-2001)/6*G44+(2010-$A44)/6*H44 -> 0.5 | K44: =($A44-1998)/9*I44+(2010-$A44)/9*J44 -> 0.66666667
A45: 2005 | B45: =IF(AND($A45>=1998,$A45<2001),1,0) -> 0 | C45: =IF(AND($A45>=2001,$A45<2004),1,0) -> 0 | D45: =IF(AND($A45>=2004,$A45<2007),1,0) -> 1 | E45: =IF(AND($A45>=2007,$A45<2010),1,0) -> 0 | F45: =($A45-1998)/3*B45+(2004-$A45)/3*C45 -> 0 | G45: =($A45-2001)/3*C45+(2007-$A45)/3*D45 -> 0.66666667 | H45: =($A45-2004)/3*D45+(2010-$A45)/3*E45 -> 0.33333333 | I45: =($A45-1998)/6*F45+(2007-$A45)/6*G45 -> 0.22222222 | J45: =($A45-2001)/6*G45+(2010-$A45)/6*H45 -> 0.72222222 | K45: =($A45-1998)/9*I45+(2010-$A45)/9*J45 -> 0.57407407
A46: 2006 | B46: =IF(AND($A46>=1998,$A46<2001),1,0) -> 0 | C46: =IF(AND($A46>=2001,$A46<2004),1,0) -> 0 | D46: =IF(AND($A46>=2004,$A46<2007),1,0) -> 1 | E46: =IF(AND($A46>=2007,$A46<2010),1,0) -> 0 | F46: =($A46-1998)/3*B46+(2004-$A46)/3*C46 -> 0 | G46: =($A46-2001)/3*C46+(2007-$A46)/3*D46 -> 0.33333333 | H46: =($A46-2004)/3*D46+(2010-$A46)/3*E46 -> 0.66666667 | I46: =($A46-1998)/6*F46+(2007-$A46)/6*G46 -> 0.055555556 | J46: =($A46-2001)/6*G46+(2010-$A46)/6*H46 -> 0.72222222 | K46: =($A46-1998)/9*I46+(2010-$A46)/9*J46 -> 0.37037037
... A53: 2013 | B53: =IF(AND($A53>=1998,$A53<2001),1,0) -> 0 | C53: =IF(AND($A53>=2001,$A53<2004),1,0) -> 0 | D53: =IF(AND($A53>=2004,$A53<2007),1,0) -> 0 | E53: =IF(AND($A53>=2007,$A53<2010),1,0) -> 0 | F53: =($A53-1998)/3*B53+(2004-$A53)/3*C53 -> 0 | G53: =($A53-2001)/3*C53+(2007-$A53)/3*D53 -> 0 | H53: =($A53-2004)/3*D53+(2010-$A53)/3*E53 -> 0 | I53: =($A53-1998)/6*F53+(2007-$A53)/6*G53 -> 0 | J53: =($A53-2001)/6*G53+(2010-$A53)/6*H53 -> 0 | K53: =($A53-1998)/9*I53+(2010-$A53)/9*J53 -> 0

Sheet Q2_ReadMe
A1: Question 2 — workbook guide and instructor correction
A2: Original sheets M_70_t and Sheet1 are preserved. Source: uploaded M_70_t.xlsx. Added sheets contain all Q2 calculations. Input rates have units of deaths per person-year; coefficients describe natural-log mortality; the B-spline basis is dimensionless.
A4: Instructor correction supplied by the user: treat (b) and (c) independently. For (c), refit both M1 and M2 using M_70_t data and refer to age 70 in the discussion, although the instructor states the spreadsheet rates actually belong to age 25.
A6: Part (b) inputs from assignment PDF (independent of spreadsheet observations)
A7: Year | B7: Central death rate
A8: 1995 | B8: 0.0235
A9: 1998 | B9: 0.0207
A10: 2001 | B10: 0.0183
A11: 2004 | B11: 0.0166
A13: Part (b) uses exactly the four rates above: no interpolation of missing annual observations and no use of M_70_t data in estimation. Annual fitted values are model evaluations, not invented observations.
A15: Part (c) uses M_70_t!A2:B11 (1995–2004) to estimate both models. Rows A12:B26 (2005–2019) are retained as out-of-sample observations for plotting only; they do not enter SSE or the normal equations.
A17: Week 11 layout: Q2(a)_Derivation contains recursion/support. Q2(b)_M1, Q2(c)_M1 and Q2(c)_M2 contain fitting/Solver tables. Each has a separate Forecast sheet; Q2(c)_Comparison contains the combined plot and answers.
A19: No extra objective, nonnegativity constraint, automatic smoothing selection is used. As confirmed by the user, LN(m) is the response, following Unit 4 pp.79–80 and Week11_Q1sol.xlsx; EXP converts fitted log rates back to mortality. lambda=1 and the second-order coefficient penalty are applied exactly as L=SSE+(lambda/2)*Penalty.
A21: Method reference: assignment Q2 Cox–de Boor construction and coefficient second-difference projection. The zero-second-difference forecast continues the final coefficient slope. Cross-checked against Unit 4 pp.63–64,79–81 and Week11_Q1sol.xlsx. Unit 4 p.88 uses a third-order example; this assignment specifies second order, so the Week 11 second-order extension is used.
A25: Year | B25: Part (b) M1 projection
A26: 2007 | B26: ='Q2(b)_Forecast'!I19 -> 0.014826547
A27: 2010 | B27: ='Q2(b)_Forecast'!I22 -> 0.013316994
A28: 2013 | B28: ='Q2(b)_Forecast'!I25 -> 0.011961134
A29: 2016 | B29: ='Q2(b)_Forecast'!I28 -> 0.01074332
A30: 2019 | B30: ='Q2(b)_Forecast'!I31 -> 0.0096494969
A33: This version follows Week11_Q1sol.xlsx: numeric theta decision cells, SUMPRODUCT fitted LN(m), first/second differences, separate SSE and unweighted penalty, L=SSE+lambda/2*Penalty, and explicit coefficient forecasts. Matrix inversion has been removed from the fitting worksheets.
A35: To rerun: open the desired fitting sheet, Data > Solver. Set B34 to Min, changing the theta row B24 onward; GRG Nonlinear; no constraints; disable nonnegative variables. Existing theta cells are numeric, so no paste-values step is required.

Sheet Q2(b)_M1
A1: Q2(b)_M1 — Week 11 fitting layout
A2: Fourth-order B-splines; fit LN(m). Coefficients are numeric Solver decision cells, as in Week11_Q1sol.xlsx. All basis functions, fitted values, differences, errors and objective calculations are Excel formulas.
A3: Part (b) uses only the four assignment observations. Part (c) refits M1 and M2 independently on M_70_t observations for 1995–2004, following the instructor correction.
D6: 1986 | E6: 1989 | F6: 1992 | G6: 1995 | H6: 1998 | I6: 2001
A7: Year | B7: Observed mortality m | C7: LN(m) | D7: B_1986,4(t) | E7: B_1989,4(t) | F7: B_1992,4(t) | G7: B_1995,4(t) | H7: B_1998,4(t) | I7: B_2001,4(t) | J7: Fitted LN(m) | K7: Log residual | L7: Squared log error
A8: 1995 | B8: ='Q2_ReadMe'!B8 -> 0.0235 | C8: =LN(B8) -> -3.7507549 | D8: =IF($A8<=1986,0,IF($A8<=1989,(($A8-1986)/3)^3/6,IF($A8<=1992,2/3-((($A8-1986)/3)-2)^2-0.5*((($A8-1986)/3)-2)^3,IF($A8<=1995,2/3-((($A8-1986)/3)-2)^2+0.5*((($A8-1986)/3)-2)^3,IF($A8<=1998,(4-(($A8-1986)/3))^3/6,0))))) -> 0.16666667 | E8: =IF($A8<=1989,0,IF($A8<=1992,(($A8-1989)/3)^3/6,IF($A8<=1995,2/3-((($A8-1989)/3)-2)^2-0.5*((($A8-1989)/3)-2)^3,IF($A8<=1998,2/3-((($A8-1989)/3)-2)^2+0.5*((($A8-1989)/3)-2)^3,IF($A8<=2001,(4-(($A8-1989)/3))^3/6,0))))) -> 0.66666667 | F8: =IF($A8<=1992,0,IF($A8<=1995,(($A8-1992)/3)^3/6,IF($A8<=1998,2/3-((($A8-1992)/3)-2)^2-0.5*((($A8-1992)/3)-2)^3,IF($A8<=2001,2/3-((($A8-1992)/3)-2)^2+0.5*((($A8-1992)/3)-2)^3,IF($A8<=2004,(4-(($A8-1992)/3))^3/6,0))))) -> 0.16666667 | G8: =IF($A8<=1995,0,IF($A8<=1998,(($A8-1995)/3)^3/6,IF($A8<=2001,2/3-((($A8-1995)/3)-2)^2-0.5*((($A8-1995)/3)-2)^3,IF($A8<=2004,2/3-((($A8-1995)/3)-2)^2+0.5*((($A8-1995)/3)-2)^3,IF($A8<=2007,(4-(($A8-1995)/3))^3/6,0))))) -> 0 | H8: =IF($A8<=1998,0,IF($A8<=2001,(($A8-1998)/3)^3/6,IF($A8<=2004,2/3-((($A8-1998)/3)-2)^2-0.5*((($A8-1998)/3)-2)^3,IF($A8<=2007,2/3-((($A8-1998)/3)-2)^2+0.5*((($A8-1998)/3)-2)^3,IF($A8<=2010,(4-(($A8-1998)/3))^3/6,0))))) -> 0 | I8: =IF($A8<=2001,0,IF($A8<=2004,(($A8-2001)/3)^3/6,IF($A8<=2007,2/3-((($A8-2001)/3)-2)^2-0.5*((($A8-2001)/3)-2)^3,IF($A8<=2010,2/3-((($A8-2001)/3)-2)^2+0.5*((($A8-2001)/3)-2)^3,IF($A8<=2013,(4-(($A8-2001)/3))^3/6,0))))) -> 0 | J8: =SUMPRODUCT(D8:I8,$B$24:$G$24) -> -3.7539712 | K8: =C8-J8 -> 0.0032162971 | L8: =K8^2 -> 1.0344567e-05
A9: 1998 | B9: ='Q2_ReadMe'!B9 -> 0.0207 | C9: =LN(B9) -> -3.8776216 | D9: =IF($A9<=1986,0,IF($A9<=1989,(($A9-1986)/3)^3/6,IF($A9<=1992,2/3-((($A9-1986)/3)-2)^2-0.5*((($A9-1986)/3)-2)^3,IF($A9<=1995,2/3-((($A9-1986)/3)-2)^2+0.5*((($A9-1986)/3)-2)^3,IF($A9<=1998,(4-(($A9-1986)/3))^3/6,0))))) -> 0 | E9: =IF($A9<=1989,0,IF($A9<=1992,(($A9-1989)/3)^3/6,IF($A9<=1995,2/3-((($A9-1989)/3)-2)^2-0.5*((($A9-1989)/3)-2)^3,IF($A9<=1998,2/3-((($A9-1989)/3)-2)^2+0.5*((($A9-1989)/3)-2)^3,IF($A9<=2001,(4-(($A9-1989)/3))^3/6,0))))) -> 0.16666667 | F9: =IF($A9<=1992,0,IF($A9<=1995,(($A9-1992)/3)^3/6,IF($A9<=1998,2/3-((($A9-1992)/3)-2)^2-0.5*((($A9-1992)/3)-2)^3,IF($A9<=2001,2/3-((($A9-1992)/3)-2)^2+0.5*((($A9-1992)/3)-2)^3,IF($A9<=2004,(4-(($A9-1992)/3))^3/6,0))))) -> 0.66666667 | G9: =IF($A9<=1995,0,IF($A9<=1998,(($A9-1995)/3)^3/6,IF($A9<=2001,2/3-((($A9-1995)/3)-2)^2-0.5*((($A9-1995)/3)-2)^3,IF($A9<=2004,2/3-((($A9-1995)/3)-2)^2+0.5*((($A9-1995)/3)-2)^3,IF($A9<=2007,(4-(($A9-1995)/3))^3/6,0))))) -> 0.16666667 | H9: =IF($A9<=1998,0,IF($A9<=2001,(($A9-1998)/3)^3/6,IF($A9<=2004,2/3-((($A9-1998)/3)-2)^2-0.5*((($A9-1998)/3)-2)^3,IF($A9<=2007,2/3-((($A9-1998)/3)-2)^2+0.5*((($A9-1998)/3)-2)^3,IF($A9<=2010,(4-(($A9-1998)/3))^3/6,0))))) -> 0 | I9: =IF($A9<=2001,0,IF($A9<=2004,(($A9-2001)/3)^3/6,IF($A9<=2007,2/3-((($A9-2001)/3)-2)^2-0.5*((($A9-2001)/3)-2)^3,IF($A9<=2010,2/3-((($A9-2001)/3)-2)^2+0.5*((($A9-2001)/3)-2)^3,IF($A9<=2013,(4-(($A9-2001)/3))^3/6,0))))) -> 0 | J9: =SUMPRODUCT(D9:I9,$B$24:$G$24) -> -3.876499 | K9: =C9-J9 -> -0.0011225944 | L9: =K9^2 -> 1.2602182e-06
A10: 2001 | B10: ='Q2_ReadMe'!B10 -> 0.0183 | C10: =LN(B10) -> -4.0008542 | D10: =IF($A10<=1986,0,IF($A10<=1989,(($A10-1986)/3)^3/6,IF($A10<=1992,2/3-((($A10-1986)/3)-2)^2-0.5*((($A10-1986)/3)-2)^3,IF($A10<=1995,2/3-((($A10-1986)/3)-2)^2+0.5*((($A10-1986)/3)-2)^3,IF($A10<=1998,(4-(($A10-1986)/3))^3/6,0))))) -> 0 | E10: =IF($A10<=1989,0,IF($A10<=1992,(($A10-1989)/3)^3/6,IF($A10<=1995,2/3-((($A10-1989)/3)-2)^2-0.5*((($A10-1989)/3)-2)^3,IF($A10<=1998,2/3-((($A10-1989)/3)-2)^2+0.5*((($A10-1989)/3)-2)^3,IF($A10<=2001,(4-(($A10-1989)/3))^3/6,0))))) -> 0 | F10: =IF($A10<=1992,0,IF($A10<=1995,(($A10-1992)/3)^3/6,IF($A10<=1998,2/3-((($A10-1992)/3)-2)^2-0.5*((($A10-1992)/3)-2)^3,IF($A10<=2001,2/3-((($A10-1992)/3)-2)^2+0.5*((($A10-1992)/3)-2)^3,IF($A10<=2004,(4-(($A10-1992)/3))^3/6,0))))) -> 0.16666667 | G10: =IF($A10<=1995,0,IF($A10<=1998,(($A10-1995)/3)^3/6,IF($A10<=2001,2/3-((($A10-1995)/3)-2)^2-0.5*((($A10-1995)/3)-2)^3,IF($A10<=2004,2/3-((($A10-1995)/3)-2)^2+0.5*((($A10-1995)/3)-2)^3,IF($A10<=2007,(4-(($A10-1995)/3))^3/6,0))))) -> 0.66666667 | H10: =IF($A10<=1998,0,IF($A10<=2001,(($A10-1998)/3)^3/6,IF($A10<=2004,2/3-((($A10-1998)/3)-2)^2-0.5*((($A10-1998)/3)-2)^3,IF($A10<=2007,2/3-((($A10-1998)/3)-2)^2+0.5*((($A10-1998)/3)-2)^3,IF($A10<=2010,(4-(($A10-1998)/3))^3/6,0))))) -> 0.16666667 | I10: =IF($A10<=2001,0,IF($A10<=2004,(($A10-2001)/3)^3/6,IF($A10<=2007,2/3-((($A10-2001)/3)-2)^2-0.5*((($A10-2001)/3)-2)^3,IF($A10<=2010,2/3-((($A10-2001)/3)-2)^2+0.5*((($A10-2001)/3)-2)^3,IF($A10<=2013,(4-(($A10-2001)/3))^3/6,0))))) -> 0 | J10: =SUMPRODUCT(D10:I10,$B$24:$G$24) -> -3.9934505 | K10: =C10-J10 -> -0.0074037026 | L10: =K10^2 -> 5.4814812e-05
A11: 2004 | B11: ='Q2_ReadMe'!B11 -> 0.0166 | C11: =LN(B11) -> -4.0983526 | D11: =IF($A11<=1986,0,IF($A11<=1989,(($A11-1986)/3)^3/6,IF($A11<=1992,2/3-((($A11-1986)/3)-2)^2-0.5*((($A11-1986)/3)-2)^3,IF($A11<=1995,2/3-((($A11-1986)/3)-2)^2+0.5*((($A11-1986)/3)-2)^3,IF($A11<=1998,(4-(($A11-1986)/3))^3/6,0))))) -> 0 | E11: =IF($A11<=1989,0,IF($A11<=1992,(($A11-1989)/3)^3/6,IF($A11<=1995,2/3-((($A11-1989)/3)-2)^2-0.5*((($A11-1989)/3)-2)^3,IF($A11<=1998,2/3-((($A11-1989)/3)-2)^2+0.5*((($A11-1989)/3)-2)^3,IF($A11<=2001,(4-(($A11-1989)/3))^3/6,0))))) -> 0 | F11: =IF($A11<=1992,0,IF($A11<=1995,(($A11-1992)/3)^3/6,IF($A11<=1998,2/3-((($A11-1992)/3)-2)^2-0.5*((($A11-1992)/3)-2)^3,IF($A11<=2001,2/3-((($A11-1992)/3)-2)^2+0.5*((($A11-1992)/3)-2)^3,IF($A11<=2004,(4-(($A11-1992)/3))^3/6,0))))) -> 0 | G11: =IF($A11<=1995,0,IF($A11<=1998,(($A11-1995)/3)^3/6,IF($A11<=2001,2/3-((($A11-1995)/3)-2)^2-0.5*((($A11-1995)/3)-2)^3,IF($A11<=2004,2/3-((($A11-1995)/3)-2)^2+0.5*((($A11-1995)/3)-2)^3,IF($A11<=2007,(4-(($A11-1995)/3))^3/6,0))))) -> 0.16666667 | H11: =IF($A11<=1998,0,IF($A11<=2001,(($A11-1998)/3)^3/6,IF($A11<=2004,2/3-((($A11-1998)/3)-2)^2-0.5*((($A11-1998)/3)-2)^3,IF($A11<=2007,2/3-((($A11-1998)/3)-2)^2+0.5*((($A11-1998)/3)-2)^3,IF($A11<=2010,(4-(($A11-1998)/3))^3/6,0))))) -> 0.66666667 | I11: =IF($A11<=2001,0,IF($A11<=2004,(($A11-2001)/3)^3/6,IF($A11<=2007,2/3-((($A11-2001)/3)-2)^2-0.5*((($A11-2001)/3)-2)^3,IF($A11<=2010,2/3-((($A11-2001)/3)-2)^2+0.5*((($A11-2001)/3)-2)^3,IF($A11<=2013,(4-(($A11-2001)/3))^3/6,0))))) -> 0.16666667 | J11: =SUMPRODUCT(D11:I11,$B$24:$G$24) -> -4.1036626 | K11: =C11-J11 -> 0.0053099999 | L11: =K11^2 -> 2.8196099e-05
A23: Coefficient knot year | B23: 1986 | C23: 1989 | D23: 1992 | E23: 1995 | F23: 1998 | G23: 2001
A24: theta (Solver values) | B24: -3.6297189 | C24: -3.7541498 | D24: -3.8775087 | E24: -3.9948092 | F24: -4.1039576 | G24: -4.211336
A25: First difference | B25: =C24-B24 -> -0.12443098 | C25: =D24-C24 -> -0.12335888 | D25: =E24-D24 -> -0.11730048 | E25: =F24-E24 -> -0.10914838 | F25: =G24-F24 -> -0.10737838
A26: Second difference | B26: =C25-B25 -> 0.001072099 | C26: =D25-C25 -> 0.0060583961 | D26: =E25-D25 -> 0.0081520989 | E26: =F25-E25 -> 0.00177
A27: Squared second difference | B27: =B26^2 -> 1.1493964e-06 | C27: =C26^2 -> 3.6704164e-05 | D27: =D26^2 -> 6.6456716e-05 | E27: =E26^2 -> 3.1328999e-06
A31: Total SSE | B31: =SUM(L8:L11) -> 9.4615696e-05
A32: Penalty (unweighted) | B32: =SUM(B27:E27) -> 0.00010744318
A33: lambda | B33: 1
A34: Objective L | B34: =B31+B33/2*B32 -> 0.00014833728
A37: Solver: minimise $B$34 by changing $B$24:$G$24. Method: GRG Nonlinear; no constraints; disable nonnegative-variable option; enable automatic scaling. lambda=$B$33=1. Decision cells already contain the fitted coefficient values and can be rerun directly.
A39: The numeric coefficient values were obtained by numerical minimisation of the displayed objective and checked against its normal equations. Microsoft Excel Solver was not executed in this environment; its reproducible settings are saved in this sheet.
A41: Forecast worksheet: Q2(b)_Forecast. Forward coefficient differences are computed exactly as in Week 11, using h=3 year(s); projected second differences are zero. No extra smoothing parameter search or positivity constraints are added.

Sheet Q2(b)_Forecast
A1: Q2(b)_Forecast — Week 11 forecasting layout
A2: Coefficient forecasts: theta_new=2*theta_previous−theta_two_periods_back, so added second differences are zero. Fit/forecast LN(m) with SUMPRODUCT; apply EXP to return to mortality rates. No observed data after 2004 enter estimation.
K5: =B7 -> -3.6297189 | L5: =B8 -> -3.7541498 | M5: =B9 -> -3.8775087 | N5: =B10 -> -3.9948092 | O5: =B11 -> -4.1039576 | P5: =B12 -> -4.211336 | Q5: =B13 -> -4.3187144 | R5: =B14 -> -4.4260927 | S5: =B15 -> -4.5334711 | T5: =B16 -> -4.6408495 | U5: =B17 -> -4.7482279
A6: Coefficient knot year | B6: theta | C6: First difference | D6: Second difference | F6: Year | G6: Observed mortality | H6: Fitted / forecast LN(m) | I6: Fitted / forecast m | J6: Period | K6: 1986 | L6: 1989 | M6: 1992 | N6: 1995 | O6: 1998 | P6: 2001 | Q6: 2004 | R6: 2007 | S6: 2010 | T6: 2013 | U6: 2016
A7: 1986 | B7: ='Q2(b)_M1'!B24 -> -3.6297189 | F7: 1995 | G7: ='Q2(b)_M1'!B8 -> 0.0235 | H7: =SUMPRODUCT(K7:U7,$K$5:$U$5) -> -3.7539712 | I7: =EXP(H7) -> 0.023424538 | J7: Fitted | K7: =IF($F7<=1986,0,IF($F7<=1989,(($F7-1986)/3)^3/6,IF($F7<=1992,2/3-((($F7-1986)/3)-2)^2-0.5*((($F7-1986)/3)-2)^3,IF($F7<=1995,2/3-((($F7-1986)/3)-2)^2+0.5*((($F7-1986)/3)-2)^3,IF($F7<=1998,(4-(($F7-1986)/3))^3/6,0))))) -> 0.16666667 | L7: =IF($F7<=1989,0,IF($F7<=1992,(($F7-1989)/3)^3/6,IF($F7<=1995,2/3-((($F7-1989)/3)-2)^2-0.5*((($F7-1989)/3)-2)^3,IF($F7<=1998,2/3-((($F7-1989)/3)-2)^2+0.5*((($F7-1989)/3)-2)^3,IF($F7<=2001,(4-(($F7-1989)/3))^3/6,0))))) -> 0.66666667 | M7: =IF($F7<=1992,0,IF($F7<=1995,(($F7-1992)/3)^3/6,IF($F7<=1998,2/3-((($F7-1992)/3)-2)^2-0.5*((($F7-1992)/3)-2)^3,IF($F7<=2001,2/3-((($F7-1992)/3)-2)^2+0.5*((($F7-1992)/3)-2)^3,IF($F7<=2004,(4-(($F7-1992)/3))^3/6,0))))) -> 0.16666667 | N7: =IF($F7<=1995,0,IF($F7<=1998,(($F7-1995)/3)^3/6,IF($F7<=2001,2/3-((($F7-1995)/3)-2)^2-0.5*((($F7-1995)/3)-2)^3,IF($F7<=2004,2/3-((($F7-1995)/3)-2)^2+0.5*((($F7-1995)/3)-2)^3,IF($F7<=2007,(4-(($F7-1995)/3))^3/6,0))))) -> 0 | O7: =IF($F7<=1998,0,IF($F7<=2001,(($F7-1998)/3)^3/6,IF($F7<=2004,2/3-((($F7-1998)/3)-2)^2-0.5*((($F7-1998)/3)-2)^3,IF($F7<=2007,2/3-((($F7-1998)/3)-2)^2+0.5*((($F7-1998)/3)-2)^3,IF($F7<=2010,(4-(($F7-1998)/3))^3/6,0))))) -> 0 | P7: =IF($F7<=2001,0,IF($F7<=2004,(($F7-2001)/3)^3/6,IF($F7<=2007,2/3-((($F7-2001)/3)-2)^2-0.5*((($F7-2001)/3)-2)^3,IF($F7<=2010,2/3-((($F7-2001)/3)-2)^2+0.5*((($F7-2001)/3)-2)^3,IF($F7<=2013,(4-(($F7-2001)/3))^3/6,0))))) -> 0 | Q7: =IF($F7<=2004,0,IF($F7<=2007,(($F7-2004)/3)^3/6,IF($F7<=2010,2/3-((($F7-2004)/3)-2)^2-0.5*((($F7-2004)/3)-2)^3,IF($F7<=2013,2/3-((($F7-2004)/3)-2)^2+0.5*((($F7-2004)/3)-2)^3,IF($F7<=2016,(4-(($F7-2004)/3))^3/6,0))))) -> 0 | R7: =IF($F7<=2007,0,IF($F7<=2010,(($F7-2007)/3)^3/6,IF($F7<=2013,2/3-((($F7-2007)/3)-2)^2-0.5*((($F7-2007)/3)-2)^3,IF($F7<=2016,2/3-((($F7-2007)/3)-2)^2+0.5*((($F7-2007)/3)-2)^3,IF($F7<=2019,(4-(($F7-2007)/3))^3/6,0))))) -> 0 | S7: =IF($F7<=2010,0,IF($F7<=2013,(($F7-2010)/3)^3/6,IF($F7<=2016,2/3-((($F7-2010)/3)-2)^2-0.5*((($F7-2010)/3)-2)^3,IF($F7<=2019,2/3-((($F7-2010)/3)-2)^2+0.5*((($F7-2010)/3)-2)^3,IF($F7<=2022,(4-(($F7-2010)/3))^3/6,0))))) -> 0 | T7: =IF($F7<=2013,0,IF($F7<=2016,(($F7-2013)/3)^3/6,IF($F7<=2019,2/3-((($F7-2013)/3)-2)^2-0.5*((($F7-2013)/3)-2)^3,IF($F7<=2022,2/3-((($F7-2013)/3)-2)^2+0.5*((($F7-2013)/3)-2)^3,IF($F7<=2025,(4-(($F7-2013)/3))^3/6,0))))) -> 0 | U7: =IF($F7<=2016,0,IF($F7<=2019,(($F7-2016)/3)^3/6,IF($F7<=2022,2/3-((($F7-2016)/3)-2)^2-0.5*((($F7-2016)/3)-2)^3,IF($F7<=2025,2/3-((($F7-2016)/3)-2)^2+0.5*((($F7-2016)/3)-2)^3,IF($F7<=2028,(4-(($F7-2016)/3))^3/6,0))))) -> 0
A8: 1989 | B8: ='Q2(b)_M1'!C24 -> -3.7541498 | C8: =B8-B7 -> -0.12443098 | F8: 1996 | H8: =SUMPRODUCT(K8:U8,$K$5:$U$5) -> -3.7951791 | I8: =EXP(H8) -> 0.022478879 | J8: Fitted | K8: =IF($F8<=1986,0,IF($F8<=1989,(($F8-1986)/3)^3/6,IF($F8<=1992,2/3-((($F8-1986)/3)-2)^2-0.5*((($F8-1986)/3)-2)^3,IF($F8<=1995,2/3-((($F8-1986)/3)-2)^2+0.5*((($F8-1986)/3)-2)^3,IF($F8<=1998,(4-(($F8-1986)/3))^3/6,0))))) -> 0.049382716 | L8: =IF($F8<=1989,0,IF($F8<=1992,(($F8-1989)/3)^3/6,IF($F8<=1995,2/3-((($F8-1989)/3)-2)^2-0.5*((($F8-1989)/3)-2)^3,IF($F8<=1998,2/3-((($F8-1989)/3)-2)^2+0.5*((($F8-1989)/3)-2)^3,IF($F8<=2001,(4-(($F8-1989)/3))^3/6,0))))) -> 0.57407407 | M8: =IF($F8<=1992,0,IF($F8<=1995,(($F8-1992)/3)^3/6,IF($F8<=1998,2/3-((($F8-1992)/3)-2)^2-0.5*((($F8-1992)/3)-2)^3,IF($F8<=2001,2/3-((($F8-1992)/3)-2)^2+0.5*((($F8-1992)/3)-2)^3,IF($F8<=2004,(4-(($F8-1992)/3))^3/6,0))))) -> 0.37037037 | N8: =IF($F8<=1995,0,IF($F8<=1998,(($F8-1995)/3)^3/6,IF($F8<=2001,2/3-((($F8-1995)/3)-2)^2-0.5*((($F8-1995)/3)-2)^3,IF($F8<=2004,2/3-((($F8-1995)/3)-2)^2+0.5*((($F8-1995)/3)-2)^3,IF($F8<=2007,(4-(($F8-1995)/3))^3/6,0))))) -> 0.0061728395 | O8: =IF($F8<=1998,0,IF($F8<=2001,(($F8-1998)/3)^3/6,IF($F8<=2004,2/3-((($F8-1998)/3)-2)^2-0.5*((($F8-1998)/3)-2)^3,IF($F8<=2007,2/3-((($F8-1998)/3)-2)^2+0.5*((($F8-1998)/3)-2)^3,IF($F8<=2010,(4-(($F8-1998)/3))^3/6,0))))) -> 0 | P8: =IF($F8<=2001,0,IF($F8<=2004,(($F8-2001)/3)^3/6,IF($F8<=2007,2/3-((($F8-2001)/3)-2)^2-0.5*((($F8-2001)/3)-2)^3,IF($F8<=2010,2/3-((($F8-2001)/3)-2)^2+0.5*((($F8-2001)/3)-2)^3,IF($F8<=2013,(4-(($F8-2001)/3))^3/6,0))))) -> 0 | Q8: =IF($F8<=2004,0,IF($F8<=2007,(($F8-2004)/3)^3/6,IF($F8<=2010,2/3-((($F8-2004)/3)-2)^2-0.5*((($F8-2004)/3)-2)^3,IF($F8<=2013,2/3-((($F8-2004)/3)-2)^2+0.5*((($F8-2004)/3)-2)^3,IF($F8<=2016,(4-(($F8-2004)/3))^3/6,0))))) -> 0 | R8: =IF($F8<=2007,0,IF($F8<=2010,(($F8-2007)/3)^3/6,IF($F8<=2013,2/3-((($F8-2007)/3)-2)^2-0.5*((($F8-2007)/3)-2)^3,IF($F8<=2016,2/3-((($F8-2007)/3)-2)^2+0.5*((($F8-2007)/3)-2)^3,IF($F8<=2019,(4-(($F8-2007)/3))^3/6,0))))) -> 0 | S8: =IF($F8<=2010,0,IF($F8<=2013,(($F8-2010)/3)^3/6,IF($F8<=2016,2/3-((($F8-2010)/3)-2)^2-0.5*((($F8-2010)/3)-2)^3,IF($F8<=2019,2/3-((($F8-2010)/3)-2)^2+0.5*((($F8-2010)/3)-2)^3,IF($F8<=2022,(4-(($F8-2010)/3))^3/6,0))))) -> 0 | T8: =IF($F8<=2013,0,IF($F8<=2016,(($F8-2013)/3)^3/6,IF($F8<=2019,2/3-((($F8-2013)/3)-2)^2-0.5*((($F8-2013)/3)-2)^3,IF($F8<=2022,2/3-((($F8-2013)/3)-2)^2+0.5*((($F8-2013)/3)-2)^3,IF($F8<=2025,(4-(($F8-2013)/3))^3/6,0))))) -> 0 | U8: =IF($F8<=2016,0,IF($F8<=2019,(($F8-2016)/3)^3/6,IF($F8<=2022,2/3-((($F8-2016)/3)-2)^2-0.5*((($F8-2016)/3)-2)^3,IF($F8<=2025,2/3-((($F8-2016)/3)-2)^2+0.5*((($F8-2016)/3)-2)^3,IF($F8<=2028,(4-(($F8-2016)/3))^3/6,0))))) -> 0
A9: 1992 | B9: ='Q2(b)_M1'!D24 -> -3.8775087 | C9: =B9-B8 -> -0.12335888 | D9: =C9-C8 -> 0.001072099 | F9: 1997 | H9: =SUMPRODUCT(K9:U9,$K$5:$U$5) -> -3.8360833 | I9: =EXP(H9) -> 0.021577951 | J9: Fitted | K9: =IF($F9<=1986,0,IF($F9<=1989,(($F9-1986)/3)^3/6,IF($F9<=1992,2/3-((($F9-1986)/3)-2)^2-0.5*((($F9-1986)/3)-2)^3,IF($F9<=1995,2/3-((($F9-1986)/3)-2)^2+0.5*((($F9-1986)/3)-2)^3,IF($F9<=1998,(4-(($F9-1986)/3))^3/6,0))))) -> 0.0061728395 | L9: =IF($F9<=1989,0,IF($F9<=1992,(($F9-1989)/3)^3/6,IF($F9<=1995,2/3-((($F9-1989)/3)-2)^2-0.5*((($F9-1989)/3)-2)^3,IF($F9<=1998,2/3-((($F9-1989)/3)-2)^2+0.5*((($F9-1989)/3)-2)^3,IF($F9<=2001,(4-(($F9-1989)/3))^3/6,0))))) -> 0.37037037 | M9: =IF($F9<=1992,0,IF($F9<=1995,(($F9-1992)/3)^3/6,IF($F9<=1998,2/3-((($F9-1992)/3)-2)^2-0.5*((($F9-1992)/3)-2)^3,IF($F9<=2001,2/3-((($F9-1992)/3)-2)^2+0.5*((($F9-1992)/3)-2)^3,IF($F9<=2004,(4-(($F9-1992)/3))^3/6,0))))) -> 0.57407407 | N9: =IF($F9<=1995,0,IF($F9<=1998,(($F9-1995)/3)^3/6,IF($F9<=2001,2/3-((($F9-1995)/3)-2)^2-0.5*((($F9-1995)/3)-2)^3,IF($F9<=2004,2/3-((($F9-1995)/3)-2)^2+0.5*((($F9-1995)/3)-2)^3,IF($F9<=2007,(4-(($F9-1995)/3))^3/6,0))))) -> 0.049382716 | O9: =IF($F9<=1998,0,IF($F9<=2001,(($F9-1998)/3)^3/6,IF($F9<=2004,2/3-((($F9-1998)/3)-2)^2-0.5*((($F9-1998)/3)-2)^3,IF($F9<=2007,2/3-((($F9-1998)/3)-2)^2+0.5*((($F9-1998)/3)-2)^3,IF($F9<=2010,(4-(($F9-1998)/3))^3/6,0))))) -> 0 | P9: =IF($F9<=2001,0,IF($F9<=2004,(($F9-2001)/3)^3/6,IF($F9<=2007,2/3-((($F9-2001)/3)-2)^2-0.5*((($F9-2001)/3)-2)^3,IF($F9<=2010,2/3-((($F9-2001)/3)-2)^2+0.5*((($F9-2001)/3)-2)^3,IF($F9<=2013,(4-(($F9-2001)/3))^3/6,0))))) -> 0 | Q9: =IF($F9<=2004,0,IF($F9<=2007,(($F9-2004)/3)^3/6,IF($F9<=2010,2/3-((($F9-2004)/3)-2)^2-0.5*((($F9-2004)/3)-2)^3,IF($F9<=2013,2/3-((($F9-2004)/3)-2)^2+0.5*((($F9-2004)/3)-2)^3,IF($F9<=2016,(4-(($F9-2004)/3))^3/6,0))))) -> 0 | R9: =IF($F9<=2007,0,IF($F9<=2010,(($F9-2007)/3)^3/6,IF($F9<=2013,2/3-((($F9-2007)/3)-2)^2-0.5*((($F9-2007)/3)-2)^3,IF($F9<=2016,2/3-((($F9-2007)/3)-2)^2+0.5*((($F9-2007)/3)-2)^3,IF($F9<=2019,(4-(($F9-2007)/3))^3/6,0))))) -> 0 | S9: =IF($F9<=2010,0,IF($F9<=2013,(($F9-2010)/3)^3/6,IF($F9<=2016,2/3-((($F9-2010)/3)-2)^2-0.5*((($F9-2010)/3)-2)^3,IF($F9<=2019,2/3-((($F9-2010)/3)-2)^2+0.5*((($F9-2010)/3)-2)^3,IF($F9<=2022,(4-(($F9-2010)/3))^3/6,0))))) -> 0 | T9: =IF($F9<=2013,0,IF($F9<=2016,(($F9-2013)/3)^3/6,IF($F9<=2019,2/3-((($F9-2013)/3)-2)^2-0.5*((($F9-2013)/3)-2)^3,IF($F9<=2022,2/3-((($F9-2013)/3)-2)^2+0.5*((($F9-2013)/3)-2)^3,IF($F9<=2025,(4-(($F9-2013)/3))^3/6,0))))) -> 0 | U9: =IF($F9<=2016,0,IF($F9<=2019,(($F9-2016)/3)^3/6,IF($F9<=2022,2/3-((($F9-2016)/3)-2)^2-0.5*((($F9-2016)/3)-2)^3,IF($F9<=2025,2/3-((($F9-2016)/3)-2)^2+0.5*((($F9-2016)/3)-2)^3,IF($F9<=2028,(4-(($F9-2016)/3))^3/6,0))))) -> 0
A10: 1995 | B10: ='Q2(b)_M1'!E24 -> -3.9948092 | C10: =B10-B9 -> -0.11730048 | D10: =C10-C9 -> 0.0060583961 | F10: 1998 | G10: ='Q2(b)_M1'!B9 -> 0.0207 | H10: =SUMPRODUCT(K10:U10,$K$5:$U$5) -> -3.876499 | I10: =EXP(H10) -> 0.020723251 | J10: Fitted | K10: =IF($F10<=1986,0,IF($F10<=1989,(($F10-1986)/3)^3/6,IF($F10<=1992,2/3-((($F10-1986)/3)-2)^2-0.5*((($F10-1986)/3)-2)^3,IF($F10<=1995,2/3-((($F10-1986)/3)-2)^2+0.5*((($F10-1986)/3)-2)^3,IF($F10<=1998,(4-(($F10-1986)/3))^3/6,0))))) -> 0 | L10: =IF($F10<=1989,0,IF($F10<=1992,(($F10-1989)/3)^3/6,IF($F10<=1995,2/3-((($F10-1989)/3)-2)^2-0.5*((($F10-1989)/3)-2)^3,IF($F10<=1998,2/3-((($F10-1989)/3)-2)^2+0.5*((($F10-1989)/3)-2)^3,IF($F10<=2001,(4-(($F10-1989)/3))^3/6,0))))) -> 0.16666667 | M10: =IF($F10<=1992,0,IF($F10<=1995,(($F10-1992)/3)^3/6,IF($F10<=1998,2/3-((($F10-1992)/3)-2)^2-0.5*((($F10-1992)/3)-2)^3,IF($F10<=2001,2/3-((($F10-1992)/3)-2)^2+0.5*((($F10-1992)/3)-2)^3,IF($F10<=2004,(4-(($F10-1992)/3))^3/6,0))))) -> 0.66666667 | N10: =IF($F10<=1995,0,IF($F10<=1998,(($F10-1995)/3)^3/6,IF($F10<=2001,2/3-((($F10-1995)/3)-2)^2-0.5*((($F10-1995)/3)-2)^3,IF($F10<=2004,2/3-((($F10-1995)/3)-2)^2+0.5*((($F10-1995)/3)-2)^3,IF($F10<=2007,(4-(($F10-1995)/3))^3/6,0))))) -> 0.16666667 | O10: =IF($F10<=1998,0,IF($F10<=2001,(($F10-1998)/3)^3/6,IF($F10<=2004,2/3-((($F10-1998)/3)-2)^2-0.5*((($F10-1998)/3)-2)^3,IF($F10<=2007,2/3-((($F10-1998)/3)-2)^2+0.5*((($F10-1998)/3)-2)^3,IF($F10<=2010,(4-(($F10-1998)/3))^3/6,0))))) -> 0 | P10: =IF($F10<=2001,0,IF($F10<=2004,(($F10-2001)/3)^3/6,IF($F10<=2007,2/3-((($F10-2001)/3)-2)^2-0.5*((($F10-2001)/3)-2)^3,IF($F10<=2010,2/3-((($F10-2001)/3)-2)^2+0.5*((($F10-2001)/3)-2)^3,IF($F10<=2013,(4-(($F10-2001)/3))^3/6,0))))) -> 0 | Q10: =IF($F10<=2004,0,IF($F10<=2007,(($F10-2004)/3)^3/6,IF($F10<=2010,2/3-((($F10-2004)/3)-2)^2-0.5*((($F10-2004)/3)-2)^3,IF($F10<=2013,2/3-((($F10-2004)/3)-2)^2+0.5*((($F10-2004)/3)-2)^3,IF($F10<=2016,(4-(($F10-2004)/3))^3/6,0))))) -> 0 | R10: =IF($F10<=2007,0,IF($F10<=2010,(($F10-2007)/3)^3/6,IF($F10<=2013,2/3-((($F10-2007)/3)-2)^2-0.5*((($F10-2007)/3)-2)^3,IF($F10<=2016,2/3-((($F10-2007)/3)-2)^2+0.5*((($F10-2007)/3)-2)^3,IF($F10<=2019,(4-(($F10-2007)/3))^3/6,0))))) -> 0 | S10: =IF($F10<=2010,0,IF($F10<=2013,(($F10-2010)/3)^3/6,IF($F10<=2016,2/3-((($F10-2010)/3)-2)^2-0.5*((($F10-2010)/3)-2)^3,IF($F10<=2019,2/3-((($F10-2010)/3)-2)^2+0.5*((($F10-2010)/3)-2)^3,IF($F10<=2022,(4-(($F10-2010)/3))^3/6,0))))) -> 0 | T10: =IF($F10<=2013,0,IF($F10<=2016,(($F10-2013)/3)^3/6,IF($F10<=2019,2/3-((($F10-2013)/3)-2)^2-0.5*((($F10-2013)/3)-2)^3,IF($F10<=2022,2/3-((($F10-2013)/3)-2)^2+0.5*((($F10-2013)/3)-2)^3,IF($F10<=2025,(4-(($F10-2013)/3))^3/6,0))))) -> 0 | U10: =IF($F10<=2016,0,IF($F10<=2019,(($F10-2016)/3)^3/6,IF($F10<=2022,2/3-((($F10-2016)/3)-2)^2-0.5*((($F10-2016)/3)-2)^3,IF($F10<=2025,2/3-((($F10-2016)/3)-2)^2+0.5*((($F10-2016)/3)-2)^3,IF($F10<=2028,(4-(($F10-2016)/3))^3/6,0))))) -> 0
A11: 1998 | B11: ='Q2(b)_M1'!F24 -> -4.1039576 | C11: =B11-B10 -> -0.10914838 | D11: =C11-C10 -> 0.0081520989 | F11: 1999 | H11: =SUMPRODUCT(K11:U11,$K$5:$U$5) -> -3.9162594 | I11: =EXP(H11) -> 0.019915452 | J11: Fitted | K11: =IF($F11<=1986,0,IF($F11<=1989,(($F11-1986)/3)^3/6,IF($F11<=1992,2/3-((($F11-1986)/3)-2)^2-0.5*((($F11-1986)/3)-2)^3,IF($F11<=1995,2/3-((($F11-1986)/3)-2)^2+0.5*((($F11-1986)/3)-2)^3,IF($F11<=1998,(4-(($F11-1986)/3))^3/6,0))))) -> 0 | L11: =IF($F11<=1989,0,IF($F11<=1992,(($F11-1989)/3)^3/6,IF($F11<=1995,2/3-((($F11-1989)/3)-2)^2-0.5*((($F11-1989)/3)-2)^3,IF($F11<=1998,2/3-((($F11-1989)/3)-2)^2+0.5*((($F11-1989)/3)-2)^3,IF($F11<=2001,(4-(($F11-1989)/3))^3/6,0))))) -> 0.049382716 | M11: =IF($F11<=1992,0,IF($F11<=1995,(($F11-1992)/3)^3/6,IF($F11<=1998,2/3-((($F11-1992)/3)-2)^2-0.5*((($F11-1992)/3)-2)^3,IF($F11<=2001,2/3-((($F11-1992)/3)-2)^2+0.5*((($F11-1992)/3)-2)^3,IF($F11<=2004,(4-(($F11-1992)/3))^3/6,0))))) -> 0.57407407 | N11: =IF($F11<=1995,0,IF($F11<=1998,(($F11-1995)/3)^3/6,IF($F11<=2001,2/3-((($F11-1995)/3)-2)^2-0.5*((($F11-1995)/3)-2)^3,IF($F11<=2004,2/3-((($F11-1995)/3)-2)^2+0.5*((($F11-1995)/3)-2)^3,IF($F11<=2007,(4-(($F11-1995)/3))^3/6,0))))) -> 0.37037037 | O11: =IF($F11<=1998,0,IF($F11<=2001,(($F11-1998)/3)^3/6,IF($F11<=2004,2/3-((($F11-1998)/3)-2)^2-0.5*((($F11-1998)/3)-2)^3,IF($F11<=2007,2/3-((($F11-1998)/3)-2)^2+0.5*((($F11-1998)/3)-2)^3,IF($F11<=2010,(4-(($F11-1998)/3))^3/6,0))))) -> 0.0061728395 | P11: =IF($F11<=2001,0,IF($F11<=2004,(($F11-2001)/3)^3/6,IF($F11<=2007,2/3-((($F11-2001)/3)-2)^2-0.5*((($F11-2001)/3)-2)^3,IF($F11<=2010,2/3-((($F11-2001)/3)-2)^2+0.5*((($F11-2001)/3)-2)^3,IF($F11<=2013,(4-(($F11-2001)/3))^3/6,0))))) -> 0 | Q11: =IF($F11<=2004,0,IF($F11<=2007,(($F11-2004)/3)^3/6,IF($F11<=2010,2/3-((($F11-2004)/3)-2)^2-0.5*((($F11-2004)/3)-2)^3,IF($F11<=2013,2/3-((($F11-2004)/3)-2)^2+0.5*((($F11-2004)/3)-2)^3,IF($F11<=2016,(4-(($F11-2004)/3))^3/6,0))))) -> 0 | R11: =IF($F11<=2007,0,IF($F11<=2010,(($F11-2007)/3)^3/6,IF($F11<=2013,2/3-((($F11-2007)/3)-2)^2-0.5*((($F11-2007)/3)-2)^3,IF($F11<=2016,2/3-((($F11-2007)/3)-2)^2+0.5*((($F11-2007)/3)-2)^3,IF($F11<=2019,(4-(($F11-2007)/3))^3/6,0))))) -> 0 | S11: =IF($F11<=2010,0,IF($F11<=2013,(($F11-2010)/3)^3/6,IF($F11<=2016,2/3-((($F11-2010)/3)-2)^2-0.5*((($F11-2010)/3)-2)^3,IF($F11<=2019,2/3-((($F11-2010)/3)-2)^2+0.5*((($F11-2010)/3)-2)^3,IF($F11<=2022,(4-(($F11-2010)/3))^3/6,0))))) -> 0 | T11: =IF($F11<=2013,0,IF($F11<=2016,(($F11-2013)/3)^3/6,IF($F11<=2019,2/3-((($F11-2013)/3)-2)^2-0.5*((($F11-2013)/3)-2)^3,IF($F11<=2022,2/3-((($F11-2013)/3)-2)^2+0.5*((($F11-2013)/3)-2)^3,IF($F11<=2025,(4-(($F11-2013)/3))^3/6,0))))) -> 0 | U11: =IF($F11<=2016,0,IF($F11<=2019,(($F11-2016)/3)^3/6,IF($F11<=2022,2/3-((($F11-2016)/3)-2)^2-0.5*((($F11-2016)/3)-2)^3,IF($F11<=2025,2/3-((($F11-2016)/3)-2)^2+0.5*((($F11-2016)/3)-2)^3,IF($F11<=2028,(4-(($F11-2016)/3))^3/6,0))))) -> 0
A12: 2001 | B12: ='Q2(b)_M1'!G24 -> -4.211336 | C12: =B12-B11 -> -0.10737838 | D12: =C12-C11 -> 0.00177 | F12: 2000 | H12: =SUMPRODUCT(K12:U12,$K$5:$U$5) -> -3.9552691 | I12: =EXP(H12) -> 0.019153514 | J12: Fitted | K12: =IF($F12<=1986,0,IF($F12<=1989,(($F12-1986)/3)^3/6,IF($F12<=1992,2/3-((($F12-1986)/3)-2)^2-0.5*((($F12-1986)/3)-2)^3,IF($F12<=1995,2/3-((($F12-1986)/3)-2)^2+0.5*((($F12-1986)/3)-2)^3,IF($F12<=1998,(4-(($F12-1986)/3))^3/6,0))))) -> 0 | L12: =IF($F12<=1989,0,IF($F12<=1992,(($F12-1989)/3)^3/6,IF($F12<=1995,2/3-((($F12-1989)/3)-2)^2-0.5*((($F12-1989)/3)-2)^3,IF($F12<=1998,2/3-((($F12-1989)/3)-2)^2+0.5*((($F12-1989)/3)-2)^3,IF($F12<=2001,(4-(($F12-1989)/3))^3/6,0))))) -> 0.0061728395 | M12: =IF($F12<=1992,0,IF($F12<=1995,(($F12-1992)/3)^3/6,IF($F12<=1998,2/3-((($F12-1992)/3)-2)^2-0.5*((($F12-1992)/3)-2)^3,IF($F12<=2001,2/3-((($F12-1992)/3)-2)^2+0.5*((($F12-1992)/3)-2)^3,IF($F12<=2004,(4-(($F12-1992)/3))^3/6,0))))) -> 0.37037037 | N12: =IF($F12<=1995,0,IF($F12<=1998,(($F12-1995)/3)^3/6,IF($F12<=2001,2/3-((($F12-1995)/3)-2)^2-0.5*((($F12-1995)/3)-2)^3,IF($F12<=2004,2/3-((($F12-1995)/3)-2)^2+0.5*((($F12-1995)/3)-2)^3,IF($F12<=2007,(4-(($F12-1995)/3))^3/6,0))))) -> 0.57407407 | O12: =IF($F12<=1998,0,IF($F12<=2001,(($F12-1998)/3)^3/6,IF($F12<=2004,2/3-((($F12-1998)/3)-2)^2-0.5*((($F12-1998)/3)-2)^3,IF($F12<=2007,2/3-((($F12-1998)/3)-2)^2+0.5*((($F12-1998)/3)-2)^3,IF($F12<=2010,(4-(($F12-1998)/3))^3/6,0))))) -> 0.049382716 | P12: =IF($F12<=2001,0,IF($F12<=2004,(($F12-2001)/3)^3/6,IF($F12<=2007,2/3-((($F12-2001)/3)-2)^2-0.5*((($F12-2001)/3)-2)^3,IF($F12<=2010,2/3-((($F12-2001)/3)-2)^2+0.5*((($F12-2001)/3)-2)^3,IF($F12<=2013,(4-(($F12-2001)/3))^3/6,0))))) -> 0 | Q12: =IF($F12<=2004,0,IF($F12<=2007,(($F12-2004)/3)^3/6,IF($F12<=2010,2/3-((($F12-2004)/3)-2)^2-0.5*((($F12-2004)/3)-2)^3,IF($F12<=2013,2/3-((($F12-2004)/3)-2)^2+0.5*((($F12-2004)/3)-2)^3,IF($F12<=2016,(4-(($F12-2004)/3))^3/6,0))))) -> 0 | R12: =IF($F12<=2007,0,IF($F12<=2010,(($F12-2007)/3)^3/6,IF($F12<=2013,2/3-((($F12-2007)/3)-2)^2-0.5*((($F12-2007)/3)-2)^3,IF($F12<=2016,2/3-((($F12-2007)/3)-2)^2+0.5*((($F12-2007)/3)-2)^3,IF($F12<=2019,(4-(($F12-2007)/3))^3/6,0))))) -> 0 | S12: =IF($F12<=2010,0,IF($F12<=2013,(($F12-2010)/3)^3/6,IF($F12<=2016,2/3-((($F12-2010)/3)-2)^2-0.5*((($F12-2010)/3)-2)^3,IF($F12<=2019,2/3-((($F12-2010)/3)-2)^2+0.5*((($F12-2010)/3)-2)^3,IF($F12<=2022,(4-(($F12-2010)/3))^3/6,0))))) -> 0 | T12: =IF($F12<=2013,0,IF($F12<=2016,(($F12-2013)/3)^3/6,IF($F12<=2019,2/3-((($F12-2013)/3)-2)^2-0.5*((($F12-2013)/3)-2)^3,IF($F12<=2022,2/3-((($F12-2013)/3)-2)^2+0.5*((($F12-2013)/3)-2)^3,IF($F12<=2025,(4-(($F12-2013)/3))^3/6,0))))) -> 0 | U12: =IF($F12<=2016,0,IF($F12<=2019,(($F12-2016)/3)^3/6,IF($F12<=2022,2/3-((($F12-2016)/3)-2)^2-0.5*((($F12-2016)/3)-2)^3,IF($F12<=2025,2/3-((($F12-2016)/3)-2)^2+0.5*((($F12-2016)/3)-2)^3,IF($F12<=2028,(4-(($F12-2016)/3))^3/6,0))))) -> 0
A13: 2004 | B13: =2*B12-B11 -> -4.3187144 | C13: =B13-B12 -> -0.10737838 | D13: =C13-C12 -> 0 | F13: 2001 | G13: ='Q2(b)_M1'!B10 -> 0.0183 | H13: =SUMPRODUCT(K13:U13,$K$5:$U$5) -> -3.9934505 | I13: =EXP(H13) -> 0.018435991 | J13: Fitted | K13: =IF($F13<=1986,0,IF($F13<=1989,(($F13-1986)/3)^3/6,IF($F13<=1992,2/3-((($F13-1986)/3)-2)^2-0.5*((($F13-1986)/3)-2)^3,IF($F13<=1995,2/3-((($F13-1986)/3)-2)^2+0.5*((($F13-1986)/3)-2)^3,IF($F13<=1998,(4-(($F13-1986)/3))^3/6,0))))) -> 0 | L13: =IF($F13<=1989,0,IF($F13<=1992,(($F13-1989)/3)^3/6,IF($F13<=1995,2/3-((($F13-1989)/3)-2)^2-0.5*((($F13-1989)/3)-2)^3,IF($F13<=1998,2/3-((($F13-1989)/3)-2)^2+0.5*((($F13-1989)/3)-2)^3,IF($F13<=2001,(4-(($F13-1989)/3))^3/6,0))))) -> 0 | M13: =IF($F13<=1992,0,IF($F13<=1995,(($F13-1992)/3)^3/6,IF($F13<=1998,2/3-((($F13-1992)/3)-2)^2-0.5*((($F13-1992)/3)-2)^3,IF($F13<=2001,2/3-((($F13-1992)/3)-2)^2+0.5*((($F13-1992)/3)-2)^3,IF($F13<=2004,(4-(($F13-1992)/3))^3/6,0))))) -> 0.16666667 | N13: =IF($F13<=1995,0,IF($F13<=1998,(($F13-1995)/3)^3/6,IF($F13<=2001,2/3-((($F13-1995)/3)-2)^2-0.5*((($F13-1995)/3)-2)^3,IF($F13<=2004,2/3-((($F13-1995)/3)-2)^2+0.5*((($F13-1995)/3)-2)^3,IF($F13<=2007,(4-(($F13-1995)/3))^3/6,0))))) -> 0.66666667 | O13: =IF($F13<=1998,0,IF($F13<=2001,(($F13-1998)/3)^3/6,IF($F13<=2004,2/3-((($F13-1998)/3)-2)^2-0.5*((($F13-1998)/3)-2)^3,IF($F13<=2007,2/3-((($F13-1998)/3)-2)^2+0.5*((($F13-1998)/3)-2)^3,IF($F13<=2010,(4-(($F13-1998)/3))^3/6,0))))) -> 0.16666667 | P13: =IF($F13<=2001,0,IF($F13<=2004,(($F13-2001)/3)^3/6,IF($F13<=2007,2/3-((($F13-2001)/3)-2)^2-0.5*((($F13-2001)/3)-2)^3,IF($F13<=2010,2/3-((($F13-2001)/3)-2)^2+0.5*((($F13-2001)/3)-2)^3,IF($F13<=2013,(4-(($F13-2001)/3))^3/6,0))))) -> 0 | Q13: =IF($F13<=2004,0,IF($F13<=2007,(($F13-2004)/3)^3/6,IF($F13<=2010,2/3-((($F13-2004)/3)-2)^2-0.5*((($F13-2004)/3)-2)^3,IF($F13<=2013,2/3-((($F13-2004)/3)-2)^2+0.5*((($F13-2004)/3)-2)^3,IF($F13<=2016,(4-(($F13-2004)/3))^3/6,0))))) -> 0 | R13: =IF($F13<=2007,0,IF($F13<=2010,(($F13-2007)/3)^3/6,IF($F13<=2013,2/3-((($F13-2007)/3)-2)^2-0.5*((($F13-2007)/3)-2)^3,IF($F13<=2016,2/3-((($F13-2007)/3)-2)^2+0.5*((($F13-2007)/3)-2)^3,IF($F13<=2019,(4-(($F13-2007)/3))^3/6,0))))) -> 0 | S13: =IF($F13<=2010,0,IF($F13<=2013,(($F13-2010)/3)^3/6,IF($F13<=2016,2/3-((($F13-2010)/3)-2)^2-0.5*((($F13-2010)/3)-2)^3,IF($F13<=2019,2/3-((($F13-2010)/3)-2)^2+0.5*((($F13-2010)/3)-2)^3,IF($F13<=2022,(4-(($F13-2010)/3))^3/6,0))))) -> 0 | T13: =IF($F13<=2013,0,IF($F13<=2016,(($F13-2013)/3)^3/6,IF($F13<=2019,2/3-((($F13-2013)/3)-2)^2-0.5*((($F13-2013)/3)-2)^3,IF($F13<=2022,2/3-((($F13-2013)/3)-2)^2+0.5*((($F13-2013)/3)-2)^3,IF($F13<=2025,(4-(($F13-2013)/3))^3/6,0))))) -> 0 | U13: =IF($F13<=2016,0,IF($F13<=2019,(($F13-2016)/3)^3/6,IF($F13<=2022,2/3-((($F13-2016)/3)-2)^2-0.5*((($F13-2016)/3)-2)^3,IF($F13<=2025,2/3-((($F13-2016)/3)-2)^2+0.5*((($F13-2016)/3)-2)^3,IF($F13<=2028,(4-(($F13-2016)/3))^3/6,0))))) -> 0
A14: 2007 | B14: =2*B13-B12 -> -4.4260927 | C14: =B14-B13 -> -0.10737838 | D14: =C14-C13 -> 0 | F14: 2002 | H14: =SUMPRODUCT(K14:U14,$K$5:$U$5) -> -4.0307785 | I14: =EXP(H14) -> 0.017760498 | J14: Fitted | K14: =IF($F14<=1986,0,IF($F14<=1989,(($F14-1986)/3)^3/6,IF($F14<=1992,2/3-((($F14-1986)/3)-2)^2-0.5*((($F14-1986)/3)-2)^3,IF($F14<=1995,2/3-((($F14-1986)/3)-2)^2+0.5*((($F14-1986)/3)-2)^3,IF($F14<=1998,(4-(($F14-1986)/3))^3/6,0))))) -> 0 | L14: =IF($F14<=1989,0,IF($F14<=1992,(($F14-1989)/3)^3/6,IF($F14<=1995,2/3-((($F14-1989)/3)-2)^2-0.5*((($F14-1989)/3)-2)^3,IF($F14<=1998,2/3-((($F14-1989)/3)-2)^2+0.5*((($F14-1989)/3)-2)^3,IF($F14<=2001,(4-(($F14-1989)/3))^3/6,0))))) -> 0 | M14: =IF($F14<=1992,0,IF($F14<=1995,(($F14-1992)/3)^3/6,IF($F14<=1998,2/3-((($F14-1992)/3)-2)^2-0.5*((($F14-1992)/3)-2)^3,IF($F14<=2001,2/3-((($F14-1992)/3)-2)^2+0.5*((($F14-1992)/3)-2)^3,IF($F14<=2004,(4-(($F14-1992)/3))^3/6,0))))) -> 0.049382716 | N14: =IF($F14<=1995,0,IF($F14<=1998,(($F14-1995)/3)^3/6,IF($F14<=2001,2/3-((($F14-1995)/3)-2)^2-0.5*((($F14-1995)/3)-2)^3,IF($F14<=2004,2/3-((($F14-1995)/3)-2)^2+0.5*((($F14-1995)/3)-2)^3,IF($F14<=2007,(4-(($F14-1995)/3))^3/6,0))))) -> 0.57407407 | O14: =IF($F14<=1998,0,IF($F14<=2001,(($F14-1998)/3)^3/6,IF($F14<=2004,2/3-((($F14-1998)/3)-2)^2-0.5*((($F14-1998)/3)-2)^3,IF($F14<=2007,2/3-((($F14-1998)/3)-2)^2+0.5*((($F14-1998)/3)-2)^3,IF($F14<=2010,(4-(($F14-1998)/3))^3/6,0))))) -> 0.37037037 | P14: =IF($F14<=2001,0,IF($F14<=2004,(($F14-2001)/3)^3/6,IF($F14<=2007,2/3-((($F14-2001)/3)-2)^2-0.5*((($F14-2001)/3)-2)^3,IF($F14<=2010,2/3-((($F14-2001)/3)-2)^2+0.5*((($F14-2001)/3)-2)^3,IF($F14<=2013,(4-(($F14-2001)/3))^3/6,0))))) -> 0.0061728395 | Q14: =IF($F14<=2004,0,IF($F14<=2007,(($F14-2004)/3)^3/6,IF($F14<=2010,2/3-((($F14-2004)/3)-2)^2-0.5*((($F14-2004)/3)-2)^3,IF($F14<=2013,2/3-((($F14-2004)/3)-2)^2+0.5*((($F14-2004)/3)-2)^3,IF($F14<=2016,(4-(($F14-2004)/3))^3/6,0))))) -> 0 | R14: =IF($F14<=2007,0,IF($F14<=2010,(($F14-2007)/3)^3/6,IF($F14<=2013,2/3-((($F14-2007)/3)-2)^2-0.5*((($F14-2007)/3)-2)^3,IF($F14<=2016,2/3-((($F14-2007)/3)-2)^2+0.5*((($F14-2007)/3)-2)^3,IF($F14<=2019,(4-(($F14-2007)/3))^3/6,0))))) -> 0 | S14: =IF($F14<=2010,0,IF($F14<=2013,(($F14-2010)/3)^3/6,IF($F14<=2016,2/3-((($F14-2010)/3)-2)^2-0.5*((($F14-2010)/3)-2)^3,IF($F14<=2019,2/3-((($F14-2010)/3)-2)^2+0.5*((($F14-2010)/3)-2)^3,IF($F14<=2022,(4-(($F14-2010)/3))^3/6,0))))) -> 0 | T14: =IF($F14<=2013,0,IF($F14<=2016,(($F14-2013)/3)^3/6,IF($F14<=2019,2/3-((($F14-2013)/3)-2)^2-0.5*((($F14-2013)/3)-2)^3,IF($F14<=2022,2/3-((($F14-2013)/3)-2)^2+0.5*((($F14-2013)/3)-2)^3,IF($F14<=2025,(4-(($F14-2013)/3))^3/6,0))))) -> 0 | U14: =IF($F14<=2016,0,IF($F14<=2019,(($F14-2016)/3)^3/6,IF($F14<=2022,2/3-((($F14-2016)/3)-2)^2-0.5*((($F14-2016)/3)-2)^3,IF($F14<=2025,2/3-((($F14-2016)/3)-2)^2+0.5*((($F14-2016)/3)-2)^3,IF($F14<=2028,(4-(($F14-2016)/3))^3/6,0))))) -> 0
A15: 2010 | B15: =2*B14-B13 -> -4.5334711 | C15: =B15-B14 -> -0.10737838 | D15: =C15-C14 -> 0 | F15: 2003 | H15: =SUMPRODUCT(K15:U15,$K$5:$U$5) -> -4.0674371 | I15: =EXP(H15) -> 0.017121213 | J15: Fitted | K15: =IF($F15<=1986,0,IF($F15<=1989,(($F15-1986)/3)^3/6,IF($F15<=1992,2/3-((($F15-1986)/3)-2)^2-0.5*((($F15-1986)/3)-2)^3,IF($F15<=1995,2/3-((($F15-1986)/3)-2)^2+0.5*((($F15-1986)/3)-2)^3,IF($F15<=1998,(4-(($F15-1986)/3))^3/6,0))))) -> 0 | L15: =IF($F15<=1989,0,IF($F15<=1992,(($F15-1989)/3)^3/6,IF($F15<=1995,2/3-((($F15-1989)/3)-2)^2-0.5*((($F15-1989)/3)-2)^3,IF($F15<=1998,2/3-((($F15-1989)/3)-2)^2+0.5*((($F15-1989)/3)-2)^3,IF($F15<=2001,(4-(($F15-1989)/3))^3/6,0))))) -> 0 | M15: =IF($F15<=1992,0,IF($F15<=1995,(($F15-1992)/3)^3/6,IF($F15<=1998,2/3-((($F15-1992)/3)-2)^2-0.5*((($F15-1992)/3)-2)^3,IF($F15<=2001,2/3-((($F15-1992)/3)-2)^2+0.5*((($F15-1992)/3)-2)^3,IF($F15<=2004,(4-(($F15-1992)/3))^3/6,0))))) -> 0.0061728395 | N15: =IF($F15<=1995,0,IF($F15<=1998,(($F15-1995)/3)^3/6,IF($F15<=2001,2/3-((($F15-1995)/3)-2)^2-0.5*((($F15-1995)/3)-2)^3,IF($F15<=2004,2/3-((($F15-1995)/3)-2)^2+0.5*((($F15-1995)/3)-2)^3,IF($F15<=2007,(4-(($F15-1995)/3))^3/6,0))))) -> 0.37037037 | O15: =IF($F15<=1998,0,IF($F15<=2001,(($F15-1998)/3)^3/6,IF($F15<=2004,2/3-((($F15-1998)/3)-2)^2-0.5*((($F15-1998)/3)-2)^3,IF($F15<=2007,2/3-((($F15-1998)/3)-2)^2+0.5*((($F15-1998)/3)-2)^3,IF($F15<=2010,(4-(($F15-1998)/3))^3/6,0))))) -> 0.57407407 | P15: =IF($F15<=2001,0,IF($F15<=2004,(($F15-2001)/3)^3/6,IF($F15<=2007,2/3-((($F15-2001)/3)-2)^2-0.5*((($F15-2001)/3)-2)^3,IF($F15<=2010,2/3-((($F15-2001)/3)-2)^2+0.5*((($F15-2001)/3)-2)^3,IF($F15<=2013,(4-(($F15-2001)/3))^3/6,0))))) -> 0.049382716 | Q15: =IF($F15<=2004,0,IF($F15<=2007,(($F15-2004)/3)^3/6,IF($F15<=2010,2/3-((($F15-2004)/3)-2)^2-0.5*((($F15-2004)/3)-2)^3,IF($F15<=2013,2/3-((($F15-2004)/3)-2)^2+0.5*((($F15-2004)/3)-2)^3,IF($F15<=2016,(4-(($F15-2004)/3))^3/6,0))))) -> 0 | R15: =IF($F15<=2007,0,IF($F15<=2010,(($F15-2007)/3)^3/6,IF($F15<=2013,2/3-((($F15-2007)/3)-2)^2-0.5*((($F15-2007)/3)-2)^3,IF($F15<=2016,2/3-((($F15-2007)/3)-2)^2+0.5*((($F15-2007)/3)-2)^3,IF($F15<=2019,(4-(($F15-2007)/3))^3/6,0))))) -> 0 | S15: =IF($F15<=2010,0,IF($F15<=2013,(($F15-2010)/3)^3/6,IF($F15<=2016,2/3-((($F15-2010)/3)-2)^2-0.5*((($F15-2010)/3)-2)^3,IF($F15<=2019,2/3-((($F15-2010)/3)-2)^2+0.5*((($F15-2010)/3)-2)^3,IF($F15<=2022,(4-(($F15-2010)/3))^3/6,0))))) -> 0 | T15: =IF($F15<=2013,0,IF($F15<=2016,(($F15-2013)/3)^3/6,IF($F15<=2019,2/3-((($F15-2013)/3)-2)^2-0.5*((($F15-2013)/3)-2)^3,IF($F15<=2022,2/3-((($F15-2013)/3)-2)^2+0.5*((($F15-2013)/3)-2)^3,IF($F15<=2025,(4-(($F15-2013)/3))^3/6,0))))) -> 0 | U15: =IF($F15<=2016,0,IF($F15<=2019,(($F15-2016)/3)^3/6,IF($F15<=2022,2/3-((($F15-2016)/3)-2)^2-0.5*((($F15-2016)/3)-2)^3,IF($F15<=2025,2/3-((($F15-2016)/3)-2)^2+0.5*((($F15-2016)/3)-2)^3,IF($F15<=2028,(4-(($F15-2016)/3))^3/6,0))))) -> 0
A16: 2013 | B16: =2*B15-B14 -> -4.6408495 | C16: =B16-B15 -> -0.10737838 | D16: =C16-C15 -> 0 | F16: 2004 | G16: ='Q2(b)_M1'!B11 -> 0.0166 | H16: =SUMPRODUCT(K16:U16,$K$5:$U$5) -> -4.1036626 | I16: =EXP(H16) -> 0.016512088 | J16: Fitted | K16: =IF($F16<=1986,0,IF($F16<=1989,(($F16-1986)/3)^3/6,IF($F16<=1992,2/3-((($F16-1986)/3)-2)^2-0.5*((($F16-1986)/3)-2)^3,IF($F16<=1995,2/3-((($F16-1986)/3)-2)^2+0.5*((($F16-1986)/3)-2)^3,IF($F16<=1998,(4-(($F16-1986)/3))^3/6,0))))) -> 0 | L16: =IF($F16<=1989,0,IF($F16<=1992,(($F16-1989)/3)^3/6,IF($F16<=1995,2/3-((($F16-1989)/3)-2)^2-0.5*((($F16-1989)/3)-2)^3,IF($F16<=1998,2/3-((($F16-1989)/3)-2)^2+0.5*((($F16-1989)/3)-2)^3,IF($F16<=2001,(4-(($F16-1989)/3))^3/6,0))))) -> 0 | M16: =IF($F16<=1992,0,IF($F16<=1995,(($F16-1992)/3)^3/6,IF($F16<=1998,2/3-((($F16-1992)/3)-2)^2-0.5*((($F16-1992)/3)-2)^3,IF($F16<=2001,2/3-((($F16-1992)/3)-2)^2+0.5*((($F16-1992)/3)-2)^3,IF($F16<=2004,(4-(($F16-1992)/3))^3/6,0))))) -> 0 | N16: =IF($F16<=1995,0,IF($F16<=1998,(($F16-1995)/3)^3/6,IF($F16<=2001,2/3-((($F16-1995)/3)-2)^2-0.5*((($F16-1995)/3)-2)^3,IF($F16<=2004,2/3-((($F16-1995)/3)-2)^2+0.5*((($F16-1995)/3)-2)^3,IF($F16<=2007,(4-(($F16-1995)/3))^3/6,0))))) -> 0.16666667 | O16: =IF($F16<=1998,0,IF($F16<=2001,(($F16-1998)/3)^3/6,IF($F16<=2004,2/3-((($F16-1998)/3)-2)^2-0.5*((($F16-1998)/3)-2)^3,IF($F16<=2007,2/3-((($F16-1998)/3)-2)^2+0.5*((($F16-1998)/3)-2)^3,IF($F16<=2010,(4-(($F16-1998)/3))^3/6,0))))) -> 0.66666667 | P16: =IF($F16<=2001,0,IF($F16<=2004,(($F16-2001)/3)^3/6,IF($F16<=2007,2/3-((($F16-2001)/3)-2)^2-0.5*((($F16-2001)/3)-2)^3,IF($F16<=2010,2/3-((($F16-2001)/3)-2)^2+0.5*((($F16-2001)/3)-2)^3,IF($F16<=2013,(4-(($F16-2001)/3))^3/6,0))))) -> 0.16666667 | Q16: =IF($F16<=2004,0,IF($F16<=2007,(($F16-2004)/3)^3/6,IF($F16<=2010,2/3-((($F16-2004)/3)-2)^2-0.5*((($F16-2004)/3)-2)^3,IF($F16<=2013,2/3-((($F16-2004)/3)-2)^2+0.5*((($F16-2004)/3)-2)^3,IF($F16<=2016,(4-(($F16-2004)/3))^3/6,0))))) -> 0 | R16: =IF($F16<=2007,0,IF($F16<=2010,(($F16-2007)/3)^3/6,IF($F16<=2013,2/3-((($F16-2007)/3)-2)^2-0.5*((($F16-2007)/3)-2)^3,IF($F16<=2016,2/3-((($F16-2007)/3)-2)^2+0.5*((($F16-2007)/3)-2)^3,IF($F16<=2019,(4-(($F16-2007)/3))^3/6,0))))) -> 0 | S16: =IF($F16<=2010,0,IF($F16<=2013,(($F16-2010)/3)^3/6,IF($F16<=2016,2/3-((($F16-2010)/3)-2)^2-0.5*((($F16-2010)/3)-2)^3,IF($F16<=2019,2/3-((($F16-2010)/3)-2)^2+0.5*((($F16-2010)/3)-2)^3,IF($F16<=2022,(4-(($F16-2010)/3))^3/6,0))))) -> 0 | T16: =IF($F16<=2013,0,IF($F16<=2016,(($F16-2013)/3)^3/6,IF($F16<=2019,2/3-((($F16-2013)/3)-2)^2-0.5*((($F16-2013)/3)-2)^3,IF($F16<=2022,2/3-((($F16-2013)/3)-2)^2+0.5*((($F16-2013)/3)-2)^3,IF($F16<=2025,(4-(($F16-2013)/3))^3/6,0))))) -> 0 | U16: =IF($F16<=2016,0,IF($F16<=2019,(($F16-2016)/3)^3/6,IF($F16<=2022,2/3-((($F16-2016)/3)-2)^2-0.5*((($F16-2016)/3)-2)^3,IF($F16<=2025,2/3-((($F16-2016)/3)-2)^2+0.5*((($F16-2016)/3)-2)^3,IF($F16<=2028,(4-(($F16-2016)/3))^3/6,0))))) -> 0
A17: 2016 | B17: =2*B16-B15 -> -4.7482279 | C17: =B17-B16 -> -0.10737838 | D17: =C17-C16 -> 0 | F17: 2005 | H17: =SUMPRODUCT(K17:U17,$K$5:$U$5) -> -4.139663 | I17: =EXP(H17) -> 0.015928219 | J17: Projected | K17: =IF($F17<=1986,0,IF($F17<=1989,(($F17-1986)/3)^3/6,IF($F17<=1992,2/3-((($F17-1986)/3)-2)^2-0.5*((($F17-1986)/3)-2)^3,IF($F17<=1995,2/3-((($F17-1986)/3)-2)^2+0.5*((($F17-1986)/3)-2)^3,IF($F17<=1998,(4-(($F17-1986)/3))^3/6,0))))) -> 0 | L17: =IF($F17<=1989,0,IF($F17<=1992,(($F17-1989)/3)^3/6,IF($F17<=1995,2/3-((($F17-1989)/3)-2)^2-0.5*((($F17-1989)/3)-2)^3,IF($F17<=1998,2/3-((($F17-1989)/3)-2)^2+0.5*((($F17-1989)/3)-2)^3,IF($F17<=2001,(4-(($F17-1989)/3))^3/6,0))))) -> 0 | M17: =IF($F17<=1992,0,IF($F17<=1995,(($F17-1992)/3)^3/6,IF($F17<=1998,2/3-((($F17-1992)/3)-2)^2-0.5*((($F17-1992)/3)-2)^3,IF($F17<=2001,2/3-((($F17-1992)/3)-2)^2+0.5*((($F17-1992)/3)-2)^3,IF($F17<=2004,(4-(($F17-1992)/3))^3/6,0))))) -> 0 | N17: =IF($F17<=1995,0,IF($F17<=1998,(($F17-1995)/3)^3/6,IF($F17<=2001,2/3-((($F17-1995)/3)-2)^2-0.5*((($F17-1995)/3)-2)^3,IF($F17<=2004,2/3-((($F17-1995)/3)-2)^2+0.5*((($F17-1995)/3)-2)^3,IF($F17<=2007,(4-(($F17-1995)/3))^3/6,0))))) -> 0.049382716 | O17: =IF($F17<=1998,0,IF($F17<=2001,(($F17-1998)/3)^3/6,IF($F17<=2004,2/3-((($F17-1998)/3)-2)^2-0.5*((($F17-1998)/3)-2)^3,IF($F17<=2007,2/3-((($F17-1998)/3)-2)^2+0.5*((($F17-1998)/3)-2)^3,IF($F17<=2010,(4-(($F17-1998)/3))^3/6,0))))) -> 0.57407407 | P17: =IF($F17<=2001,0,IF($F17<=2004,(($F17-2001)/3)^3/6,IF($F17<=2007,2/3-((($F17-2001)/3)-2)^2-0.5*((($F17-2001)/3)-2)^3,IF($F17<=2010,2/3-((($F17-2001)/3)-2)^2+0.5*((($F17-2001)/3)-2)^3,IF($F17<=2013,(4-(($F17-2001)/3))^3/6,0))))) -> 0.37037037 | Q17: =IF($F17<=2004,0,IF($F17<=2007,(($F17-2004)/3)^3/6,IF($F17<=2010,2/3-((($F17-2004)/3)-2)^2-0.5*((($F17-2004)/3)-2)^3,IF($F17<=2013,2/3-((($F17-2004)/3)-2)^2+0.5*((($F17-2004)/3)-2)^3,IF($F17<=2016,(4-(($F17-2004)/3))^3/6,0))))) -> 0.0061728395 | R17: =IF($F17<=2007,0,IF($F17<=2010,(($F17-2007)/3)^3/6,IF($F17<=2013,2/3-((($F17-2007)/3)-2)^2-0.5*((($F17-2007)/3)-2)^3,IF($F17<=2016,2/3-((($F17-2007)/3)-2)^2+0.5*((($F17-2007)/3)-2)^3,IF($F17<=2019,(4-(($F17-2007)/3))^3/6,0))))) -> 0 | S17: =IF($F17<=2010,0,IF($F17<=2013,(($F17-2010)/3)^3/6,IF($F17<=2016,2/3-((($F17-2010)/3)-2)^2-0.5*((($F17-2010)/3)-2)^3,IF($F17<=2019,2/3-((($F17-2010)/3)-2)^2+0.5*((($F17-2010)/3)-2)^3,IF($F17<=2022,(4-(($F17-2010)/3))^3/6,0))))) -> 0 | T17: =IF($F17<=2013,0,IF($F17<=2016,(($F17-2013)/3)^3/6,IF($F17<=2019,2/3-((($F17-2013)/3)-2)^2-0.5*((($F17-2013)/3)-2)^3,IF($F17<=2022,2/3-((($F17-2013)/3)-2)^2+0.5*((($F17-2013)/3)-2)^3,IF($F17<=2025,(4-(($F17-2013)/3))^3/6,0))))) -> 0 | U17: =IF($F17<=2016,0,IF($F17<=2019,(($F17-2016)/3)^3/6,IF($F17<=2022,2/3-((($F17-2016)/3)-2)^2-0.5*((($F17-2016)/3)-2)^3,IF($F17<=2025,2/3-((($F17-2016)/3)-2)^2+0.5*((($F17-2016)/3)-2)^3,IF($F17<=2028,(4-(($F17-2016)/3))^3/6,0))))) -> 0
F18: 2006 | H18: =SUMPRODUCT(K18:U18,$K$5:$U$5) -> -4.1755322 | I18: =EXP(H18) -> 0.01536701 | J18: Projected | K18: =IF($F18<=1986,0,IF($F18<=1989,(($F18-1986)/3)^3/6,IF($F18<=1992,2/3-((($F18-1986)/3)-2)^2-0.5*((($F18-1986)/3)-2)^3,IF($F18<=1995,2/3-((($F18-1986)/3)-2)^2+0.5*((($F18-1986)/3)-2)^3,IF($F18<=1998,(4-(($F18-1986)/3))^3/6,0))))) -> 0 | L18: =IF($F18<=1989,0,IF($F18<=1992,(($F18-1989)/3)^3/6,IF($F18<=1995,2/3-((($F18-1989)/3)-2)^2-0.5*((($F18-1989)/3)-2)^3,IF($F18<=1998,2/3-((($F18-1989)/3)-2)^2+0.5*((($F18-1989)/3)-2)^3,IF($F18<=2001,(4-(($F18-1989)/3))^3/6,0))))) -> 0 | M18: =IF($F18<=1992,0,IF($F18<=1995,(($F18-1992)/3)^3/6,IF($F18<=1998,2/3-((($F18-1992)/3)-2)^2-0.5*((($F18-1992)/3)-2)^3,IF($F18<=2001,2/3-((($F18-1992)/3)-2)^2+0.5*((($F18-1992)/3)-2)^3,IF($F18<=2004,(4-(($F18-1992)/3))^3/6,0))))) -> 0 | N18: =IF($F18<=1995,0,IF($F18<=1998,(($F18-1995)/3)^3/6,IF($F18<=2001,2/3-((($F18-1995)/3)-2)^2-0.5*((($F18-1995)/3)-2)^3,IF($F18<=2004,2/3-((($F18-1995)/3)-2)^2+0.5*((($F18-1995)/3)-2)^3,IF($F18<=2007,(4-(($F18-1995)/3))^3/6,0))))) -> 0.0061728395 | O18: =IF($F18<=1998,0,IF($F18<=2001,(($F18-1998)/3)^3/6,IF($F18<=2004,2/3-((($F18-1998)/3)-2)^2-0.5*((($F18-1998)/3)-2)^3,IF($F18<=2007,2/3-((($F18-1998)/3)-2)^2+0.5*((($F18-1998)/3)-2)^3,IF($F18<=2010,(4-(($F18-1998)/3))^3/6,0))))) -> 0.37037037 | P18: =IF($F18<=2001,0,IF($F18<=2004,(($F18-2001)/3)^3/6,IF($F18<=2007,2/3-((($F18-2001)/3)-2)^2-0.5*((($F18-2001)/3)-2)^3,IF($F18<=2010,2/3-((($F18-2001)/3)-2)^2+0.5*((($F18-2001)/3)-2)^3,IF($F18<=2013,(4-(($F18-2001)/3))^3/6,0))))) -> 0.57407407 | Q18: =IF($F18<=2004,0,IF($F18<=2007,(($F18-2004)/3)^3/6,IF($F18<=2010,2/3-((($F18-2004)/3)-2)^2-0.5*((($F18-2004)/3)-2)^3,IF($F18<=2013,2/3-((($F18-2004)/3)-2)^2+0.5*((($F18-2004)/3)-2)^3,IF($F18<=2016,(4-(($F18-2004)/3))^3/6,0))))) -> 0.049382716 | R18: =IF($F18<=2007,0,IF($F18<=2010,(($F18-2007)/3)^3/6,IF($F18<=2013,2/3-((($F18-2007)/3)-2)^2-0.5*((($F18-2007)/3)-2)^3,IF($F18<=2016,2/3-((($F18-2007)/3)-2)^2+0.5*((($F18-2007)/3)-2)^3,IF($F18<=2019,(4-(($F18-2007)/3))^3/6,0))))) -> 0 | S18: =IF($F18<=2010,0,IF($F18<=2013,(($F18-2010)/3)^3/6,IF($F18<=2016,2/3-((($F18-2010)/3)-2)^2-0.5*((($F18-2010)/3)-2)^3,IF($F18<=2019,2/3-((($F18-2010)/3)-2)^2+0.5*((($F18-2010)/3)-2)^3,IF($F18<=2022,(4-(($F18-2010)/3))^3/6,0))))) -> 0 | T18: =IF($F18<=2013,0,IF($F18<=2016,(($F18-2013)/3)^3/6,IF($F18<=2019,2/3-((($F18-2013)/3)-2)^2-0.5*((($F18-2013)/3)-2)^3,IF($F18<=2022,2/3-((($F18-2013)/3)-2)^2+0.5*((($F18-2013)/3)-2)^3,IF($F18<=2025,(4-(($F18-2013)/3))^3/6,0))))) -> 0 | U18: =IF($F18<=2016,0,IF($F18<=2019,(($F18-2016)/3)^3/6,IF($F18<=2022,2/3-((($F18-2016)/3)-2)^2-0.5*((($F18-2016)/3)-2)^3,IF($F18<=2025,2/3-((($F18-2016)/3)-2)^2+0.5*((($F18-2016)/3)-2)^3,IF($F18<=2028,(4-(($F18-2016)/3))^3/6,0))))) -> 0
F19: 2007 | H19: =SUMPRODUCT(K19:U19,$K$5:$U$5) -> -4.211336 | I19: =EXP(H19) -> 0.014826547 | J19: Projected | K19: =IF($F19<=1986,0,IF($F19<=1989,(($F19-1986)/3)^3/6,IF($F19<=1992,2/3-((($F19-1986)/3)-2)^2-0.5*((($F19-1986)/3)-2)^3,IF($F19<=1995,2/3-((($F19-1986)/3)-2)^2+0.5*((($F19-1986)/3)-2)^3,IF($F19<=1998,(4-(($F19-1986)/3))^3/6,0))))) -> 0 | L19: =IF($F19<=1989,0,IF($F19<=1992,(($F19-1989)/3)^3/6,IF($F19<=1995,2/3-((($F19-1989)/3)-2)^2-0.5*((($F19-1989)/3)-2)^3,IF($F19<=1998,2/3-((($F19-1989)/3)-2)^2+0.5*((($F19-1989)/3)-2)^3,IF($F19<=2001,(4-(($F19-1989)/3))^3/6,0))))) -> 0 | M19: =IF($F19<=1992,0,IF($F19<=1995,(($F19-1992)/3)^3/6,IF($F19<=1998,2/3-((($F19-1992)/3)-2)^2-0.5*((($F19-1992)/3)-2)^3,IF($F19<=2001,2/3-((($F19-1992)/3)-2)^2+0.5*((($F19-1992)/3)-2)^3,IF($F19<=2004,(4-(($F19-1992)/3))^3/6,0))))) -> 0 | N19: =IF($F19<=1995,0,IF($F19<=1998,(($F19-1995)/3)^3/6,IF($F19<=2001,2/3-((($F19-1995)/3)-2)^2-0.5*((($F19-1995)/3)-2)^3,IF($F19<=2004,2/3-((($F19-1995)/3)-2)^2+0.5*((($F19-1995)/3)-2)^3,IF($F19<=2007,(4-(($F19-1995)/3))^3/6,0))))) -> 0 | O19: =IF($F19<=1998,0,IF($F19<=2001,(($F19-1998)/3)^3/6,IF($F19<=2004,2/3-((($F19-1998)/3)-2)^2-0.5*((($F19-1998)/3)-2)^3,IF($F19<=2007,2/3-((($F19-1998)/3)-2)^2+0.5*((($F19-1998)/3)-2)^3,IF($F19<=2010,(4-(($F19-1998)/3))^3/6,0))))) -> 0.16666667 | P19: =IF($F19<=2001,0,IF($F19<=2004,(($F19-2001)/3)^3/6,IF($F19<=2007,2/3-((($F19-2001)/3)-2)^2-0.5*((($F19-2001)/3)-2)^3,IF($F19<=2010,2/3-((($F19-2001)/3)-2)^2+0.5*((($F19-2001)/3)-2)^3,IF($F19<=2013,(4-(($F19-2001)/3))^3/6,0))))) -> 0.66666667 | Q19: =IF($F19<=2004,0,IF($F19<=2007,(($F19-2004)/3)^3/6,IF($F19<=2010,2/3-((($F19-2004)/3)-2)^2-0.5*((($F19-2004)/3)-2)^3,IF($F19<=2013,2/3-((($F19-2004)/3)-2)^2+0.5*((($F19-2004)/3)-2)^3,IF($F19<=2016,(4-(($F19-2004)/3))^3/6,0))))) -> 0.16666667 | R19: =IF($F19<=2007,0,IF($F19<=2010,(($F19-2007)/3)^3/6,IF($F19<=2013,2/3-((($F19-2007)/3)-2)^2-0.5*((($F19-2007)/3)-2)^3,IF($F19<=2016,2/3-((($F19-2007)/3)-2)^2+0.5*((($F19-2007)/3)-2)^3,IF($F19<=2019,(4-(($F19-2007)/3))^3/6,0))))) -> 0 | S19: =IF($F19<=2010,0,IF($F19<=2013,(($F19-2010)/3)^3/6,IF($F19<=2016,2/3-((($F19-2010)/3)-2)^2-0.5*((($F19-2010)/3)-2)^3,IF($F19<=2019,2/3-((($F19-2010)/3)-2)^2+0.5*((($F19-2010)/3)-2)^3,IF($F19<=2022,(4-(($F19-2010)/3))^3/6,0))))) -> 0 | T19: =IF($F19<=2013,0,IF($F19<=2016,(($F19-2013)/3)^3/6,IF($F19<=2019,2/3-((($F19-2013)/3)-2)^2-0.5*((($F19-2013)/3)-2)^3,IF($F19<=2022,2/3-((($F19-2013)/3)-2)^2+0.5*((($F19-2013)/3)-2)^3,IF($F19<=2025,(4-(($F19-2013)/3))^3/6,0))))) -> 0 | U19: =IF($F19<=2016,0,IF($F19<=2019,(($F19-2016)/3)^3/6,IF($F19<=2022,2/3-((($F19-2016)/3)-2)^2-0.5*((($F19-2016)/3)-2)^3,IF($F19<=2025,2/3-((($F19-2016)/3)-2)^2+0.5*((($F19-2016)/3)-2)^3,IF($F19<=2028,(4-(($F19-2016)/3))^3/6,0))))) -> 0
